11:20:04 aiogram INFO Bot: Well Wisher Bot [@well_wisher_inno_bot]
11:20:04 aiogram WARNING Updates were skipped successfully.
11:20:04 root INFO Bot is starting...
11:20:05 aiogram.dispatcher.dispatcher INFO Start polling.
11:20:28 asyncio ERROR Task exception was never retrieved
future: <Task finished name='Task-11' coro=<Dispatcher._process_polling_updates() done, defined at C:\Users\milan\OneDrive\Документы\Innopolis_studying\1_year\2_sem\well_wisher_inno_bot\venv\lib\site-packages\aiogram\dispatcher\dispatcher.py:407> exception=NameError("name 'send_birthday_congratulations' is not defined")>
Traceback (most recent call last):
  File "C:\Users\milan\OneDrive\Документы\Innopolis_studying\1_year\2_sem\well_wisher_inno_bot\venv\lib\site-packages\aiogram\dispatcher\dispatcher.py", line 415, in _process_polling_updates
    for responses in itertools.chain.from_iterable(await self.process_updates(updates, fast)):
  File "C:\Users\milan\OneDrive\Документы\Innopolis_studying\1_year\2_sem\well_wisher_inno_bot\venv\lib\site-packages\aiogram\dispatcher\dispatcher.py", line 235, in process_updates
    return await asyncio.gather(*tasks)
  File "C:\Users\milan\OneDrive\Документы\Innopolis_studying\1_year\2_sem\well_wisher_inno_bot\venv\lib\site-packages\aiogram\dispatcher\handler.py", line 117, in notify
    response = await handler_obj.handler(*args, **partial_data)
  File "C:\Users\milan\OneDrive\Документы\Innopolis_studying\1_year\2_sem\well_wisher_inno_bot\venv\lib\site-packages\aiogram\dispatcher\dispatcher.py", line 256, in process_update
    return await self.message_handlers.notify(update.message)
  File "C:\Users\milan\OneDrive\Документы\Innopolis_studying\1_year\2_sem\well_wisher_inno_bot\venv\lib\site-packages\aiogram\dispatcher\handler.py", line 117, in notify
    response = await handler_obj.handler(*args, **partial_data)
  File "C:\Users\milan\OneDrive\Документы\Innopolis_studying\1_year\2_sem\well_wisher_inno_bot\app\main_logic.py", line 48, in start_handler
    await schedule_task(schedule_time, send_birthday_congratulations)
NameError: name 'send_birthday_congratulations' is not defined
11:20:57 aiogram.dispatcher.dispatcher INFO Stop polling...
11:20:57 aiogram WARNING Goodbye!
11:20:59 aiogram INFO Bot: Well Wisher Bot [@well_wisher_inno_bot]
11:20:59 aiogram WARNING Updates were skipped successfully.
11:20:59 root INFO Bot is starting...
11:20:59 aiogram.dispatcher.dispatcher INFO Start polling.
11:21:50 aiogram.dispatcher.dispatcher INFO Stop polling...
11:21:50 aiogram WARNING Goodbye!
11:21:52 aiogram INFO Bot: Well Wisher Bot [@well_wisher_inno_bot]
11:21:52 aiogram WARNING Updates were skipped successfully.
11:21:52 root INFO Bot is starting...
11:21:52 aiogram.dispatcher.dispatcher INFO Start polling.
11:25:18 aiogram.dispatcher.dispatcher INFO Stop polling...
11:25:18 aiogram WARNING Goodbye!
11:25:19 aiogram INFO Bot: Well Wisher Bot [@well_wisher_inno_bot]
11:25:19 aiogram WARNING Updates were skipped successfully.
11:25:19 root INFO Bot is starting...
11:25:19 aiogram.dispatcher.dispatcher INFO Start polling.
12:34:51 aiogram.dispatcher.dispatcher ERROR Cause exception while getting updates.
Traceback (most recent call last):
  File "C:\Users\milan\OneDrive\Документы\Innopolis_studying\1_year\2_sem\well_wisher_inno_bot\venv\lib\site-packages\aiogram\dispatcher\dispatcher.py", line 381, in start_polling
    updates = await self.bot.get_updates(
  File "C:\Users\milan\OneDrive\Документы\Innopolis_studying\1_year\2_sem\well_wisher_inno_bot\venv\lib\site-packages\aiogram\bot\bot.py", line 110, in get_updates
    result = await self.request(api.Methods.GET_UPDATES, payload)
  File "C:\Users\milan\OneDrive\Документы\Innopolis_studying\1_year\2_sem\well_wisher_inno_bot\venv\lib\site-packages\aiogram\bot\base.py", line 236, in request
    return await api.make_request(await self.get_session(), self.server, self.__token, method, data, files,
  File "C:\Users\milan\OneDrive\Документы\Innopolis_studying\1_year\2_sem\well_wisher_inno_bot\venv\lib\site-packages\aiogram\bot\api.py", line 139, in make_request
    async with session.post(url, data=req, **kwargs) as response:
  File "C:\Users\milan\OneDrive\Документы\Innopolis_studying\1_year\2_sem\well_wisher_inno_bot\venv\lib\site-packages\aiohttp\client.py", line 1141, in __aenter__
    self._resp = await self._coro
  File "C:\Users\milan\OneDrive\Документы\Innopolis_studying\1_year\2_sem\well_wisher_inno_bot\venv\lib\site-packages\aiohttp\client.py", line 560, in _request
    await resp.start(conn)
  File "C:\Users\milan\OneDrive\Документы\Innopolis_studying\1_year\2_sem\well_wisher_inno_bot\venv\lib\site-packages\aiohttp\client_reqrep.py", line 894, in start
    with self._timer:
  File "C:\Users\milan\OneDrive\Документы\Innopolis_studying\1_year\2_sem\well_wisher_inno_bot\venv\lib\site-packages\aiohttp\helpers.py", line 721, in __exit__
    raise asyncio.TimeoutError from None
asyncio.exceptions.TimeoutError
12:34:56 aiogram.dispatcher.dispatcher ERROR Cause exception while getting updates.
Traceback (most recent call last):
  File "C:\Users\milan\OneDrive\Документы\Innopolis_studying\1_year\2_sem\well_wisher_inno_bot\venv\lib\site-packages\aiohttp\connector.py", line 1152, in _create_direct_connection
    hosts = await asyncio.shield(host_resolved)
  File "C:\Users\milan\OneDrive\Документы\Innopolis_studying\1_year\2_sem\well_wisher_inno_bot\venv\lib\site-packages\aiohttp\connector.py", line 874, in _resolve_host
    addrs = await self._resolver.resolve(host, port, family=self._family)
  File "C:\Users\milan\OneDrive\Документы\Innopolis_studying\1_year\2_sem\well_wisher_inno_bot\venv\lib\site-packages\aiohttp\resolver.py", line 33, in resolve
    infos = await self._loop.getaddrinfo(
  File "C:\Users\milan\AppData\Local\Programs\Python\Python310\lib\asyncio\base_events.py", line 860, in getaddrinfo
    return await self.run_in_executor(
  File "C:\Users\milan\AppData\Local\Programs\Python\Python310\lib\concurrent\futures\thread.py", line 58, in run
    result = self.fn(*self.args, **self.kwargs)
  File "C:\Users\milan\AppData\Local\Programs\Python\Python310\lib\socket.py", line 955, in getaddrinfo
    for res in _socket.getaddrinfo(host, port, family, type, proto, flags):
socket.gaierror: [Errno 11004] getaddrinfo failed

The above exception was the direct cause of the following exception:

Traceback (most recent call last):
  File "C:\Users\milan\OneDrive\Документы\Innopolis_studying\1_year\2_sem\well_wisher_inno_bot\venv\lib\site-packages\aiogram\bot\api.py", line 139, in make_request
    async with session.post(url, data=req, **kwargs) as response:
  File "C:\Users\milan\OneDrive\Документы\Innopolis_studying\1_year\2_sem\well_wisher_inno_bot\venv\lib\site-packages\aiohttp\client.py", line 1141, in __aenter__
    self._resp = await self._coro
  File "C:\Users\milan\OneDrive\Документы\Innopolis_studying\1_year\2_sem\well_wisher_inno_bot\venv\lib\site-packages\aiohttp\client.py", line 536, in _request
    conn = await self._connector.connect(
  File "C:\Users\milan\OneDrive\Документы\Innopolis_studying\1_year\2_sem\well_wisher_inno_bot\venv\lib\site-packages\aiohttp\connector.py", line 540, in connect
    proto = await self._create_connection(req, traces, timeout)
  File "C:\Users\milan\OneDrive\Документы\Innopolis_studying\1_year\2_sem\well_wisher_inno_bot\venv\lib\site-packages\aiohttp\connector.py", line 901, in _create_connection
    _, proto = await self._create_direct_connection(req, traces, timeout)
  File "C:\Users\milan\OneDrive\Документы\Innopolis_studying\1_year\2_sem\well_wisher_inno_bot\venv\lib\site-packages\aiohttp\connector.py", line 1166, in _create_direct_connection
    raise ClientConnectorError(req.connection_key, exc) from exc
aiohttp.client_exceptions.ClientConnectorError: Cannot connect to host api.telegram.org:443 ssl:default [getaddrinfo failed]

During handling of the above exception, another exception occurred:

Traceback (most recent call last):
  File "C:\Users\milan\OneDrive\Документы\Innopolis_studying\1_year\2_sem\well_wisher_inno_bot\venv\lib\site-packages\aiogram\dispatcher\dispatcher.py", line 381, in start_polling
    updates = await self.bot.get_updates(
  File "C:\Users\milan\OneDrive\Документы\Innopolis_studying\1_year\2_sem\well_wisher_inno_bot\venv\lib\site-packages\aiogram\bot\bot.py", line 110, in get_updates
    result = await self.request(api.Methods.GET_UPDATES, payload)
  File "C:\Users\milan\OneDrive\Документы\Innopolis_studying\1_year\2_sem\well_wisher_inno_bot\venv\lib\site-packages\aiogram\bot\base.py", line 236, in request
    return await api.make_request(await self.get_session(), self.server, self.__token, method, data, files,
  File "C:\Users\milan\OneDrive\Документы\Innopolis_studying\1_year\2_sem\well_wisher_inno_bot\venv\lib\site-packages\aiogram\bot\api.py", line 142, in make_request
    raise exceptions.NetworkError(f"aiohttp client throws an error: {e.__class__.__name__}: {e}")
aiogram.utils.exceptions.NetworkError: Aiohttp client throws an error: ClientConnectorError: Cannot connect to host api.telegram.org:443 ssl:default [getaddrinfo failed]
12:35:01 aiogram.dispatcher.dispatcher ERROR Cause exception while getting updates.
Traceback (most recent call last):
  File "C:\Users\milan\OneDrive\Документы\Innopolis_studying\1_year\2_sem\well_wisher_inno_bot\venv\lib\site-packages\aiohttp\connector.py", line 1152, in _create_direct_connection
    hosts = await asyncio.shield(host_resolved)
  File "C:\Users\milan\OneDrive\Документы\Innopolis_studying\1_year\2_sem\well_wisher_inno_bot\venv\lib\site-packages\aiohttp\connector.py", line 874, in _resolve_host
    addrs = await self._resolver.resolve(host, port, family=self._family)
  File "C:\Users\milan\OneDrive\Документы\Innopolis_studying\1_year\2_sem\well_wisher_inno_bot\venv\lib\site-packages\aiohttp\resolver.py", line 33, in resolve
    infos = await self._loop.getaddrinfo(
  File "C:\Users\milan\AppData\Local\Programs\Python\Python310\lib\asyncio\base_events.py", line 860, in getaddrinfo
    return await self.run_in_executor(
  File "C:\Users\milan\AppData\Local\Programs\Python\Python310\lib\concurrent\futures\thread.py", line 58, in run
    result = self.fn(*self.args, **self.kwargs)
  File "C:\Users\milan\AppData\Local\Programs\Python\Python310\lib\socket.py", line 955, in getaddrinfo
    for res in _socket.getaddrinfo(host, port, family, type, proto, flags):
socket.gaierror: [Errno 11004] getaddrinfo failed

The above exception was the direct cause of the following exception:

Traceback (most recent call last):
  File "C:\Users\milan\OneDrive\Документы\Innopolis_studying\1_year\2_sem\well_wisher_inno_bot\venv\lib\site-packages\aiogram\bot\api.py", line 139, in make_request
    async with session.post(url, data=req, **kwargs) as response:
  File "C:\Users\milan\OneDrive\Документы\Innopolis_studying\1_year\2_sem\well_wisher_inno_bot\venv\lib\site-packages\aiohttp\client.py", line 1141, in __aenter__
    self._resp = await self._coro
  File "C:\Users\milan\OneDrive\Документы\Innopolis_studying\1_year\2_sem\well_wisher_inno_bot\venv\lib\site-packages\aiohttp\client.py", line 536, in _request
    conn = await self._connector.connect(
  File "C:\Users\milan\OneDrive\Документы\Innopolis_studying\1_year\2_sem\well_wisher_inno_bot\venv\lib\site-packages\aiohttp\connector.py", line 540, in connect
    proto = await self._create_connection(req, traces, timeout)
  File "C:\Users\milan\OneDrive\Документы\Innopolis_studying\1_year\2_sem\well_wisher_inno_bot\venv\lib\site-packages\aiohttp\connector.py", line 901, in _create_connection
    _, proto = await self._create_direct_connection(req, traces, timeout)
  File "C:\Users\milan\OneDrive\Документы\Innopolis_studying\1_year\2_sem\well_wisher_inno_bot\venv\lib\site-packages\aiohttp\connector.py", line 1166, in _create_direct_connection
    raise ClientConnectorError(req.connection_key, exc) from exc
aiohttp.client_exceptions.ClientConnectorError: Cannot connect to host api.telegram.org:443 ssl:default [getaddrinfo failed]

During handling of the above exception, another exception occurred:

Traceback (most recent call last):
  File "C:\Users\milan\OneDrive\Документы\Innopolis_studying\1_year\2_sem\well_wisher_inno_bot\venv\lib\site-packages\aiogram\dispatcher\dispatcher.py", line 381, in start_polling
    updates = await self.bot.get_updates(
  File "C:\Users\milan\OneDrive\Документы\Innopolis_studying\1_year\2_sem\well_wisher_inno_bot\venv\lib\site-packages\aiogram\bot\bot.py", line 110, in get_updates
    result = await self.request(api.Methods.GET_UPDATES, payload)
  File "C:\Users\milan\OneDrive\Документы\Innopolis_studying\1_year\2_sem\well_wisher_inno_bot\venv\lib\site-packages\aiogram\bot\base.py", line 236, in request
    return await api.make_request(await self.get_session(), self.server, self.__token, method, data, files,
  File "C:\Users\milan\OneDrive\Документы\Innopolis_studying\1_year\2_sem\well_wisher_inno_bot\venv\lib\site-packages\aiogram\bot\api.py", line 142, in make_request
    raise exceptions.NetworkError(f"aiohttp client throws an error: {e.__class__.__name__}: {e}")
aiogram.utils.exceptions.NetworkError: Aiohttp client throws an error: ClientConnectorError: Cannot connect to host api.telegram.org:443 ssl:default [getaddrinfo failed]
12:35:06 aiogram.dispatcher.dispatcher ERROR Cause exception while getting updates.
Traceback (most recent call last):
  File "C:\Users\milan\OneDrive\Документы\Innopolis_studying\1_year\2_sem\well_wisher_inno_bot\venv\lib\site-packages\aiohttp\connector.py", line 1152, in _create_direct_connection
    hosts = await asyncio.shield(host_resolved)
  File "C:\Users\milan\OneDrive\Документы\Innopolis_studying\1_year\2_sem\well_wisher_inno_bot\venv\lib\site-packages\aiohttp\connector.py", line 874, in _resolve_host
    addrs = await self._resolver.resolve(host, port, family=self._family)
  File "C:\Users\milan\OneDrive\Документы\Innopolis_studying\1_year\2_sem\well_wisher_inno_bot\venv\lib\site-packages\aiohttp\resolver.py", line 33, in resolve
    infos = await self._loop.getaddrinfo(
  File "C:\Users\milan\AppData\Local\Programs\Python\Python310\lib\asyncio\base_events.py", line 860, in getaddrinfo
    return await self.run_in_executor(
  File "C:\Users\milan\AppData\Local\Programs\Python\Python310\lib\concurrent\futures\thread.py", line 58, in run
    result = self.fn(*self.args, **self.kwargs)
  File "C:\Users\milan\AppData\Local\Programs\Python\Python310\lib\socket.py", line 955, in getaddrinfo
    for res in _socket.getaddrinfo(host, port, family, type, proto, flags):
socket.gaierror: [Errno 11004] getaddrinfo failed

The above exception was the direct cause of the following exception:

Traceback (most recent call last):
  File "C:\Users\milan\OneDrive\Документы\Innopolis_studying\1_year\2_sem\well_wisher_inno_bot\venv\lib\site-packages\aiogram\bot\api.py", line 139, in make_request
    async with session.post(url, data=req, **kwargs) as response:
  File "C:\Users\milan\OneDrive\Документы\Innopolis_studying\1_year\2_sem\well_wisher_inno_bot\venv\lib\site-packages\aiohttp\client.py", line 1141, in __aenter__
    self._resp = await self._coro
  File "C:\Users\milan\OneDrive\Документы\Innopolis_studying\1_year\2_sem\well_wisher_inno_bot\venv\lib\site-packages\aiohttp\client.py", line 536, in _request
    conn = await self._connector.connect(
  File "C:\Users\milan\OneDrive\Документы\Innopolis_studying\1_year\2_sem\well_wisher_inno_bot\venv\lib\site-packages\aiohttp\connector.py", line 540, in connect
    proto = await self._create_connection(req, traces, timeout)
  File "C:\Users\milan\OneDrive\Документы\Innopolis_studying\1_year\2_sem\well_wisher_inno_bot\venv\lib\site-packages\aiohttp\connector.py", line 901, in _create_connection
    _, proto = await self._create_direct_connection(req, traces, timeout)
  File "C:\Users\milan\OneDrive\Документы\Innopolis_studying\1_year\2_sem\well_wisher_inno_bot\venv\lib\site-packages\aiohttp\connector.py", line 1166, in _create_direct_connection
    raise ClientConnectorError(req.connection_key, exc) from exc
aiohttp.client_exceptions.ClientConnectorError: Cannot connect to host api.telegram.org:443 ssl:default [getaddrinfo failed]

During handling of the above exception, another exception occurred:

Traceback (most recent call last):
  File "C:\Users\milan\OneDrive\Документы\Innopolis_studying\1_year\2_sem\well_wisher_inno_bot\venv\lib\site-packages\aiogram\dispatcher\dispatcher.py", line 381, in start_polling
    updates = await self.bot.get_updates(
  File "C:\Users\milan\OneDrive\Документы\Innopolis_studying\1_year\2_sem\well_wisher_inno_bot\venv\lib\site-packages\aiogram\bot\bot.py", line 110, in get_updates
    result = await self.request(api.Methods.GET_UPDATES, payload)
  File "C:\Users\milan\OneDrive\Документы\Innopolis_studying\1_year\2_sem\well_wisher_inno_bot\venv\lib\site-packages\aiogram\bot\base.py", line 236, in request
    return await api.make_request(await self.get_session(), self.server, self.__token, method, data, files,
  File "C:\Users\milan\OneDrive\Документы\Innopolis_studying\1_year\2_sem\well_wisher_inno_bot\venv\lib\site-packages\aiogram\bot\api.py", line 142, in make_request
    raise exceptions.NetworkError(f"aiohttp client throws an error: {e.__class__.__name__}: {e}")
aiogram.utils.exceptions.NetworkError: Aiohttp client throws an error: ClientConnectorError: Cannot connect to host api.telegram.org:443 ssl:default [getaddrinfo failed]
12:35:11 aiogram.dispatcher.dispatcher ERROR Cause exception while getting updates.
Traceback (most recent call last):
  File "C:\Users\milan\OneDrive\Документы\Innopolis_studying\1_year\2_sem\well_wisher_inno_bot\venv\lib\site-packages\aiohttp\connector.py", line 1152, in _create_direct_connection
    hosts = await asyncio.shield(host_resolved)
  File "C:\Users\milan\OneDrive\Документы\Innopolis_studying\1_year\2_sem\well_wisher_inno_bot\venv\lib\site-packages\aiohttp\connector.py", line 874, in _resolve_host
    addrs = await self._resolver.resolve(host, port, family=self._family)
  File "C:\Users\milan\OneDrive\Документы\Innopolis_studying\1_year\2_sem\well_wisher_inno_bot\venv\lib\site-packages\aiohttp\resolver.py", line 33, in resolve
    infos = await self._loop.getaddrinfo(
  File "C:\Users\milan\AppData\Local\Programs\Python\Python310\lib\asyncio\base_events.py", line 860, in getaddrinfo
    return await self.run_in_executor(
  File "C:\Users\milan\AppData\Local\Programs\Python\Python310\lib\concurrent\futures\thread.py", line 58, in run
    result = self.fn(*self.args, **self.kwargs)
  File "C:\Users\milan\AppData\Local\Programs\Python\Python310\lib\socket.py", line 955, in getaddrinfo
    for res in _socket.getaddrinfo(host, port, family, type, proto, flags):
socket.gaierror: [Errno 11004] getaddrinfo failed

The above exception was the direct cause of the following exception:

Traceback (most recent call last):
  File "C:\Users\milan\OneDrive\Документы\Innopolis_studying\1_year\2_sem\well_wisher_inno_bot\venv\lib\site-packages\aiogram\bot\api.py", line 139, in make_request
    async with session.post(url, data=req, **kwargs) as response:
  File "C:\Users\milan\OneDrive\Документы\Innopolis_studying\1_year\2_sem\well_wisher_inno_bot\venv\lib\site-packages\aiohttp\client.py", line 1141, in __aenter__
    self._resp = await self._coro
  File "C:\Users\milan\OneDrive\Документы\Innopolis_studying\1_year\2_sem\well_wisher_inno_bot\venv\lib\site-packages\aiohttp\client.py", line 536, in _request
    conn = await self._connector.connect(
  File "C:\Users\milan\OneDrive\Документы\Innopolis_studying\1_year\2_sem\well_wisher_inno_bot\venv\lib\site-packages\aiohttp\connector.py", line 540, in connect
    proto = await self._create_connection(req, traces, timeout)
  File "C:\Users\milan\OneDrive\Документы\Innopolis_studying\1_year\2_sem\well_wisher_inno_bot\venv\lib\site-packages\aiohttp\connector.py", line 901, in _create_connection
    _, proto = await self._create_direct_connection(req, traces, timeout)
  File "C:\Users\milan\OneDrive\Документы\Innopolis_studying\1_year\2_sem\well_wisher_inno_bot\venv\lib\site-packages\aiohttp\connector.py", line 1166, in _create_direct_connection
    raise ClientConnectorError(req.connection_key, exc) from exc
aiohttp.client_exceptions.ClientConnectorError: Cannot connect to host api.telegram.org:443 ssl:default [getaddrinfo failed]

During handling of the above exception, another exception occurred:

Traceback (most recent call last):
  File "C:\Users\milan\OneDrive\Документы\Innopolis_studying\1_year\2_sem\well_wisher_inno_bot\venv\lib\site-packages\aiogram\dispatcher\dispatcher.py", line 381, in start_polling
    updates = await self.bot.get_updates(
  File "C:\Users\milan\OneDrive\Документы\Innopolis_studying\1_year\2_sem\well_wisher_inno_bot\venv\lib\site-packages\aiogram\bot\bot.py", line 110, in get_updates
    result = await self.request(api.Methods.GET_UPDATES, payload)
  File "C:\Users\milan\OneDrive\Документы\Innopolis_studying\1_year\2_sem\well_wisher_inno_bot\venv\lib\site-packages\aiogram\bot\base.py", line 236, in request
    return await api.make_request(await self.get_session(), self.server, self.__token, method, data, files,
  File "C:\Users\milan\OneDrive\Документы\Innopolis_studying\1_year\2_sem\well_wisher_inno_bot\venv\lib\site-packages\aiogram\bot\api.py", line 142, in make_request
    raise exceptions.NetworkError(f"aiohttp client throws an error: {e.__class__.__name__}: {e}")
aiogram.utils.exceptions.NetworkError: Aiohttp client throws an error: ClientConnectorError: Cannot connect to host api.telegram.org:443 ssl:default [getaddrinfo failed]
12:35:16 aiogram.dispatcher.dispatcher ERROR Cause exception while getting updates.
Traceback (most recent call last):
  File "C:\Users\milan\OneDrive\Документы\Innopolis_studying\1_year\2_sem\well_wisher_inno_bot\venv\lib\site-packages\aiohttp\connector.py", line 1152, in _create_direct_connection
    hosts = await asyncio.shield(host_resolved)
  File "C:\Users\milan\OneDrive\Документы\Innopolis_studying\1_year\2_sem\well_wisher_inno_bot\venv\lib\site-packages\aiohttp\connector.py", line 874, in _resolve_host
    addrs = await self._resolver.resolve(host, port, family=self._family)
  File "C:\Users\milan\OneDrive\Документы\Innopolis_studying\1_year\2_sem\well_wisher_inno_bot\venv\lib\site-packages\aiohttp\resolver.py", line 33, in resolve
    infos = await self._loop.getaddrinfo(
  File "C:\Users\milan\AppData\Local\Programs\Python\Python310\lib\asyncio\base_events.py", line 860, in getaddrinfo
    return await self.run_in_executor(
  File "C:\Users\milan\AppData\Local\Programs\Python\Python310\lib\concurrent\futures\thread.py", line 58, in run
    result = self.fn(*self.args, **self.kwargs)
  File "C:\Users\milan\AppData\Local\Programs\Python\Python310\lib\socket.py", line 955, in getaddrinfo
    for res in _socket.getaddrinfo(host, port, family, type, proto, flags):
socket.gaierror: [Errno 11004] getaddrinfo failed

The above exception was the direct cause of the following exception:

Traceback (most recent call last):
  File "C:\Users\milan\OneDrive\Документы\Innopolis_studying\1_year\2_sem\well_wisher_inno_bot\venv\lib\site-packages\aiogram\bot\api.py", line 139, in make_request
    async with session.post(url, data=req, **kwargs) as response:
  File "C:\Users\milan\OneDrive\Документы\Innopolis_studying\1_year\2_sem\well_wisher_inno_bot\venv\lib\site-packages\aiohttp\client.py", line 1141, in __aenter__
    self._resp = await self._coro
  File "C:\Users\milan\OneDrive\Документы\Innopolis_studying\1_year\2_sem\well_wisher_inno_bot\venv\lib\site-packages\aiohttp\client.py", line 536, in _request
    conn = await self._connector.connect(
  File "C:\Users\milan\OneDrive\Документы\Innopolis_studying\1_year\2_sem\well_wisher_inno_bot\venv\lib\site-packages\aiohttp\connector.py", line 540, in connect
    proto = await self._create_connection(req, traces, timeout)
  File "C:\Users\milan\OneDrive\Документы\Innopolis_studying\1_year\2_sem\well_wisher_inno_bot\venv\lib\site-packages\aiohttp\connector.py", line 901, in _create_connection
    _, proto = await self._create_direct_connection(req, traces, timeout)
  File "C:\Users\milan\OneDrive\Документы\Innopolis_studying\1_year\2_sem\well_wisher_inno_bot\venv\lib\site-packages\aiohttp\connector.py", line 1166, in _create_direct_connection
    raise ClientConnectorError(req.connection_key, exc) from exc
aiohttp.client_exceptions.ClientConnectorError: Cannot connect to host api.telegram.org:443 ssl:default [getaddrinfo failed]

During handling of the above exception, another exception occurred:

Traceback (most recent call last):
  File "C:\Users\milan\OneDrive\Документы\Innopolis_studying\1_year\2_sem\well_wisher_inno_bot\venv\lib\site-packages\aiogram\dispatcher\dispatcher.py", line 381, in start_polling
    updates = await self.bot.get_updates(
  File "C:\Users\milan\OneDrive\Документы\Innopolis_studying\1_year\2_sem\well_wisher_inno_bot\venv\lib\site-packages\aiogram\bot\bot.py", line 110, in get_updates
    result = await self.request(api.Methods.GET_UPDATES, payload)
  File "C:\Users\milan\OneDrive\Документы\Innopolis_studying\1_year\2_sem\well_wisher_inno_bot\venv\lib\site-packages\aiogram\bot\base.py", line 236, in request
    return await api.make_request(await self.get_session(), self.server, self.__token, method, data, files,
  File "C:\Users\milan\OneDrive\Документы\Innopolis_studying\1_year\2_sem\well_wisher_inno_bot\venv\lib\site-packages\aiogram\bot\api.py", line 142, in make_request
    raise exceptions.NetworkError(f"aiohttp client throws an error: {e.__class__.__name__}: {e}")
aiogram.utils.exceptions.NetworkError: Aiohttp client throws an error: ClientConnectorError: Cannot connect to host api.telegram.org:443 ssl:default [getaddrinfo failed]
12:35:21 aiogram.dispatcher.dispatcher ERROR Cause exception while getting updates.
Traceback (most recent call last):
  File "C:\Users\milan\OneDrive\Документы\Innopolis_studying\1_year\2_sem\well_wisher_inno_bot\venv\lib\site-packages\aiohttp\connector.py", line 1152, in _create_direct_connection
    hosts = await asyncio.shield(host_resolved)
  File "C:\Users\milan\OneDrive\Документы\Innopolis_studying\1_year\2_sem\well_wisher_inno_bot\venv\lib\site-packages\aiohttp\connector.py", line 874, in _resolve_host
    addrs = await self._resolver.resolve(host, port, family=self._family)
  File "C:\Users\milan\OneDrive\Документы\Innopolis_studying\1_year\2_sem\well_wisher_inno_bot\venv\lib\site-packages\aiohttp\resolver.py", line 33, in resolve
    infos = await self._loop.getaddrinfo(
  File "C:\Users\milan\AppData\Local\Programs\Python\Python310\lib\asyncio\base_events.py", line 860, in getaddrinfo
    return await self.run_in_executor(
  File "C:\Users\milan\AppData\Local\Programs\Python\Python310\lib\concurrent\futures\thread.py", line 58, in run
    result = self.fn(*self.args, **self.kwargs)
  File "C:\Users\milan\AppData\Local\Programs\Python\Python310\lib\socket.py", line 955, in getaddrinfo
    for res in _socket.getaddrinfo(host, port, family, type, proto, flags):
socket.gaierror: [Errno 11004] getaddrinfo failed

The above exception was the direct cause of the following exception:

Traceback (most recent call last):
  File "C:\Users\milan\OneDrive\Документы\Innopolis_studying\1_year\2_sem\well_wisher_inno_bot\venv\lib\site-packages\aiogram\bot\api.py", line 139, in make_request
    async with session.post(url, data=req, **kwargs) as response:
  File "C:\Users\milan\OneDrive\Документы\Innopolis_studying\1_year\2_sem\well_wisher_inno_bot\venv\lib\site-packages\aiohttp\client.py", line 1141, in __aenter__
    self._resp = await self._coro
  File "C:\Users\milan\OneDrive\Документы\Innopolis_studying\1_year\2_sem\well_wisher_inno_bot\venv\lib\site-packages\aiohttp\client.py", line 536, in _request
    conn = await self._connector.connect(
  File "C:\Users\milan\OneDrive\Документы\Innopolis_studying\1_year\2_sem\well_wisher_inno_bot\venv\lib\site-packages\aiohttp\connector.py", line 540, in connect
    proto = await self._create_connection(req, traces, timeout)
  File "C:\Users\milan\OneDrive\Документы\Innopolis_studying\1_year\2_sem\well_wisher_inno_bot\venv\lib\site-packages\aiohttp\connector.py", line 901, in _create_connection
    _, proto = await self._create_direct_connection(req, traces, timeout)
  File "C:\Users\milan\OneDrive\Документы\Innopolis_studying\1_year\2_sem\well_wisher_inno_bot\venv\lib\site-packages\aiohttp\connector.py", line 1166, in _create_direct_connection
    raise ClientConnectorError(req.connection_key, exc) from exc
aiohttp.client_exceptions.ClientConnectorError: Cannot connect to host api.telegram.org:443 ssl:default [getaddrinfo failed]

During handling of the above exception, another exception occurred:

Traceback (most recent call last):
  File "C:\Users\milan\OneDrive\Документы\Innopolis_studying\1_year\2_sem\well_wisher_inno_bot\venv\lib\site-packages\aiogram\dispatcher\dispatcher.py", line 381, in start_polling
    updates = await self.bot.get_updates(
  File "C:\Users\milan\OneDrive\Документы\Innopolis_studying\1_year\2_sem\well_wisher_inno_bot\venv\lib\site-packages\aiogram\bot\bot.py", line 110, in get_updates
    result = await self.request(api.Methods.GET_UPDATES, payload)
  File "C:\Users\milan\OneDrive\Документы\Innopolis_studying\1_year\2_sem\well_wisher_inno_bot\venv\lib\site-packages\aiogram\bot\base.py", line 236, in request
    return await api.make_request(await self.get_session(), self.server, self.__token, method, data, files,
  File "C:\Users\milan\OneDrive\Документы\Innopolis_studying\1_year\2_sem\well_wisher_inno_bot\venv\lib\site-packages\aiogram\bot\api.py", line 142, in make_request
    raise exceptions.NetworkError(f"aiohttp client throws an error: {e.__class__.__name__}: {e}")
aiogram.utils.exceptions.NetworkError: Aiohttp client throws an error: ClientConnectorError: Cannot connect to host api.telegram.org:443 ssl:default [getaddrinfo failed]
12:35:26 aiogram.dispatcher.dispatcher ERROR Cause exception while getting updates.
Traceback (most recent call last):
  File "C:\Users\milan\OneDrive\Документы\Innopolis_studying\1_year\2_sem\well_wisher_inno_bot\venv\lib\site-packages\aiohttp\connector.py", line 1152, in _create_direct_connection
    hosts = await asyncio.shield(host_resolved)
  File "C:\Users\milan\OneDrive\Документы\Innopolis_studying\1_year\2_sem\well_wisher_inno_bot\venv\lib\site-packages\aiohttp\connector.py", line 874, in _resolve_host
    addrs = await self._resolver.resolve(host, port, family=self._family)
  File "C:\Users\milan\OneDrive\Документы\Innopolis_studying\1_year\2_sem\well_wisher_inno_bot\venv\lib\site-packages\aiohttp\resolver.py", line 33, in resolve
    infos = await self._loop.getaddrinfo(
  File "C:\Users\milan\AppData\Local\Programs\Python\Python310\lib\asyncio\base_events.py", line 860, in getaddrinfo
    return await self.run_in_executor(
  File "C:\Users\milan\AppData\Local\Programs\Python\Python310\lib\concurrent\futures\thread.py", line 58, in run
    result = self.fn(*self.args, **self.kwargs)
  File "C:\Users\milan\AppData\Local\Programs\Python\Python310\lib\socket.py", line 955, in getaddrinfo
    for res in _socket.getaddrinfo(host, port, family, type, proto, flags):
socket.gaierror: [Errno 11004] getaddrinfo failed

The above exception was the direct cause of the following exception:

Traceback (most recent call last):
  File "C:\Users\milan\OneDrive\Документы\Innopolis_studying\1_year\2_sem\well_wisher_inno_bot\venv\lib\site-packages\aiogram\bot\api.py", line 139, in make_request
    async with session.post(url, data=req, **kwargs) as response:
  File "C:\Users\milan\OneDrive\Документы\Innopolis_studying\1_year\2_sem\well_wisher_inno_bot\venv\lib\site-packages\aiohttp\client.py", line 1141, in __aenter__
    self._resp = await self._coro
  File "C:\Users\milan\OneDrive\Документы\Innopolis_studying\1_year\2_sem\well_wisher_inno_bot\venv\lib\site-packages\aiohttp\client.py", line 536, in _request
    conn = await self._connector.connect(
  File "C:\Users\milan\OneDrive\Документы\Innopolis_studying\1_year\2_sem\well_wisher_inno_bot\venv\lib\site-packages\aiohttp\connector.py", line 540, in connect
    proto = await self._create_connection(req, traces, timeout)
  File "C:\Users\milan\OneDrive\Документы\Innopolis_studying\1_year\2_sem\well_wisher_inno_bot\venv\lib\site-packages\aiohttp\connector.py", line 901, in _create_connection
    _, proto = await self._create_direct_connection(req, traces, timeout)
  File "C:\Users\milan\OneDrive\Документы\Innopolis_studying\1_year\2_sem\well_wisher_inno_bot\venv\lib\site-packages\aiohttp\connector.py", line 1166, in _create_direct_connection
    raise ClientConnectorError(req.connection_key, exc) from exc
aiohttp.client_exceptions.ClientConnectorError: Cannot connect to host api.telegram.org:443 ssl:default [getaddrinfo failed]

During handling of the above exception, another exception occurred:

Traceback (most recent call last):
  File "C:\Users\milan\OneDrive\Документы\Innopolis_studying\1_year\2_sem\well_wisher_inno_bot\venv\lib\site-packages\aiogram\dispatcher\dispatcher.py", line 381, in start_polling
    updates = await self.bot.get_updates(
  File "C:\Users\milan\OneDrive\Документы\Innopolis_studying\1_year\2_sem\well_wisher_inno_bot\venv\lib\site-packages\aiogram\bot\bot.py", line 110, in get_updates
    result = await self.request(api.Methods.GET_UPDATES, payload)
  File "C:\Users\milan\OneDrive\Документы\Innopolis_studying\1_year\2_sem\well_wisher_inno_bot\venv\lib\site-packages\aiogram\bot\base.py", line 236, in request
    return await api.make_request(await self.get_session(), self.server, self.__token, method, data, files,
  File "C:\Users\milan\OneDrive\Документы\Innopolis_studying\1_year\2_sem\well_wisher_inno_bot\venv\lib\site-packages\aiogram\bot\api.py", line 142, in make_request
    raise exceptions.NetworkError(f"aiohttp client throws an error: {e.__class__.__name__}: {e}")
aiogram.utils.exceptions.NetworkError: Aiohttp client throws an error: ClientConnectorError: Cannot connect to host api.telegram.org:443 ssl:default [getaddrinfo failed]
12:35:31 aiogram.dispatcher.dispatcher ERROR Cause exception while getting updates.
Traceback (most recent call last):
  File "C:\Users\milan\OneDrive\Документы\Innopolis_studying\1_year\2_sem\well_wisher_inno_bot\venv\lib\site-packages\aiohttp\connector.py", line 1152, in _create_direct_connection
    hosts = await asyncio.shield(host_resolved)
  File "C:\Users\milan\OneDrive\Документы\Innopolis_studying\1_year\2_sem\well_wisher_inno_bot\venv\lib\site-packages\aiohttp\connector.py", line 874, in _resolve_host
    addrs = await self._resolver.resolve(host, port, family=self._family)
  File "C:\Users\milan\OneDrive\Документы\Innopolis_studying\1_year\2_sem\well_wisher_inno_bot\venv\lib\site-packages\aiohttp\resolver.py", line 33, in resolve
    infos = await self._loop.getaddrinfo(
  File "C:\Users\milan\AppData\Local\Programs\Python\Python310\lib\asyncio\base_events.py", line 860, in getaddrinfo
    return await self.run_in_executor(
  File "C:\Users\milan\AppData\Local\Programs\Python\Python310\lib\concurrent\futures\thread.py", line 58, in run
    result = self.fn(*self.args, **self.kwargs)
  File "C:\Users\milan\AppData\Local\Programs\Python\Python310\lib\socket.py", line 955, in getaddrinfo
    for res in _socket.getaddrinfo(host, port, family, type, proto, flags):
socket.gaierror: [Errno 11004] getaddrinfo failed

The above exception was the direct cause of the following exception:

Traceback (most recent call last):
  File "C:\Users\milan\OneDrive\Документы\Innopolis_studying\1_year\2_sem\well_wisher_inno_bot\venv\lib\site-packages\aiogram\bot\api.py", line 139, in make_request
    async with session.post(url, data=req, **kwargs) as response:
  File "C:\Users\milan\OneDrive\Документы\Innopolis_studying\1_year\2_sem\well_wisher_inno_bot\venv\lib\site-packages\aiohttp\client.py", line 1141, in __aenter__
    self._resp = await self._coro
  File "C:\Users\milan\OneDrive\Документы\Innopolis_studying\1_year\2_sem\well_wisher_inno_bot\venv\lib\site-packages\aiohttp\client.py", line 536, in _request
    conn = await self._connector.connect(
  File "C:\Users\milan\OneDrive\Документы\Innopolis_studying\1_year\2_sem\well_wisher_inno_bot\venv\lib\site-packages\aiohttp\connector.py", line 540, in connect
    proto = await self._create_connection(req, traces, timeout)
  File "C:\Users\milan\OneDrive\Документы\Innopolis_studying\1_year\2_sem\well_wisher_inno_bot\venv\lib\site-packages\aiohttp\connector.py", line 901, in _create_connection
    _, proto = await self._create_direct_connection(req, traces, timeout)
  File "C:\Users\milan\OneDrive\Документы\Innopolis_studying\1_year\2_sem\well_wisher_inno_bot\venv\lib\site-packages\aiohttp\connector.py", line 1166, in _create_direct_connection
    raise ClientConnectorError(req.connection_key, exc) from exc
aiohttp.client_exceptions.ClientConnectorError: Cannot connect to host api.telegram.org:443 ssl:default [getaddrinfo failed]

During handling of the above exception, another exception occurred:

Traceback (most recent call last):
  File "C:\Users\milan\OneDrive\Документы\Innopolis_studying\1_year\2_sem\well_wisher_inno_bot\venv\lib\site-packages\aiogram\dispatcher\dispatcher.py", line 381, in start_polling
    updates = await self.bot.get_updates(
  File "C:\Users\milan\OneDrive\Документы\Innopolis_studying\1_year\2_sem\well_wisher_inno_bot\venv\lib\site-packages\aiogram\bot\bot.py", line 110, in get_updates
    result = await self.request(api.Methods.GET_UPDATES, payload)
  File "C:\Users\milan\OneDrive\Документы\Innopolis_studying\1_year\2_sem\well_wisher_inno_bot\venv\lib\site-packages\aiogram\bot\base.py", line 236, in request
    return await api.make_request(await self.get_session(), self.server, self.__token, method, data, files,
  File "C:\Users\milan\OneDrive\Документы\Innopolis_studying\1_year\2_sem\well_wisher_inno_bot\venv\lib\site-packages\aiogram\bot\api.py", line 142, in make_request
    raise exceptions.NetworkError(f"aiohttp client throws an error: {e.__class__.__name__}: {e}")
aiogram.utils.exceptions.NetworkError: Aiohttp client throws an error: ClientConnectorError: Cannot connect to host api.telegram.org:443 ssl:default [getaddrinfo failed]
12:35:36 aiogram.dispatcher.dispatcher ERROR Cause exception while getting updates.
Traceback (most recent call last):
  File "C:\Users\milan\OneDrive\Документы\Innopolis_studying\1_year\2_sem\well_wisher_inno_bot\venv\lib\site-packages\aiohttp\connector.py", line 1152, in _create_direct_connection
    hosts = await asyncio.shield(host_resolved)
  File "C:\Users\milan\OneDrive\Документы\Innopolis_studying\1_year\2_sem\well_wisher_inno_bot\venv\lib\site-packages\aiohttp\connector.py", line 874, in _resolve_host
    addrs = await self._resolver.resolve(host, port, family=self._family)
  File "C:\Users\milan\OneDrive\Документы\Innopolis_studying\1_year\2_sem\well_wisher_inno_bot\venv\lib\site-packages\aiohttp\resolver.py", line 33, in resolve
    infos = await self._loop.getaddrinfo(
  File "C:\Users\milan\AppData\Local\Programs\Python\Python310\lib\asyncio\base_events.py", line 860, in getaddrinfo
    return await self.run_in_executor(
  File "C:\Users\milan\AppData\Local\Programs\Python\Python310\lib\concurrent\futures\thread.py", line 58, in run
    result = self.fn(*self.args, **self.kwargs)
  File "C:\Users\milan\AppData\Local\Programs\Python\Python310\lib\socket.py", line 955, in getaddrinfo
    for res in _socket.getaddrinfo(host, port, family, type, proto, flags):
socket.gaierror: [Errno 11004] getaddrinfo failed

The above exception was the direct cause of the following exception:

Traceback (most recent call last):
  File "C:\Users\milan\OneDrive\Документы\Innopolis_studying\1_year\2_sem\well_wisher_inno_bot\venv\lib\site-packages\aiogram\bot\api.py", line 139, in make_request
    async with session.post(url, data=req, **kwargs) as response:
  File "C:\Users\milan\OneDrive\Документы\Innopolis_studying\1_year\2_sem\well_wisher_inno_bot\venv\lib\site-packages\aiohttp\client.py", line 1141, in __aenter__
    self._resp = await self._coro
  File "C:\Users\milan\OneDrive\Документы\Innopolis_studying\1_year\2_sem\well_wisher_inno_bot\venv\lib\site-packages\aiohttp\client.py", line 536, in _request
    conn = await self._connector.connect(
  File "C:\Users\milan\OneDrive\Документы\Innopolis_studying\1_year\2_sem\well_wisher_inno_bot\venv\lib\site-packages\aiohttp\connector.py", line 540, in connect
    proto = await self._create_connection(req, traces, timeout)
  File "C:\Users\milan\OneDrive\Документы\Innopolis_studying\1_year\2_sem\well_wisher_inno_bot\venv\lib\site-packages\aiohttp\connector.py", line 901, in _create_connection
    _, proto = await self._create_direct_connection(req, traces, timeout)
  File "C:\Users\milan\OneDrive\Документы\Innopolis_studying\1_year\2_sem\well_wisher_inno_bot\venv\lib\site-packages\aiohttp\connector.py", line 1166, in _create_direct_connection
    raise ClientConnectorError(req.connection_key, exc) from exc
aiohttp.client_exceptions.ClientConnectorError: Cannot connect to host api.telegram.org:443 ssl:default [getaddrinfo failed]

During handling of the above exception, another exception occurred:

Traceback (most recent call last):
  File "C:\Users\milan\OneDrive\Документы\Innopolis_studying\1_year\2_sem\well_wisher_inno_bot\venv\lib\site-packages\aiogram\dispatcher\dispatcher.py", line 381, in start_polling
    updates = await self.bot.get_updates(
  File "C:\Users\milan\OneDrive\Документы\Innopolis_studying\1_year\2_sem\well_wisher_inno_bot\venv\lib\site-packages\aiogram\bot\bot.py", line 110, in get_updates
    result = await self.request(api.Methods.GET_UPDATES, payload)
  File "C:\Users\milan\OneDrive\Документы\Innopolis_studying\1_year\2_sem\well_wisher_inno_bot\venv\lib\site-packages\aiogram\bot\base.py", line 236, in request
    return await api.make_request(await self.get_session(), self.server, self.__token, method, data, files,
  File "C:\Users\milan\OneDrive\Документы\Innopolis_studying\1_year\2_sem\well_wisher_inno_bot\venv\lib\site-packages\aiogram\bot\api.py", line 142, in make_request
    raise exceptions.NetworkError(f"aiohttp client throws an error: {e.__class__.__name__}: {e}")
aiogram.utils.exceptions.NetworkError: Aiohttp client throws an error: ClientConnectorError: Cannot connect to host api.telegram.org:443 ssl:default [getaddrinfo failed]
12:35:41 aiogram.dispatcher.dispatcher ERROR Cause exception while getting updates.
Traceback (most recent call last):
  File "C:\Users\milan\OneDrive\Документы\Innopolis_studying\1_year\2_sem\well_wisher_inno_bot\venv\lib\site-packages\aiohttp\connector.py", line 1152, in _create_direct_connection
    hosts = await asyncio.shield(host_resolved)
  File "C:\Users\milan\OneDrive\Документы\Innopolis_studying\1_year\2_sem\well_wisher_inno_bot\venv\lib\site-packages\aiohttp\connector.py", line 874, in _resolve_host
    addrs = await self._resolver.resolve(host, port, family=self._family)
  File "C:\Users\milan\OneDrive\Документы\Innopolis_studying\1_year\2_sem\well_wisher_inno_bot\venv\lib\site-packages\aiohttp\resolver.py", line 33, in resolve
    infos = await self._loop.getaddrinfo(
  File "C:\Users\milan\AppData\Local\Programs\Python\Python310\lib\asyncio\base_events.py", line 860, in getaddrinfo
    return await self.run_in_executor(
  File "C:\Users\milan\AppData\Local\Programs\Python\Python310\lib\concurrent\futures\thread.py", line 58, in run
    result = self.fn(*self.args, **self.kwargs)
  File "C:\Users\milan\AppData\Local\Programs\Python\Python310\lib\socket.py", line 955, in getaddrinfo
    for res in _socket.getaddrinfo(host, port, family, type, proto, flags):
socket.gaierror: [Errno 11004] getaddrinfo failed

The above exception was the direct cause of the following exception:

Traceback (most recent call last):
  File "C:\Users\milan\OneDrive\Документы\Innopolis_studying\1_year\2_sem\well_wisher_inno_bot\venv\lib\site-packages\aiogram\bot\api.py", line 139, in make_request
    async with session.post(url, data=req, **kwargs) as response:
  File "C:\Users\milan\OneDrive\Документы\Innopolis_studying\1_year\2_sem\well_wisher_inno_bot\venv\lib\site-packages\aiohttp\client.py", line 1141, in __aenter__
    self._resp = await self._coro
  File "C:\Users\milan\OneDrive\Документы\Innopolis_studying\1_year\2_sem\well_wisher_inno_bot\venv\lib\site-packages\aiohttp\client.py", line 536, in _request
    conn = await self._connector.connect(
  File "C:\Users\milan\OneDrive\Документы\Innopolis_studying\1_year\2_sem\well_wisher_inno_bot\venv\lib\site-packages\aiohttp\connector.py", line 540, in connect
    proto = await self._create_connection(req, traces, timeout)
  File "C:\Users\milan\OneDrive\Документы\Innopolis_studying\1_year\2_sem\well_wisher_inno_bot\venv\lib\site-packages\aiohttp\connector.py", line 901, in _create_connection
    _, proto = await self._create_direct_connection(req, traces, timeout)
  File "C:\Users\milan\OneDrive\Документы\Innopolis_studying\1_year\2_sem\well_wisher_inno_bot\venv\lib\site-packages\aiohttp\connector.py", line 1166, in _create_direct_connection
    raise ClientConnectorError(req.connection_key, exc) from exc
aiohttp.client_exceptions.ClientConnectorError: Cannot connect to host api.telegram.org:443 ssl:default [getaddrinfo failed]

During handling of the above exception, another exception occurred:

Traceback (most recent call last):
  File "C:\Users\milan\OneDrive\Документы\Innopolis_studying\1_year\2_sem\well_wisher_inno_bot\venv\lib\site-packages\aiogram\dispatcher\dispatcher.py", line 381, in start_polling
    updates = await self.bot.get_updates(
  File "C:\Users\milan\OneDrive\Документы\Innopolis_studying\1_year\2_sem\well_wisher_inno_bot\venv\lib\site-packages\aiogram\bot\bot.py", line 110, in get_updates
    result = await self.request(api.Methods.GET_UPDATES, payload)
  File "C:\Users\milan\OneDrive\Документы\Innopolis_studying\1_year\2_sem\well_wisher_inno_bot\venv\lib\site-packages\aiogram\bot\base.py", line 236, in request
    return await api.make_request(await self.get_session(), self.server, self.__token, method, data, files,
  File "C:\Users\milan\OneDrive\Документы\Innopolis_studying\1_year\2_sem\well_wisher_inno_bot\venv\lib\site-packages\aiogram\bot\api.py", line 142, in make_request
    raise exceptions.NetworkError(f"aiohttp client throws an error: {e.__class__.__name__}: {e}")
aiogram.utils.exceptions.NetworkError: Aiohttp client throws an error: ClientConnectorError: Cannot connect to host api.telegram.org:443 ssl:default [getaddrinfo failed]
12:35:46 aiogram.dispatcher.dispatcher ERROR Cause exception while getting updates.
Traceback (most recent call last):
  File "C:\Users\milan\OneDrive\Документы\Innopolis_studying\1_year\2_sem\well_wisher_inno_bot\venv\lib\site-packages\aiohttp\connector.py", line 1152, in _create_direct_connection
    hosts = await asyncio.shield(host_resolved)
  File "C:\Users\milan\OneDrive\Документы\Innopolis_studying\1_year\2_sem\well_wisher_inno_bot\venv\lib\site-packages\aiohttp\connector.py", line 874, in _resolve_host
    addrs = await self._resolver.resolve(host, port, family=self._family)
  File "C:\Users\milan\OneDrive\Документы\Innopolis_studying\1_year\2_sem\well_wisher_inno_bot\venv\lib\site-packages\aiohttp\resolver.py", line 33, in resolve
    infos = await self._loop.getaddrinfo(
  File "C:\Users\milan\AppData\Local\Programs\Python\Python310\lib\asyncio\base_events.py", line 860, in getaddrinfo
    return await self.run_in_executor(
  File "C:\Users\milan\AppData\Local\Programs\Python\Python310\lib\concurrent\futures\thread.py", line 58, in run
    result = self.fn(*self.args, **self.kwargs)
  File "C:\Users\milan\AppData\Local\Programs\Python\Python310\lib\socket.py", line 955, in getaddrinfo
    for res in _socket.getaddrinfo(host, port, family, type, proto, flags):
socket.gaierror: [Errno 11004] getaddrinfo failed

The above exception was the direct cause of the following exception:

Traceback (most recent call last):
  File "C:\Users\milan\OneDrive\Документы\Innopolis_studying\1_year\2_sem\well_wisher_inno_bot\venv\lib\site-packages\aiogram\bot\api.py", line 139, in make_request
    async with session.post(url, data=req, **kwargs) as response:
  File "C:\Users\milan\OneDrive\Документы\Innopolis_studying\1_year\2_sem\well_wisher_inno_bot\venv\lib\site-packages\aiohttp\client.py", line 1141, in __aenter__
    self._resp = await self._coro
  File "C:\Users\milan\OneDrive\Документы\Innopolis_studying\1_year\2_sem\well_wisher_inno_bot\venv\lib\site-packages\aiohttp\client.py", line 536, in _request
    conn = await self._connector.connect(
  File "C:\Users\milan\OneDrive\Документы\Innopolis_studying\1_year\2_sem\well_wisher_inno_bot\venv\lib\site-packages\aiohttp\connector.py", line 540, in connect
    proto = await self._create_connection(req, traces, timeout)
  File "C:\Users\milan\OneDrive\Документы\Innopolis_studying\1_year\2_sem\well_wisher_inno_bot\venv\lib\site-packages\aiohttp\connector.py", line 901, in _create_connection
    _, proto = await self._create_direct_connection(req, traces, timeout)
  File "C:\Users\milan\OneDrive\Документы\Innopolis_studying\1_year\2_sem\well_wisher_inno_bot\venv\lib\site-packages\aiohttp\connector.py", line 1166, in _create_direct_connection
    raise ClientConnectorError(req.connection_key, exc) from exc
aiohttp.client_exceptions.ClientConnectorError: Cannot connect to host api.telegram.org:443 ssl:default [getaddrinfo failed]

During handling of the above exception, another exception occurred:

Traceback (most recent call last):
  File "C:\Users\milan\OneDrive\Документы\Innopolis_studying\1_year\2_sem\well_wisher_inno_bot\venv\lib\site-packages\aiogram\dispatcher\dispatcher.py", line 381, in start_polling
    updates = await self.bot.get_updates(
  File "C:\Users\milan\OneDrive\Документы\Innopolis_studying\1_year\2_sem\well_wisher_inno_bot\venv\lib\site-packages\aiogram\bot\bot.py", line 110, in get_updates
    result = await self.request(api.Methods.GET_UPDATES, payload)
  File "C:\Users\milan\OneDrive\Документы\Innopolis_studying\1_year\2_sem\well_wisher_inno_bot\venv\lib\site-packages\aiogram\bot\base.py", line 236, in request
    return await api.make_request(await self.get_session(), self.server, self.__token, method, data, files,
  File "C:\Users\milan\OneDrive\Документы\Innopolis_studying\1_year\2_sem\well_wisher_inno_bot\venv\lib\site-packages\aiogram\bot\api.py", line 142, in make_request
    raise exceptions.NetworkError(f"aiohttp client throws an error: {e.__class__.__name__}: {e}")
aiogram.utils.exceptions.NetworkError: Aiohttp client throws an error: ClientConnectorError: Cannot connect to host api.telegram.org:443 ssl:default [getaddrinfo failed]
12:35:51 aiogram.dispatcher.dispatcher ERROR Cause exception while getting updates.
Traceback (most recent call last):
  File "C:\Users\milan\OneDrive\Документы\Innopolis_studying\1_year\2_sem\well_wisher_inno_bot\venv\lib\site-packages\aiohttp\connector.py", line 1152, in _create_direct_connection
    hosts = await asyncio.shield(host_resolved)
  File "C:\Users\milan\OneDrive\Документы\Innopolis_studying\1_year\2_sem\well_wisher_inno_bot\venv\lib\site-packages\aiohttp\connector.py", line 874, in _resolve_host
    addrs = await self._resolver.resolve(host, port, family=self._family)
  File "C:\Users\milan\OneDrive\Документы\Innopolis_studying\1_year\2_sem\well_wisher_inno_bot\venv\lib\site-packages\aiohttp\resolver.py", line 33, in resolve
    infos = await self._loop.getaddrinfo(
  File "C:\Users\milan\AppData\Local\Programs\Python\Python310\lib\asyncio\base_events.py", line 860, in getaddrinfo
    return await self.run_in_executor(
  File "C:\Users\milan\AppData\Local\Programs\Python\Python310\lib\concurrent\futures\thread.py", line 58, in run
    result = self.fn(*self.args, **self.kwargs)
  File "C:\Users\milan\AppData\Local\Programs\Python\Python310\lib\socket.py", line 955, in getaddrinfo
    for res in _socket.getaddrinfo(host, port, family, type, proto, flags):
socket.gaierror: [Errno 11004] getaddrinfo failed

The above exception was the direct cause of the following exception:

Traceback (most recent call last):
  File "C:\Users\milan\OneDrive\Документы\Innopolis_studying\1_year\2_sem\well_wisher_inno_bot\venv\lib\site-packages\aiogram\bot\api.py", line 139, in make_request
    async with session.post(url, data=req, **kwargs) as response:
  File "C:\Users\milan\OneDrive\Документы\Innopolis_studying\1_year\2_sem\well_wisher_inno_bot\venv\lib\site-packages\aiohttp\client.py", line 1141, in __aenter__
    self._resp = await self._coro
  File "C:\Users\milan\OneDrive\Документы\Innopolis_studying\1_year\2_sem\well_wisher_inno_bot\venv\lib\site-packages\aiohttp\client.py", line 536, in _request
    conn = await self._connector.connect(
  File "C:\Users\milan\OneDrive\Документы\Innopolis_studying\1_year\2_sem\well_wisher_inno_bot\venv\lib\site-packages\aiohttp\connector.py", line 540, in connect
    proto = await self._create_connection(req, traces, timeout)
  File "C:\Users\milan\OneDrive\Документы\Innopolis_studying\1_year\2_sem\well_wisher_inno_bot\venv\lib\site-packages\aiohttp\connector.py", line 901, in _create_connection
    _, proto = await self._create_direct_connection(req, traces, timeout)
  File "C:\Users\milan\OneDrive\Документы\Innopolis_studying\1_year\2_sem\well_wisher_inno_bot\venv\lib\site-packages\aiohttp\connector.py", line 1166, in _create_direct_connection
    raise ClientConnectorError(req.connection_key, exc) from exc
aiohttp.client_exceptions.ClientConnectorError: Cannot connect to host api.telegram.org:443 ssl:default [getaddrinfo failed]

During handling of the above exception, another exception occurred:

Traceback (most recent call last):
  File "C:\Users\milan\OneDrive\Документы\Innopolis_studying\1_year\2_sem\well_wisher_inno_bot\venv\lib\site-packages\aiogram\dispatcher\dispatcher.py", line 381, in start_polling
    updates = await self.bot.get_updates(
  File "C:\Users\milan\OneDrive\Документы\Innopolis_studying\1_year\2_sem\well_wisher_inno_bot\venv\lib\site-packages\aiogram\bot\bot.py", line 110, in get_updates
    result = await self.request(api.Methods.GET_UPDATES, payload)
  File "C:\Users\milan\OneDrive\Документы\Innopolis_studying\1_year\2_sem\well_wisher_inno_bot\venv\lib\site-packages\aiogram\bot\base.py", line 236, in request
    return await api.make_request(await self.get_session(), self.server, self.__token, method, data, files,
  File "C:\Users\milan\OneDrive\Документы\Innopolis_studying\1_year\2_sem\well_wisher_inno_bot\venv\lib\site-packages\aiogram\bot\api.py", line 142, in make_request
    raise exceptions.NetworkError(f"aiohttp client throws an error: {e.__class__.__name__}: {e}")
aiogram.utils.exceptions.NetworkError: Aiohttp client throws an error: ClientConnectorError: Cannot connect to host api.telegram.org:443 ssl:default [getaddrinfo failed]
12:35:56 aiogram.dispatcher.dispatcher ERROR Cause exception while getting updates.
Traceback (most recent call last):
  File "C:\Users\milan\OneDrive\Документы\Innopolis_studying\1_year\2_sem\well_wisher_inno_bot\venv\lib\site-packages\aiohttp\connector.py", line 1152, in _create_direct_connection
    hosts = await asyncio.shield(host_resolved)
  File "C:\Users\milan\OneDrive\Документы\Innopolis_studying\1_year\2_sem\well_wisher_inno_bot\venv\lib\site-packages\aiohttp\connector.py", line 874, in _resolve_host
    addrs = await self._resolver.resolve(host, port, family=self._family)
  File "C:\Users\milan\OneDrive\Документы\Innopolis_studying\1_year\2_sem\well_wisher_inno_bot\venv\lib\site-packages\aiohttp\resolver.py", line 33, in resolve
    infos = await self._loop.getaddrinfo(
  File "C:\Users\milan\AppData\Local\Programs\Python\Python310\lib\asyncio\base_events.py", line 860, in getaddrinfo
    return await self.run_in_executor(
  File "C:\Users\milan\AppData\Local\Programs\Python\Python310\lib\concurrent\futures\thread.py", line 58, in run
    result = self.fn(*self.args, **self.kwargs)
  File "C:\Users\milan\AppData\Local\Programs\Python\Python310\lib\socket.py", line 955, in getaddrinfo
    for res in _socket.getaddrinfo(host, port, family, type, proto, flags):
socket.gaierror: [Errno 11004] getaddrinfo failed

The above exception was the direct cause of the following exception:

Traceback (most recent call last):
  File "C:\Users\milan\OneDrive\Документы\Innopolis_studying\1_year\2_sem\well_wisher_inno_bot\venv\lib\site-packages\aiogram\bot\api.py", line 139, in make_request
    async with session.post(url, data=req, **kwargs) as response:
  File "C:\Users\milan\OneDrive\Документы\Innopolis_studying\1_year\2_sem\well_wisher_inno_bot\venv\lib\site-packages\aiohttp\client.py", line 1141, in __aenter__
    self._resp = await self._coro
  File "C:\Users\milan\OneDrive\Документы\Innopolis_studying\1_year\2_sem\well_wisher_inno_bot\venv\lib\site-packages\aiohttp\client.py", line 536, in _request
    conn = await self._connector.connect(
  File "C:\Users\milan\OneDrive\Документы\Innopolis_studying\1_year\2_sem\well_wisher_inno_bot\venv\lib\site-packages\aiohttp\connector.py", line 540, in connect
    proto = await self._create_connection(req, traces, timeout)
  File "C:\Users\milan\OneDrive\Документы\Innopolis_studying\1_year\2_sem\well_wisher_inno_bot\venv\lib\site-packages\aiohttp\connector.py", line 901, in _create_connection
    _, proto = await self._create_direct_connection(req, traces, timeout)
  File "C:\Users\milan\OneDrive\Документы\Innopolis_studying\1_year\2_sem\well_wisher_inno_bot\venv\lib\site-packages\aiohttp\connector.py", line 1166, in _create_direct_connection
    raise ClientConnectorError(req.connection_key, exc) from exc
aiohttp.client_exceptions.ClientConnectorError: Cannot connect to host api.telegram.org:443 ssl:default [getaddrinfo failed]

During handling of the above exception, another exception occurred:

Traceback (most recent call last):
  File "C:\Users\milan\OneDrive\Документы\Innopolis_studying\1_year\2_sem\well_wisher_inno_bot\venv\lib\site-packages\aiogram\dispatcher\dispatcher.py", line 381, in start_polling
    updates = await self.bot.get_updates(
  File "C:\Users\milan\OneDrive\Документы\Innopolis_studying\1_year\2_sem\well_wisher_inno_bot\venv\lib\site-packages\aiogram\bot\bot.py", line 110, in get_updates
    result = await self.request(api.Methods.GET_UPDATES, payload)
  File "C:\Users\milan\OneDrive\Документы\Innopolis_studying\1_year\2_sem\well_wisher_inno_bot\venv\lib\site-packages\aiogram\bot\base.py", line 236, in request
    return await api.make_request(await self.get_session(), self.server, self.__token, method, data, files,
  File "C:\Users\milan\OneDrive\Документы\Innopolis_studying\1_year\2_sem\well_wisher_inno_bot\venv\lib\site-packages\aiogram\bot\api.py", line 142, in make_request
    raise exceptions.NetworkError(f"aiohttp client throws an error: {e.__class__.__name__}: {e}")
aiogram.utils.exceptions.NetworkError: Aiohttp client throws an error: ClientConnectorError: Cannot connect to host api.telegram.org:443 ssl:default [getaddrinfo failed]
12:36:01 aiogram.dispatcher.dispatcher ERROR Cause exception while getting updates.
Traceback (most recent call last):
  File "C:\Users\milan\OneDrive\Документы\Innopolis_studying\1_year\2_sem\well_wisher_inno_bot\venv\lib\site-packages\aiohttp\connector.py", line 1152, in _create_direct_connection
    hosts = await asyncio.shield(host_resolved)
  File "C:\Users\milan\OneDrive\Документы\Innopolis_studying\1_year\2_sem\well_wisher_inno_bot\venv\lib\site-packages\aiohttp\connector.py", line 874, in _resolve_host
    addrs = await self._resolver.resolve(host, port, family=self._family)
  File "C:\Users\milan\OneDrive\Документы\Innopolis_studying\1_year\2_sem\well_wisher_inno_bot\venv\lib\site-packages\aiohttp\resolver.py", line 33, in resolve
    infos = await self._loop.getaddrinfo(
  File "C:\Users\milan\AppData\Local\Programs\Python\Python310\lib\asyncio\base_events.py", line 860, in getaddrinfo
    return await self.run_in_executor(
  File "C:\Users\milan\AppData\Local\Programs\Python\Python310\lib\concurrent\futures\thread.py", line 58, in run
    result = self.fn(*self.args, **self.kwargs)
  File "C:\Users\milan\AppData\Local\Programs\Python\Python310\lib\socket.py", line 955, in getaddrinfo
    for res in _socket.getaddrinfo(host, port, family, type, proto, flags):
socket.gaierror: [Errno 11004] getaddrinfo failed

The above exception was the direct cause of the following exception:

Traceback (most recent call last):
  File "C:\Users\milan\OneDrive\Документы\Innopolis_studying\1_year\2_sem\well_wisher_inno_bot\venv\lib\site-packages\aiogram\bot\api.py", line 139, in make_request
    async with session.post(url, data=req, **kwargs) as response:
  File "C:\Users\milan\OneDrive\Документы\Innopolis_studying\1_year\2_sem\well_wisher_inno_bot\venv\lib\site-packages\aiohttp\client.py", line 1141, in __aenter__
    self._resp = await self._coro
  File "C:\Users\milan\OneDrive\Документы\Innopolis_studying\1_year\2_sem\well_wisher_inno_bot\venv\lib\site-packages\aiohttp\client.py", line 536, in _request
    conn = await self._connector.connect(
  File "C:\Users\milan\OneDrive\Документы\Innopolis_studying\1_year\2_sem\well_wisher_inno_bot\venv\lib\site-packages\aiohttp\connector.py", line 540, in connect
    proto = await self._create_connection(req, traces, timeout)
  File "C:\Users\milan\OneDrive\Документы\Innopolis_studying\1_year\2_sem\well_wisher_inno_bot\venv\lib\site-packages\aiohttp\connector.py", line 901, in _create_connection
    _, proto = await self._create_direct_connection(req, traces, timeout)
  File "C:\Users\milan\OneDrive\Документы\Innopolis_studying\1_year\2_sem\well_wisher_inno_bot\venv\lib\site-packages\aiohttp\connector.py", line 1166, in _create_direct_connection
    raise ClientConnectorError(req.connection_key, exc) from exc
aiohttp.client_exceptions.ClientConnectorError: Cannot connect to host api.telegram.org:443 ssl:default [getaddrinfo failed]

During handling of the above exception, another exception occurred:

Traceback (most recent call last):
  File "C:\Users\milan\OneDrive\Документы\Innopolis_studying\1_year\2_sem\well_wisher_inno_bot\venv\lib\site-packages\aiogram\dispatcher\dispatcher.py", line 381, in start_polling
    updates = await self.bot.get_updates(
  File "C:\Users\milan\OneDrive\Документы\Innopolis_studying\1_year\2_sem\well_wisher_inno_bot\venv\lib\site-packages\aiogram\bot\bot.py", line 110, in get_updates
    result = await self.request(api.Methods.GET_UPDATES, payload)
  File "C:\Users\milan\OneDrive\Документы\Innopolis_studying\1_year\2_sem\well_wisher_inno_bot\venv\lib\site-packages\aiogram\bot\base.py", line 236, in request
    return await api.make_request(await self.get_session(), self.server, self.__token, method, data, files,
  File "C:\Users\milan\OneDrive\Документы\Innopolis_studying\1_year\2_sem\well_wisher_inno_bot\venv\lib\site-packages\aiogram\bot\api.py", line 142, in make_request
    raise exceptions.NetworkError(f"aiohttp client throws an error: {e.__class__.__name__}: {e}")
aiogram.utils.exceptions.NetworkError: Aiohttp client throws an error: ClientConnectorError: Cannot connect to host api.telegram.org:443 ssl:default [getaddrinfo failed]
12:36:06 aiogram.dispatcher.dispatcher ERROR Cause exception while getting updates.
Traceback (most recent call last):
  File "C:\Users\milan\OneDrive\Документы\Innopolis_studying\1_year\2_sem\well_wisher_inno_bot\venv\lib\site-packages\aiohttp\connector.py", line 1152, in _create_direct_connection
    hosts = await asyncio.shield(host_resolved)
  File "C:\Users\milan\OneDrive\Документы\Innopolis_studying\1_year\2_sem\well_wisher_inno_bot\venv\lib\site-packages\aiohttp\connector.py", line 874, in _resolve_host
    addrs = await self._resolver.resolve(host, port, family=self._family)
  File "C:\Users\milan\OneDrive\Документы\Innopolis_studying\1_year\2_sem\well_wisher_inno_bot\venv\lib\site-packages\aiohttp\resolver.py", line 33, in resolve
    infos = await self._loop.getaddrinfo(
  File "C:\Users\milan\AppData\Local\Programs\Python\Python310\lib\asyncio\base_events.py", line 860, in getaddrinfo
    return await self.run_in_executor(
  File "C:\Users\milan\AppData\Local\Programs\Python\Python310\lib\concurrent\futures\thread.py", line 58, in run
    result = self.fn(*self.args, **self.kwargs)
  File "C:\Users\milan\AppData\Local\Programs\Python\Python310\lib\socket.py", line 955, in getaddrinfo
    for res in _socket.getaddrinfo(host, port, family, type, proto, flags):
socket.gaierror: [Errno 11004] getaddrinfo failed

The above exception was the direct cause of the following exception:

Traceback (most recent call last):
  File "C:\Users\milan\OneDrive\Документы\Innopolis_studying\1_year\2_sem\well_wisher_inno_bot\venv\lib\site-packages\aiogram\bot\api.py", line 139, in make_request
    async with session.post(url, data=req, **kwargs) as response:
  File "C:\Users\milan\OneDrive\Документы\Innopolis_studying\1_year\2_sem\well_wisher_inno_bot\venv\lib\site-packages\aiohttp\client.py", line 1141, in __aenter__
    self._resp = await self._coro
  File "C:\Users\milan\OneDrive\Документы\Innopolis_studying\1_year\2_sem\well_wisher_inno_bot\venv\lib\site-packages\aiohttp\client.py", line 536, in _request
    conn = await self._connector.connect(
  File "C:\Users\milan\OneDrive\Документы\Innopolis_studying\1_year\2_sem\well_wisher_inno_bot\venv\lib\site-packages\aiohttp\connector.py", line 540, in connect
    proto = await self._create_connection(req, traces, timeout)
  File "C:\Users\milan\OneDrive\Документы\Innopolis_studying\1_year\2_sem\well_wisher_inno_bot\venv\lib\site-packages\aiohttp\connector.py", line 901, in _create_connection
    _, proto = await self._create_direct_connection(req, traces, timeout)
  File "C:\Users\milan\OneDrive\Документы\Innopolis_studying\1_year\2_sem\well_wisher_inno_bot\venv\lib\site-packages\aiohttp\connector.py", line 1166, in _create_direct_connection
    raise ClientConnectorError(req.connection_key, exc) from exc
aiohttp.client_exceptions.ClientConnectorError: Cannot connect to host api.telegram.org:443 ssl:default [getaddrinfo failed]

During handling of the above exception, another exception occurred:

Traceback (most recent call last):
  File "C:\Users\milan\OneDrive\Документы\Innopolis_studying\1_year\2_sem\well_wisher_inno_bot\venv\lib\site-packages\aiogram\dispatcher\dispatcher.py", line 381, in start_polling
    updates = await self.bot.get_updates(
  File "C:\Users\milan\OneDrive\Документы\Innopolis_studying\1_year\2_sem\well_wisher_inno_bot\venv\lib\site-packages\aiogram\bot\bot.py", line 110, in get_updates
    result = await self.request(api.Methods.GET_UPDATES, payload)
  File "C:\Users\milan\OneDrive\Документы\Innopolis_studying\1_year\2_sem\well_wisher_inno_bot\venv\lib\site-packages\aiogram\bot\base.py", line 236, in request
    return await api.make_request(await self.get_session(), self.server, self.__token, method, data, files,
  File "C:\Users\milan\OneDrive\Документы\Innopolis_studying\1_year\2_sem\well_wisher_inno_bot\venv\lib\site-packages\aiogram\bot\api.py", line 142, in make_request
    raise exceptions.NetworkError(f"aiohttp client throws an error: {e.__class__.__name__}: {e}")
aiogram.utils.exceptions.NetworkError: Aiohttp client throws an error: ClientConnectorError: Cannot connect to host api.telegram.org:443 ssl:default [getaddrinfo failed]
13:23:40 aiogram.dispatcher.dispatcher ERROR Cause exception while getting updates.
Traceback (most recent call last):
  File "C:\Users\milan\OneDrive\Документы\Innopolis_studying\1_year\2_sem\well_wisher_inno_bot\venv\lib\site-packages\aiohttp\connector.py", line 1152, in _create_direct_connection
    hosts = await asyncio.shield(host_resolved)
  File "C:\Users\milan\OneDrive\Документы\Innopolis_studying\1_year\2_sem\well_wisher_inno_bot\venv\lib\site-packages\aiohttp\connector.py", line 874, in _resolve_host
    addrs = await self._resolver.resolve(host, port, family=self._family)
  File "C:\Users\milan\OneDrive\Документы\Innopolis_studying\1_year\2_sem\well_wisher_inno_bot\venv\lib\site-packages\aiohttp\resolver.py", line 33, in resolve
    infos = await self._loop.getaddrinfo(
  File "C:\Users\milan\AppData\Local\Programs\Python\Python310\lib\asyncio\base_events.py", line 860, in getaddrinfo
    return await self.run_in_executor(
  File "C:\Users\milan\AppData\Local\Programs\Python\Python310\lib\concurrent\futures\thread.py", line 58, in run
    result = self.fn(*self.args, **self.kwargs)
  File "C:\Users\milan\AppData\Local\Programs\Python\Python310\lib\socket.py", line 955, in getaddrinfo
    for res in _socket.getaddrinfo(host, port, family, type, proto, flags):
socket.gaierror: [Errno 11004] getaddrinfo failed

The above exception was the direct cause of the following exception:

Traceback (most recent call last):
  File "C:\Users\milan\OneDrive\Документы\Innopolis_studying\1_year\2_sem\well_wisher_inno_bot\venv\lib\site-packages\aiogram\bot\api.py", line 139, in make_request
    async with session.post(url, data=req, **kwargs) as response:
  File "C:\Users\milan\OneDrive\Документы\Innopolis_studying\1_year\2_sem\well_wisher_inno_bot\venv\lib\site-packages\aiohttp\client.py", line 1141, in __aenter__
    self._resp = await self._coro
  File "C:\Users\milan\OneDrive\Документы\Innopolis_studying\1_year\2_sem\well_wisher_inno_bot\venv\lib\site-packages\aiohttp\client.py", line 536, in _request
    conn = await self._connector.connect(
  File "C:\Users\milan\OneDrive\Документы\Innopolis_studying\1_year\2_sem\well_wisher_inno_bot\venv\lib\site-packages\aiohttp\connector.py", line 540, in connect
    proto = await self._create_connection(req, traces, timeout)
  File "C:\Users\milan\OneDrive\Документы\Innopolis_studying\1_year\2_sem\well_wisher_inno_bot\venv\lib\site-packages\aiohttp\connector.py", line 901, in _create_connection
    _, proto = await self._create_direct_connection(req, traces, timeout)
  File "C:\Users\milan\OneDrive\Документы\Innopolis_studying\1_year\2_sem\well_wisher_inno_bot\venv\lib\site-packages\aiohttp\connector.py", line 1166, in _create_direct_connection
    raise ClientConnectorError(req.connection_key, exc) from exc
aiohttp.client_exceptions.ClientConnectorError: Cannot connect to host api.telegram.org:443 ssl:default [getaddrinfo failed]

During handling of the above exception, another exception occurred:

Traceback (most recent call last):
  File "C:\Users\milan\OneDrive\Документы\Innopolis_studying\1_year\2_sem\well_wisher_inno_bot\venv\lib\site-packages\aiogram\dispatcher\dispatcher.py", line 381, in start_polling
    updates = await self.bot.get_updates(
  File "C:\Users\milan\OneDrive\Документы\Innopolis_studying\1_year\2_sem\well_wisher_inno_bot\venv\lib\site-packages\aiogram\bot\bot.py", line 110, in get_updates
    result = await self.request(api.Methods.GET_UPDATES, payload)
  File "C:\Users\milan\OneDrive\Документы\Innopolis_studying\1_year\2_sem\well_wisher_inno_bot\venv\lib\site-packages\aiogram\bot\base.py", line 236, in request
    return await api.make_request(await self.get_session(), self.server, self.__token, method, data, files,
  File "C:\Users\milan\OneDrive\Документы\Innopolis_studying\1_year\2_sem\well_wisher_inno_bot\venv\lib\site-packages\aiogram\bot\api.py", line 142, in make_request
    raise exceptions.NetworkError(f"aiohttp client throws an error: {e.__class__.__name__}: {e}")
aiogram.utils.exceptions.NetworkError: Aiohttp client throws an error: ClientConnectorError: Cannot connect to host api.telegram.org:443 ssl:default [getaddrinfo failed]
13:47:29 aiogram.dispatcher.dispatcher ERROR Cause exception while getting updates.
Traceback (most recent call last):
  File "C:\Users\milan\OneDrive\Документы\Innopolis_studying\1_year\2_sem\well_wisher_inno_bot\venv\lib\site-packages\aiogram\dispatcher\dispatcher.py", line 381, in start_polling
    updates = await self.bot.get_updates(
  File "C:\Users\milan\OneDrive\Документы\Innopolis_studying\1_year\2_sem\well_wisher_inno_bot\venv\lib\site-packages\aiogram\bot\bot.py", line 110, in get_updates
    result = await self.request(api.Methods.GET_UPDATES, payload)
  File "C:\Users\milan\OneDrive\Документы\Innopolis_studying\1_year\2_sem\well_wisher_inno_bot\venv\lib\site-packages\aiogram\bot\base.py", line 236, in request
    return await api.make_request(await self.get_session(), self.server, self.__token, method, data, files,
  File "C:\Users\milan\OneDrive\Документы\Innopolis_studying\1_year\2_sem\well_wisher_inno_bot\venv\lib\site-packages\aiogram\bot\api.py", line 139, in make_request
    async with session.post(url, data=req, **kwargs) as response:
  File "C:\Users\milan\OneDrive\Документы\Innopolis_studying\1_year\2_sem\well_wisher_inno_bot\venv\lib\site-packages\aiohttp\client.py", line 1141, in __aenter__
    self._resp = await self._coro
  File "C:\Users\milan\OneDrive\Документы\Innopolis_studying\1_year\2_sem\well_wisher_inno_bot\venv\lib\site-packages\aiohttp\client.py", line 560, in _request
    await resp.start(conn)
  File "C:\Users\milan\OneDrive\Документы\Innopolis_studying\1_year\2_sem\well_wisher_inno_bot\venv\lib\site-packages\aiohttp\client_reqrep.py", line 894, in start
    with self._timer:
  File "C:\Users\milan\OneDrive\Документы\Innopolis_studying\1_year\2_sem\well_wisher_inno_bot\venv\lib\site-packages\aiohttp\helpers.py", line 721, in __exit__
    raise asyncio.TimeoutError from None
asyncio.exceptions.TimeoutError
16:18:37 aiogram.dispatcher.dispatcher ERROR Cause exception while getting updates.
Traceback (most recent call last):
  File "C:\Users\milan\OneDrive\Документы\Innopolis_studying\1_year\2_sem\well_wisher_inno_bot\venv\lib\site-packages\aiogram\dispatcher\dispatcher.py", line 381, in start_polling
    updates = await self.bot.get_updates(
  File "C:\Users\milan\OneDrive\Документы\Innopolis_studying\1_year\2_sem\well_wisher_inno_bot\venv\lib\site-packages\aiogram\bot\bot.py", line 110, in get_updates
    result = await self.request(api.Methods.GET_UPDATES, payload)
  File "C:\Users\milan\OneDrive\Документы\Innopolis_studying\1_year\2_sem\well_wisher_inno_bot\venv\lib\site-packages\aiogram\bot\base.py", line 236, in request
    return await api.make_request(await self.get_session(), self.server, self.__token, method, data, files,
  File "C:\Users\milan\OneDrive\Документы\Innopolis_studying\1_year\2_sem\well_wisher_inno_bot\venv\lib\site-packages\aiogram\bot\api.py", line 139, in make_request
    async with session.post(url, data=req, **kwargs) as response:
  File "C:\Users\milan\OneDrive\Документы\Innopolis_studying\1_year\2_sem\well_wisher_inno_bot\venv\lib\site-packages\aiohttp\client.py", line 1141, in __aenter__
    self._resp = await self._coro
  File "C:\Users\milan\OneDrive\Документы\Innopolis_studying\1_year\2_sem\well_wisher_inno_bot\venv\lib\site-packages\aiohttp\client.py", line 560, in _request
    await resp.start(conn)
  File "C:\Users\milan\OneDrive\Документы\Innopolis_studying\1_year\2_sem\well_wisher_inno_bot\venv\lib\site-packages\aiohttp\client_reqrep.py", line 894, in start
    with self._timer:
  File "C:\Users\milan\OneDrive\Документы\Innopolis_studying\1_year\2_sem\well_wisher_inno_bot\venv\lib\site-packages\aiohttp\helpers.py", line 721, in __exit__
    raise asyncio.TimeoutError from None
asyncio.exceptions.TimeoutError
16:18:42 aiogram.dispatcher.dispatcher ERROR Cause exception while getting updates.
Traceback (most recent call last):
  File "C:\Users\milan\OneDrive\Документы\Innopolis_studying\1_year\2_sem\well_wisher_inno_bot\venv\lib\site-packages\aiohttp\connector.py", line 1152, in _create_direct_connection
    hosts = await asyncio.shield(host_resolved)
  File "C:\Users\milan\OneDrive\Документы\Innopolis_studying\1_year\2_sem\well_wisher_inno_bot\venv\lib\site-packages\aiohttp\connector.py", line 874, in _resolve_host
    addrs = await self._resolver.resolve(host, port, family=self._family)
  File "C:\Users\milan\OneDrive\Документы\Innopolis_studying\1_year\2_sem\well_wisher_inno_bot\venv\lib\site-packages\aiohttp\resolver.py", line 33, in resolve
    infos = await self._loop.getaddrinfo(
  File "C:\Users\milan\AppData\Local\Programs\Python\Python310\lib\asyncio\base_events.py", line 860, in getaddrinfo
    return await self.run_in_executor(
  File "C:\Users\milan\AppData\Local\Programs\Python\Python310\lib\concurrent\futures\thread.py", line 58, in run
    result = self.fn(*self.args, **self.kwargs)
  File "C:\Users\milan\AppData\Local\Programs\Python\Python310\lib\socket.py", line 955, in getaddrinfo
    for res in _socket.getaddrinfo(host, port, family, type, proto, flags):
socket.gaierror: [Errno 11004] getaddrinfo failed

The above exception was the direct cause of the following exception:

Traceback (most recent call last):
  File "C:\Users\milan\OneDrive\Документы\Innopolis_studying\1_year\2_sem\well_wisher_inno_bot\venv\lib\site-packages\aiogram\bot\api.py", line 139, in make_request
    async with session.post(url, data=req, **kwargs) as response:
  File "C:\Users\milan\OneDrive\Документы\Innopolis_studying\1_year\2_sem\well_wisher_inno_bot\venv\lib\site-packages\aiohttp\client.py", line 1141, in __aenter__
    self._resp = await self._coro
  File "C:\Users\milan\OneDrive\Документы\Innopolis_studying\1_year\2_sem\well_wisher_inno_bot\venv\lib\site-packages\aiohttp\client.py", line 536, in _request
    conn = await self._connector.connect(
  File "C:\Users\milan\OneDrive\Документы\Innopolis_studying\1_year\2_sem\well_wisher_inno_bot\venv\lib\site-packages\aiohttp\connector.py", line 540, in connect
    proto = await self._create_connection(req, traces, timeout)
  File "C:\Users\milan\OneDrive\Документы\Innopolis_studying\1_year\2_sem\well_wisher_inno_bot\venv\lib\site-packages\aiohttp\connector.py", line 901, in _create_connection
    _, proto = await self._create_direct_connection(req, traces, timeout)
  File "C:\Users\milan\OneDrive\Документы\Innopolis_studying\1_year\2_sem\well_wisher_inno_bot\venv\lib\site-packages\aiohttp\connector.py", line 1166, in _create_direct_connection
    raise ClientConnectorError(req.connection_key, exc) from exc
aiohttp.client_exceptions.ClientConnectorError: Cannot connect to host api.telegram.org:443 ssl:default [getaddrinfo failed]

During handling of the above exception, another exception occurred:

Traceback (most recent call last):
  File "C:\Users\milan\OneDrive\Документы\Innopolis_studying\1_year\2_sem\well_wisher_inno_bot\venv\lib\site-packages\aiogram\dispatcher\dispatcher.py", line 381, in start_polling
    updates = await self.bot.get_updates(
  File "C:\Users\milan\OneDrive\Документы\Innopolis_studying\1_year\2_sem\well_wisher_inno_bot\venv\lib\site-packages\aiogram\bot\bot.py", line 110, in get_updates
    result = await self.request(api.Methods.GET_UPDATES, payload)
  File "C:\Users\milan\OneDrive\Документы\Innopolis_studying\1_year\2_sem\well_wisher_inno_bot\venv\lib\site-packages\aiogram\bot\base.py", line 236, in request
    return await api.make_request(await self.get_session(), self.server, self.__token, method, data, files,
  File "C:\Users\milan\OneDrive\Документы\Innopolis_studying\1_year\2_sem\well_wisher_inno_bot\venv\lib\site-packages\aiogram\bot\api.py", line 142, in make_request
    raise exceptions.NetworkError(f"aiohttp client throws an error: {e.__class__.__name__}: {e}")
aiogram.utils.exceptions.NetworkError: Aiohttp client throws an error: ClientConnectorError: Cannot connect to host api.telegram.org:443 ssl:default [getaddrinfo failed]
16:18:47 aiogram.dispatcher.dispatcher ERROR Cause exception while getting updates.
Traceback (most recent call last):
  File "C:\Users\milan\OneDrive\Документы\Innopolis_studying\1_year\2_sem\well_wisher_inno_bot\venv\lib\site-packages\aiohttp\connector.py", line 1152, in _create_direct_connection
    hosts = await asyncio.shield(host_resolved)
  File "C:\Users\milan\OneDrive\Документы\Innopolis_studying\1_year\2_sem\well_wisher_inno_bot\venv\lib\site-packages\aiohttp\connector.py", line 874, in _resolve_host
    addrs = await self._resolver.resolve(host, port, family=self._family)
  File "C:\Users\milan\OneDrive\Документы\Innopolis_studying\1_year\2_sem\well_wisher_inno_bot\venv\lib\site-packages\aiohttp\resolver.py", line 33, in resolve
    infos = await self._loop.getaddrinfo(
  File "C:\Users\milan\AppData\Local\Programs\Python\Python310\lib\asyncio\base_events.py", line 860, in getaddrinfo
    return await self.run_in_executor(
  File "C:\Users\milan\AppData\Local\Programs\Python\Python310\lib\concurrent\futures\thread.py", line 58, in run
    result = self.fn(*self.args, **self.kwargs)
  File "C:\Users\milan\AppData\Local\Programs\Python\Python310\lib\socket.py", line 955, in getaddrinfo
    for res in _socket.getaddrinfo(host, port, family, type, proto, flags):
socket.gaierror: [Errno 11004] getaddrinfo failed

The above exception was the direct cause of the following exception:

Traceback (most recent call last):
  File "C:\Users\milan\OneDrive\Документы\Innopolis_studying\1_year\2_sem\well_wisher_inno_bot\venv\lib\site-packages\aiogram\bot\api.py", line 139, in make_request
    async with session.post(url, data=req, **kwargs) as response:
  File "C:\Users\milan\OneDrive\Документы\Innopolis_studying\1_year\2_sem\well_wisher_inno_bot\venv\lib\site-packages\aiohttp\client.py", line 1141, in __aenter__
    self._resp = await self._coro
  File "C:\Users\milan\OneDrive\Документы\Innopolis_studying\1_year\2_sem\well_wisher_inno_bot\venv\lib\site-packages\aiohttp\client.py", line 536, in _request
    conn = await self._connector.connect(
  File "C:\Users\milan\OneDrive\Документы\Innopolis_studying\1_year\2_sem\well_wisher_inno_bot\venv\lib\site-packages\aiohttp\connector.py", line 540, in connect
    proto = await self._create_connection(req, traces, timeout)
  File "C:\Users\milan\OneDrive\Документы\Innopolis_studying\1_year\2_sem\well_wisher_inno_bot\venv\lib\site-packages\aiohttp\connector.py", line 901, in _create_connection
    _, proto = await self._create_direct_connection(req, traces, timeout)
  File "C:\Users\milan\OneDrive\Документы\Innopolis_studying\1_year\2_sem\well_wisher_inno_bot\venv\lib\site-packages\aiohttp\connector.py", line 1166, in _create_direct_connection
    raise ClientConnectorError(req.connection_key, exc) from exc
aiohttp.client_exceptions.ClientConnectorError: Cannot connect to host api.telegram.org:443 ssl:default [getaddrinfo failed]

During handling of the above exception, another exception occurred:

Traceback (most recent call last):
  File "C:\Users\milan\OneDrive\Документы\Innopolis_studying\1_year\2_sem\well_wisher_inno_bot\venv\lib\site-packages\aiogram\dispatcher\dispatcher.py", line 381, in start_polling
    updates = await self.bot.get_updates(
  File "C:\Users\milan\OneDrive\Документы\Innopolis_studying\1_year\2_sem\well_wisher_inno_bot\venv\lib\site-packages\aiogram\bot\bot.py", line 110, in get_updates
    result = await self.request(api.Methods.GET_UPDATES, payload)
  File "C:\Users\milan\OneDrive\Документы\Innopolis_studying\1_year\2_sem\well_wisher_inno_bot\venv\lib\site-packages\aiogram\bot\base.py", line 236, in request
    return await api.make_request(await self.get_session(), self.server, self.__token, method, data, files,
  File "C:\Users\milan\OneDrive\Документы\Innopolis_studying\1_year\2_sem\well_wisher_inno_bot\venv\lib\site-packages\aiogram\bot\api.py", line 142, in make_request
    raise exceptions.NetworkError(f"aiohttp client throws an error: {e.__class__.__name__}: {e}")
aiogram.utils.exceptions.NetworkError: Aiohttp client throws an error: ClientConnectorError: Cannot connect to host api.telegram.org:443 ssl:default [getaddrinfo failed]
16:18:52 aiogram.dispatcher.dispatcher ERROR Cause exception while getting updates.
Traceback (most recent call last):
  File "C:\Users\milan\OneDrive\Документы\Innopolis_studying\1_year\2_sem\well_wisher_inno_bot\venv\lib\site-packages\aiohttp\connector.py", line 1152, in _create_direct_connection
    hosts = await asyncio.shield(host_resolved)
  File "C:\Users\milan\OneDrive\Документы\Innopolis_studying\1_year\2_sem\well_wisher_inno_bot\venv\lib\site-packages\aiohttp\connector.py", line 874, in _resolve_host
    addrs = await self._resolver.resolve(host, port, family=self._family)
  File "C:\Users\milan\OneDrive\Документы\Innopolis_studying\1_year\2_sem\well_wisher_inno_bot\venv\lib\site-packages\aiohttp\resolver.py", line 33, in resolve
    infos = await self._loop.getaddrinfo(
  File "C:\Users\milan\AppData\Local\Programs\Python\Python310\lib\asyncio\base_events.py", line 860, in getaddrinfo
    return await self.run_in_executor(
  File "C:\Users\milan\AppData\Local\Programs\Python\Python310\lib\concurrent\futures\thread.py", line 58, in run
    result = self.fn(*self.args, **self.kwargs)
  File "C:\Users\milan\AppData\Local\Programs\Python\Python310\lib\socket.py", line 955, in getaddrinfo
    for res in _socket.getaddrinfo(host, port, family, type, proto, flags):
socket.gaierror: [Errno 11004] getaddrinfo failed

The above exception was the direct cause of the following exception:

Traceback (most recent call last):
  File "C:\Users\milan\OneDrive\Документы\Innopolis_studying\1_year\2_sem\well_wisher_inno_bot\venv\lib\site-packages\aiogram\bot\api.py", line 139, in make_request
    async with session.post(url, data=req, **kwargs) as response:
  File "C:\Users\milan\OneDrive\Документы\Innopolis_studying\1_year\2_sem\well_wisher_inno_bot\venv\lib\site-packages\aiohttp\client.py", line 1141, in __aenter__
    self._resp = await self._coro
  File "C:\Users\milan\OneDrive\Документы\Innopolis_studying\1_year\2_sem\well_wisher_inno_bot\venv\lib\site-packages\aiohttp\client.py", line 536, in _request
    conn = await self._connector.connect(
  File "C:\Users\milan\OneDrive\Документы\Innopolis_studying\1_year\2_sem\well_wisher_inno_bot\venv\lib\site-packages\aiohttp\connector.py", line 540, in connect
    proto = await self._create_connection(req, traces, timeout)
  File "C:\Users\milan\OneDrive\Документы\Innopolis_studying\1_year\2_sem\well_wisher_inno_bot\venv\lib\site-packages\aiohttp\connector.py", line 901, in _create_connection
    _, proto = await self._create_direct_connection(req, traces, timeout)
  File "C:\Users\milan\OneDrive\Документы\Innopolis_studying\1_year\2_sem\well_wisher_inno_bot\venv\lib\site-packages\aiohttp\connector.py", line 1166, in _create_direct_connection
    raise ClientConnectorError(req.connection_key, exc) from exc
aiohttp.client_exceptions.ClientConnectorError: Cannot connect to host api.telegram.org:443 ssl:default [getaddrinfo failed]

During handling of the above exception, another exception occurred:

Traceback (most recent call last):
  File "C:\Users\milan\OneDrive\Документы\Innopolis_studying\1_year\2_sem\well_wisher_inno_bot\venv\lib\site-packages\aiogram\dispatcher\dispatcher.py", line 381, in start_polling
    updates = await self.bot.get_updates(
  File "C:\Users\milan\OneDrive\Документы\Innopolis_studying\1_year\2_sem\well_wisher_inno_bot\venv\lib\site-packages\aiogram\bot\bot.py", line 110, in get_updates
    result = await self.request(api.Methods.GET_UPDATES, payload)
  File "C:\Users\milan\OneDrive\Документы\Innopolis_studying\1_year\2_sem\well_wisher_inno_bot\venv\lib\site-packages\aiogram\bot\base.py", line 236, in request
    return await api.make_request(await self.get_session(), self.server, self.__token, method, data, files,
  File "C:\Users\milan\OneDrive\Документы\Innopolis_studying\1_year\2_sem\well_wisher_inno_bot\venv\lib\site-packages\aiogram\bot\api.py", line 142, in make_request
    raise exceptions.NetworkError(f"aiohttp client throws an error: {e.__class__.__name__}: {e}")
aiogram.utils.exceptions.NetworkError: Aiohttp client throws an error: ClientConnectorError: Cannot connect to host api.telegram.org:443 ssl:default [getaddrinfo failed]
16:18:57 aiogram.dispatcher.dispatcher ERROR Cause exception while getting updates.
Traceback (most recent call last):
  File "C:\Users\milan\OneDrive\Документы\Innopolis_studying\1_year\2_sem\well_wisher_inno_bot\venv\lib\site-packages\aiohttp\connector.py", line 1152, in _create_direct_connection
    hosts = await asyncio.shield(host_resolved)
  File "C:\Users\milan\OneDrive\Документы\Innopolis_studying\1_year\2_sem\well_wisher_inno_bot\venv\lib\site-packages\aiohttp\connector.py", line 874, in _resolve_host
    addrs = await self._resolver.resolve(host, port, family=self._family)
  File "C:\Users\milan\OneDrive\Документы\Innopolis_studying\1_year\2_sem\well_wisher_inno_bot\venv\lib\site-packages\aiohttp\resolver.py", line 33, in resolve
    infos = await self._loop.getaddrinfo(
  File "C:\Users\milan\AppData\Local\Programs\Python\Python310\lib\asyncio\base_events.py", line 860, in getaddrinfo
    return await self.run_in_executor(
  File "C:\Users\milan\AppData\Local\Programs\Python\Python310\lib\concurrent\futures\thread.py", line 58, in run
    result = self.fn(*self.args, **self.kwargs)
  File "C:\Users\milan\AppData\Local\Programs\Python\Python310\lib\socket.py", line 955, in getaddrinfo
    for res in _socket.getaddrinfo(host, port, family, type, proto, flags):
socket.gaierror: [Errno 11004] getaddrinfo failed

The above exception was the direct cause of the following exception:

Traceback (most recent call last):
  File "C:\Users\milan\OneDrive\Документы\Innopolis_studying\1_year\2_sem\well_wisher_inno_bot\venv\lib\site-packages\aiogram\bot\api.py", line 139, in make_request
    async with session.post(url, data=req, **kwargs) as response:
  File "C:\Users\milan\OneDrive\Документы\Innopolis_studying\1_year\2_sem\well_wisher_inno_bot\venv\lib\site-packages\aiohttp\client.py", line 1141, in __aenter__
    self._resp = await self._coro
  File "C:\Users\milan\OneDrive\Документы\Innopolis_studying\1_year\2_sem\well_wisher_inno_bot\venv\lib\site-packages\aiohttp\client.py", line 536, in _request
    conn = await self._connector.connect(
  File "C:\Users\milan\OneDrive\Документы\Innopolis_studying\1_year\2_sem\well_wisher_inno_bot\venv\lib\site-packages\aiohttp\connector.py", line 540, in connect
    proto = await self._create_connection(req, traces, timeout)
  File "C:\Users\milan\OneDrive\Документы\Innopolis_studying\1_year\2_sem\well_wisher_inno_bot\venv\lib\site-packages\aiohttp\connector.py", line 901, in _create_connection
    _, proto = await self._create_direct_connection(req, traces, timeout)
  File "C:\Users\milan\OneDrive\Документы\Innopolis_studying\1_year\2_sem\well_wisher_inno_bot\venv\lib\site-packages\aiohttp\connector.py", line 1166, in _create_direct_connection
    raise ClientConnectorError(req.connection_key, exc) from exc
aiohttp.client_exceptions.ClientConnectorError: Cannot connect to host api.telegram.org:443 ssl:default [getaddrinfo failed]

During handling of the above exception, another exception occurred:

Traceback (most recent call last):
  File "C:\Users\milan\OneDrive\Документы\Innopolis_studying\1_year\2_sem\well_wisher_inno_bot\venv\lib\site-packages\aiogram\dispatcher\dispatcher.py", line 381, in start_polling
    updates = await self.bot.get_updates(
  File "C:\Users\milan\OneDrive\Документы\Innopolis_studying\1_year\2_sem\well_wisher_inno_bot\venv\lib\site-packages\aiogram\bot\bot.py", line 110, in get_updates
    result = await self.request(api.Methods.GET_UPDATES, payload)
  File "C:\Users\milan\OneDrive\Документы\Innopolis_studying\1_year\2_sem\well_wisher_inno_bot\venv\lib\site-packages\aiogram\bot\base.py", line 236, in request
    return await api.make_request(await self.get_session(), self.server, self.__token, method, data, files,
  File "C:\Users\milan\OneDrive\Документы\Innopolis_studying\1_year\2_sem\well_wisher_inno_bot\venv\lib\site-packages\aiogram\bot\api.py", line 142, in make_request
    raise exceptions.NetworkError(f"aiohttp client throws an error: {e.__class__.__name__}: {e}")
aiogram.utils.exceptions.NetworkError: Aiohttp client throws an error: ClientConnectorError: Cannot connect to host api.telegram.org:443 ssl:default [getaddrinfo failed]
16:19:02 aiogram.dispatcher.dispatcher ERROR Cause exception while getting updates.
Traceback (most recent call last):
  File "C:\Users\milan\OneDrive\Документы\Innopolis_studying\1_year\2_sem\well_wisher_inno_bot\venv\lib\site-packages\aiohttp\connector.py", line 1152, in _create_direct_connection
    hosts = await asyncio.shield(host_resolved)
  File "C:\Users\milan\OneDrive\Документы\Innopolis_studying\1_year\2_sem\well_wisher_inno_bot\venv\lib\site-packages\aiohttp\connector.py", line 874, in _resolve_host
    addrs = await self._resolver.resolve(host, port, family=self._family)
  File "C:\Users\milan\OneDrive\Документы\Innopolis_studying\1_year\2_sem\well_wisher_inno_bot\venv\lib\site-packages\aiohttp\resolver.py", line 33, in resolve
    infos = await self._loop.getaddrinfo(
  File "C:\Users\milan\AppData\Local\Programs\Python\Python310\lib\asyncio\base_events.py", line 860, in getaddrinfo
    return await self.run_in_executor(
  File "C:\Users\milan\AppData\Local\Programs\Python\Python310\lib\concurrent\futures\thread.py", line 58, in run
    result = self.fn(*self.args, **self.kwargs)
  File "C:\Users\milan\AppData\Local\Programs\Python\Python310\lib\socket.py", line 955, in getaddrinfo
    for res in _socket.getaddrinfo(host, port, family, type, proto, flags):
socket.gaierror: [Errno 11004] getaddrinfo failed

The above exception was the direct cause of the following exception:

Traceback (most recent call last):
  File "C:\Users\milan\OneDrive\Документы\Innopolis_studying\1_year\2_sem\well_wisher_inno_bot\venv\lib\site-packages\aiogram\bot\api.py", line 139, in make_request
    async with session.post(url, data=req, **kwargs) as response:
  File "C:\Users\milan\OneDrive\Документы\Innopolis_studying\1_year\2_sem\well_wisher_inno_bot\venv\lib\site-packages\aiohttp\client.py", line 1141, in __aenter__
    self._resp = await self._coro
  File "C:\Users\milan\OneDrive\Документы\Innopolis_studying\1_year\2_sem\well_wisher_inno_bot\venv\lib\site-packages\aiohttp\client.py", line 536, in _request
    conn = await self._connector.connect(
  File "C:\Users\milan\OneDrive\Документы\Innopolis_studying\1_year\2_sem\well_wisher_inno_bot\venv\lib\site-packages\aiohttp\connector.py", line 540, in connect
    proto = await self._create_connection(req, traces, timeout)
  File "C:\Users\milan\OneDrive\Документы\Innopolis_studying\1_year\2_sem\well_wisher_inno_bot\venv\lib\site-packages\aiohttp\connector.py", line 901, in _create_connection
    _, proto = await self._create_direct_connection(req, traces, timeout)
  File "C:\Users\milan\OneDrive\Документы\Innopolis_studying\1_year\2_sem\well_wisher_inno_bot\venv\lib\site-packages\aiohttp\connector.py", line 1166, in _create_direct_connection
    raise ClientConnectorError(req.connection_key, exc) from exc
aiohttp.client_exceptions.ClientConnectorError: Cannot connect to host api.telegram.org:443 ssl:default [getaddrinfo failed]

During handling of the above exception, another exception occurred:

Traceback (most recent call last):
  File "C:\Users\milan\OneDrive\Документы\Innopolis_studying\1_year\2_sem\well_wisher_inno_bot\venv\lib\site-packages\aiogram\dispatcher\dispatcher.py", line 381, in start_polling
    updates = await self.bot.get_updates(
  File "C:\Users\milan\OneDrive\Документы\Innopolis_studying\1_year\2_sem\well_wisher_inno_bot\venv\lib\site-packages\aiogram\bot\bot.py", line 110, in get_updates
    result = await self.request(api.Methods.GET_UPDATES, payload)
  File "C:\Users\milan\OneDrive\Документы\Innopolis_studying\1_year\2_sem\well_wisher_inno_bot\venv\lib\site-packages\aiogram\bot\base.py", line 236, in request
    return await api.make_request(await self.get_session(), self.server, self.__token, method, data, files,
  File "C:\Users\milan\OneDrive\Документы\Innopolis_studying\1_year\2_sem\well_wisher_inno_bot\venv\lib\site-packages\aiogram\bot\api.py", line 142, in make_request
    raise exceptions.NetworkError(f"aiohttp client throws an error: {e.__class__.__name__}: {e}")
aiogram.utils.exceptions.NetworkError: Aiohttp client throws an error: ClientConnectorError: Cannot connect to host api.telegram.org:443 ssl:default [getaddrinfo failed]
16:19:07 aiogram.dispatcher.dispatcher ERROR Cause exception while getting updates.
Traceback (most recent call last):
  File "C:\Users\milan\OneDrive\Документы\Innopolis_studying\1_year\2_sem\well_wisher_inno_bot\venv\lib\site-packages\aiohttp\connector.py", line 1152, in _create_direct_connection
    hosts = await asyncio.shield(host_resolved)
  File "C:\Users\milan\OneDrive\Документы\Innopolis_studying\1_year\2_sem\well_wisher_inno_bot\venv\lib\site-packages\aiohttp\connector.py", line 874, in _resolve_host
    addrs = await self._resolver.resolve(host, port, family=self._family)
  File "C:\Users\milan\OneDrive\Документы\Innopolis_studying\1_year\2_sem\well_wisher_inno_bot\venv\lib\site-packages\aiohttp\resolver.py", line 33, in resolve
    infos = await self._loop.getaddrinfo(
  File "C:\Users\milan\AppData\Local\Programs\Python\Python310\lib\asyncio\base_events.py", line 860, in getaddrinfo
    return await self.run_in_executor(
  File "C:\Users\milan\AppData\Local\Programs\Python\Python310\lib\concurrent\futures\thread.py", line 58, in run
    result = self.fn(*self.args, **self.kwargs)
  File "C:\Users\milan\AppData\Local\Programs\Python\Python310\lib\socket.py", line 955, in getaddrinfo
    for res in _socket.getaddrinfo(host, port, family, type, proto, flags):
socket.gaierror: [Errno 11004] getaddrinfo failed

The above exception was the direct cause of the following exception:

Traceback (most recent call last):
  File "C:\Users\milan\OneDrive\Документы\Innopolis_studying\1_year\2_sem\well_wisher_inno_bot\venv\lib\site-packages\aiogram\bot\api.py", line 139, in make_request
    async with session.post(url, data=req, **kwargs) as response:
  File "C:\Users\milan\OneDrive\Документы\Innopolis_studying\1_year\2_sem\well_wisher_inno_bot\venv\lib\site-packages\aiohttp\client.py", line 1141, in __aenter__
    self._resp = await self._coro
  File "C:\Users\milan\OneDrive\Документы\Innopolis_studying\1_year\2_sem\well_wisher_inno_bot\venv\lib\site-packages\aiohttp\client.py", line 536, in _request
    conn = await self._connector.connect(
  File "C:\Users\milan\OneDrive\Документы\Innopolis_studying\1_year\2_sem\well_wisher_inno_bot\venv\lib\site-packages\aiohttp\connector.py", line 540, in connect
    proto = await self._create_connection(req, traces, timeout)
  File "C:\Users\milan\OneDrive\Документы\Innopolis_studying\1_year\2_sem\well_wisher_inno_bot\venv\lib\site-packages\aiohttp\connector.py", line 901, in _create_connection
    _, proto = await self._create_direct_connection(req, traces, timeout)
  File "C:\Users\milan\OneDrive\Документы\Innopolis_studying\1_year\2_sem\well_wisher_inno_bot\venv\lib\site-packages\aiohttp\connector.py", line 1166, in _create_direct_connection
    raise ClientConnectorError(req.connection_key, exc) from exc
aiohttp.client_exceptions.ClientConnectorError: Cannot connect to host api.telegram.org:443 ssl:default [getaddrinfo failed]

During handling of the above exception, another exception occurred:

Traceback (most recent call last):
  File "C:\Users\milan\OneDrive\Документы\Innopolis_studying\1_year\2_sem\well_wisher_inno_bot\venv\lib\site-packages\aiogram\dispatcher\dispatcher.py", line 381, in start_polling
    updates = await self.bot.get_updates(
  File "C:\Users\milan\OneDrive\Документы\Innopolis_studying\1_year\2_sem\well_wisher_inno_bot\venv\lib\site-packages\aiogram\bot\bot.py", line 110, in get_updates
    result = await self.request(api.Methods.GET_UPDATES, payload)
  File "C:\Users\milan\OneDrive\Документы\Innopolis_studying\1_year\2_sem\well_wisher_inno_bot\venv\lib\site-packages\aiogram\bot\base.py", line 236, in request
    return await api.make_request(await self.get_session(), self.server, self.__token, method, data, files,
  File "C:\Users\milan\OneDrive\Документы\Innopolis_studying\1_year\2_sem\well_wisher_inno_bot\venv\lib\site-packages\aiogram\bot\api.py", line 142, in make_request
    raise exceptions.NetworkError(f"aiohttp client throws an error: {e.__class__.__name__}: {e}")
aiogram.utils.exceptions.NetworkError: Aiohttp client throws an error: ClientConnectorError: Cannot connect to host api.telegram.org:443 ssl:default [getaddrinfo failed]
17:58:09 aiogram.dispatcher.dispatcher ERROR Cause exception while getting updates.
Traceback (most recent call last):
  File "C:\Users\milan\OneDrive\Документы\Innopolis_studying\1_year\2_sem\well_wisher_inno_bot\venv\lib\site-packages\aiogram\dispatcher\dispatcher.py", line 381, in start_polling
    updates = await self.bot.get_updates(
  File "C:\Users\milan\OneDrive\Документы\Innopolis_studying\1_year\2_sem\well_wisher_inno_bot\venv\lib\site-packages\aiogram\bot\bot.py", line 110, in get_updates
    result = await self.request(api.Methods.GET_UPDATES, payload)
  File "C:\Users\milan\OneDrive\Документы\Innopolis_studying\1_year\2_sem\well_wisher_inno_bot\venv\lib\site-packages\aiogram\bot\base.py", line 236, in request
    return await api.make_request(await self.get_session(), self.server, self.__token, method, data, files,
  File "C:\Users\milan\OneDrive\Документы\Innopolis_studying\1_year\2_sem\well_wisher_inno_bot\venv\lib\site-packages\aiogram\bot\api.py", line 139, in make_request
    async with session.post(url, data=req, **kwargs) as response:
  File "C:\Users\milan\OneDrive\Документы\Innopolis_studying\1_year\2_sem\well_wisher_inno_bot\venv\lib\site-packages\aiohttp\client.py", line 1141, in __aenter__
    self._resp = await self._coro
  File "C:\Users\milan\OneDrive\Документы\Innopolis_studying\1_year\2_sem\well_wisher_inno_bot\venv\lib\site-packages\aiohttp\client.py", line 560, in _request
    await resp.start(conn)
  File "C:\Users\milan\OneDrive\Документы\Innopolis_studying\1_year\2_sem\well_wisher_inno_bot\venv\lib\site-packages\aiohttp\client_reqrep.py", line 894, in start
    with self._timer:
  File "C:\Users\milan\OneDrive\Документы\Innopolis_studying\1_year\2_sem\well_wisher_inno_bot\venv\lib\site-packages\aiohttp\helpers.py", line 721, in __exit__
    raise asyncio.TimeoutError from None
asyncio.exceptions.TimeoutError
17:58:14 aiogram.dispatcher.dispatcher ERROR Cause exception while getting updates.
Traceback (most recent call last):
  File "C:\Users\milan\OneDrive\Документы\Innopolis_studying\1_year\2_sem\well_wisher_inno_bot\venv\lib\site-packages\aiohttp\connector.py", line 1152, in _create_direct_connection
    hosts = await asyncio.shield(host_resolved)
  File "C:\Users\milan\OneDrive\Документы\Innopolis_studying\1_year\2_sem\well_wisher_inno_bot\venv\lib\site-packages\aiohttp\connector.py", line 874, in _resolve_host
    addrs = await self._resolver.resolve(host, port, family=self._family)
  File "C:\Users\milan\OneDrive\Документы\Innopolis_studying\1_year\2_sem\well_wisher_inno_bot\venv\lib\site-packages\aiohttp\resolver.py", line 33, in resolve
    infos = await self._loop.getaddrinfo(
  File "C:\Users\milan\AppData\Local\Programs\Python\Python310\lib\asyncio\base_events.py", line 860, in getaddrinfo
    return await self.run_in_executor(
  File "C:\Users\milan\AppData\Local\Programs\Python\Python310\lib\concurrent\futures\thread.py", line 58, in run
    result = self.fn(*self.args, **self.kwargs)
  File "C:\Users\milan\AppData\Local\Programs\Python\Python310\lib\socket.py", line 955, in getaddrinfo
    for res in _socket.getaddrinfo(host, port, family, type, proto, flags):
socket.gaierror: [Errno 11004] getaddrinfo failed

The above exception was the direct cause of the following exception:

Traceback (most recent call last):
  File "C:\Users\milan\OneDrive\Документы\Innopolis_studying\1_year\2_sem\well_wisher_inno_bot\venv\lib\site-packages\aiogram\bot\api.py", line 139, in make_request
    async with session.post(url, data=req, **kwargs) as response:
  File "C:\Users\milan\OneDrive\Документы\Innopolis_studying\1_year\2_sem\well_wisher_inno_bot\venv\lib\site-packages\aiohttp\client.py", line 1141, in __aenter__
    self._resp = await self._coro
  File "C:\Users\milan\OneDrive\Документы\Innopolis_studying\1_year\2_sem\well_wisher_inno_bot\venv\lib\site-packages\aiohttp\client.py", line 536, in _request
    conn = await self._connector.connect(
  File "C:\Users\milan\OneDrive\Документы\Innopolis_studying\1_year\2_sem\well_wisher_inno_bot\venv\lib\site-packages\aiohttp\connector.py", line 540, in connect
    proto = await self._create_connection(req, traces, timeout)
  File "C:\Users\milan\OneDrive\Документы\Innopolis_studying\1_year\2_sem\well_wisher_inno_bot\venv\lib\site-packages\aiohttp\connector.py", line 901, in _create_connection
    _, proto = await self._create_direct_connection(req, traces, timeout)
  File "C:\Users\milan\OneDrive\Документы\Innopolis_studying\1_year\2_sem\well_wisher_inno_bot\venv\lib\site-packages\aiohttp\connector.py", line 1166, in _create_direct_connection
    raise ClientConnectorError(req.connection_key, exc) from exc
aiohttp.client_exceptions.ClientConnectorError: Cannot connect to host api.telegram.org:443 ssl:default [getaddrinfo failed]

During handling of the above exception, another exception occurred:

Traceback (most recent call last):
  File "C:\Users\milan\OneDrive\Документы\Innopolis_studying\1_year\2_sem\well_wisher_inno_bot\venv\lib\site-packages\aiogram\dispatcher\dispatcher.py", line 381, in start_polling
    updates = await self.bot.get_updates(
  File "C:\Users\milan\OneDrive\Документы\Innopolis_studying\1_year\2_sem\well_wisher_inno_bot\venv\lib\site-packages\aiogram\bot\bot.py", line 110, in get_updates
    result = await self.request(api.Methods.GET_UPDATES, payload)
  File "C:\Users\milan\OneDrive\Документы\Innopolis_studying\1_year\2_sem\well_wisher_inno_bot\venv\lib\site-packages\aiogram\bot\base.py", line 236, in request
    return await api.make_request(await self.get_session(), self.server, self.__token, method, data, files,
  File "C:\Users\milan\OneDrive\Документы\Innopolis_studying\1_year\2_sem\well_wisher_inno_bot\venv\lib\site-packages\aiogram\bot\api.py", line 142, in make_request
    raise exceptions.NetworkError(f"aiohttp client throws an error: {e.__class__.__name__}: {e}")
aiogram.utils.exceptions.NetworkError: Aiohttp client throws an error: ClientConnectorError: Cannot connect to host api.telegram.org:443 ssl:default [getaddrinfo failed]
17:58:19 aiogram.dispatcher.dispatcher ERROR Cause exception while getting updates.
Traceback (most recent call last):
  File "C:\Users\milan\OneDrive\Документы\Innopolis_studying\1_year\2_sem\well_wisher_inno_bot\venv\lib\site-packages\aiohttp\connector.py", line 1152, in _create_direct_connection
    hosts = await asyncio.shield(host_resolved)
  File "C:\Users\milan\OneDrive\Документы\Innopolis_studying\1_year\2_sem\well_wisher_inno_bot\venv\lib\site-packages\aiohttp\connector.py", line 874, in _resolve_host
    addrs = await self._resolver.resolve(host, port, family=self._family)
  File "C:\Users\milan\OneDrive\Документы\Innopolis_studying\1_year\2_sem\well_wisher_inno_bot\venv\lib\site-packages\aiohttp\resolver.py", line 33, in resolve
    infos = await self._loop.getaddrinfo(
  File "C:\Users\milan\AppData\Local\Programs\Python\Python310\lib\asyncio\base_events.py", line 860, in getaddrinfo
    return await self.run_in_executor(
  File "C:\Users\milan\AppData\Local\Programs\Python\Python310\lib\concurrent\futures\thread.py", line 58, in run
    result = self.fn(*self.args, **self.kwargs)
  File "C:\Users\milan\AppData\Local\Programs\Python\Python310\lib\socket.py", line 955, in getaddrinfo
    for res in _socket.getaddrinfo(host, port, family, type, proto, flags):
socket.gaierror: [Errno 11004] getaddrinfo failed

The above exception was the direct cause of the following exception:

Traceback (most recent call last):
  File "C:\Users\milan\OneDrive\Документы\Innopolis_studying\1_year\2_sem\well_wisher_inno_bot\venv\lib\site-packages\aiogram\bot\api.py", line 139, in make_request
    async with session.post(url, data=req, **kwargs) as response:
  File "C:\Users\milan\OneDrive\Документы\Innopolis_studying\1_year\2_sem\well_wisher_inno_bot\venv\lib\site-packages\aiohttp\client.py", line 1141, in __aenter__
    self._resp = await self._coro
  File "C:\Users\milan\OneDrive\Документы\Innopolis_studying\1_year\2_sem\well_wisher_inno_bot\venv\lib\site-packages\aiohttp\client.py", line 536, in _request
    conn = await self._connector.connect(
  File "C:\Users\milan\OneDrive\Документы\Innopolis_studying\1_year\2_sem\well_wisher_inno_bot\venv\lib\site-packages\aiohttp\connector.py", line 540, in connect
    proto = await self._create_connection(req, traces, timeout)
  File "C:\Users\milan\OneDrive\Документы\Innopolis_studying\1_year\2_sem\well_wisher_inno_bot\venv\lib\site-packages\aiohttp\connector.py", line 901, in _create_connection
    _, proto = await self._create_direct_connection(req, traces, timeout)
  File "C:\Users\milan\OneDrive\Документы\Innopolis_studying\1_year\2_sem\well_wisher_inno_bot\venv\lib\site-packages\aiohttp\connector.py", line 1166, in _create_direct_connection
    raise ClientConnectorError(req.connection_key, exc) from exc
aiohttp.client_exceptions.ClientConnectorError: Cannot connect to host api.telegram.org:443 ssl:default [getaddrinfo failed]

During handling of the above exception, another exception occurred:

Traceback (most recent call last):
  File "C:\Users\milan\OneDrive\Документы\Innopolis_studying\1_year\2_sem\well_wisher_inno_bot\venv\lib\site-packages\aiogram\dispatcher\dispatcher.py", line 381, in start_polling
    updates = await self.bot.get_updates(
  File "C:\Users\milan\OneDrive\Документы\Innopolis_studying\1_year\2_sem\well_wisher_inno_bot\venv\lib\site-packages\aiogram\bot\bot.py", line 110, in get_updates
    result = await self.request(api.Methods.GET_UPDATES, payload)
  File "C:\Users\milan\OneDrive\Документы\Innopolis_studying\1_year\2_sem\well_wisher_inno_bot\venv\lib\site-packages\aiogram\bot\base.py", line 236, in request
    return await api.make_request(await self.get_session(), self.server, self.__token, method, data, files,
  File "C:\Users\milan\OneDrive\Документы\Innopolis_studying\1_year\2_sem\well_wisher_inno_bot\venv\lib\site-packages\aiogram\bot\api.py", line 142, in make_request
    raise exceptions.NetworkError(f"aiohttp client throws an error: {e.__class__.__name__}: {e}")
aiogram.utils.exceptions.NetworkError: Aiohttp client throws an error: ClientConnectorError: Cannot connect to host api.telegram.org:443 ssl:default [getaddrinfo failed]
17:58:24 aiogram.dispatcher.dispatcher ERROR Cause exception while getting updates.
Traceback (most recent call last):
  File "C:\Users\milan\OneDrive\Документы\Innopolis_studying\1_year\2_sem\well_wisher_inno_bot\venv\lib\site-packages\aiohttp\connector.py", line 1152, in _create_direct_connection
    hosts = await asyncio.shield(host_resolved)
  File "C:\Users\milan\OneDrive\Документы\Innopolis_studying\1_year\2_sem\well_wisher_inno_bot\venv\lib\site-packages\aiohttp\connector.py", line 874, in _resolve_host
    addrs = await self._resolver.resolve(host, port, family=self._family)
  File "C:\Users\milan\OneDrive\Документы\Innopolis_studying\1_year\2_sem\well_wisher_inno_bot\venv\lib\site-packages\aiohttp\resolver.py", line 33, in resolve
    infos = await self._loop.getaddrinfo(
  File "C:\Users\milan\AppData\Local\Programs\Python\Python310\lib\asyncio\base_events.py", line 860, in getaddrinfo
    return await self.run_in_executor(
  File "C:\Users\milan\AppData\Local\Programs\Python\Python310\lib\concurrent\futures\thread.py", line 58, in run
    result = self.fn(*self.args, **self.kwargs)
  File "C:\Users\milan\AppData\Local\Programs\Python\Python310\lib\socket.py", line 955, in getaddrinfo
    for res in _socket.getaddrinfo(host, port, family, type, proto, flags):
socket.gaierror: [Errno 11004] getaddrinfo failed

The above exception was the direct cause of the following exception:

Traceback (most recent call last):
  File "C:\Users\milan\OneDrive\Документы\Innopolis_studying\1_year\2_sem\well_wisher_inno_bot\venv\lib\site-packages\aiogram\bot\api.py", line 139, in make_request
    async with session.post(url, data=req, **kwargs) as response:
  File "C:\Users\milan\OneDrive\Документы\Innopolis_studying\1_year\2_sem\well_wisher_inno_bot\venv\lib\site-packages\aiohttp\client.py", line 1141, in __aenter__
    self._resp = await self._coro
  File "C:\Users\milan\OneDrive\Документы\Innopolis_studying\1_year\2_sem\well_wisher_inno_bot\venv\lib\site-packages\aiohttp\client.py", line 536, in _request
    conn = await self._connector.connect(
  File "C:\Users\milan\OneDrive\Документы\Innopolis_studying\1_year\2_sem\well_wisher_inno_bot\venv\lib\site-packages\aiohttp\connector.py", line 540, in connect
    proto = await self._create_connection(req, traces, timeout)
  File "C:\Users\milan\OneDrive\Документы\Innopolis_studying\1_year\2_sem\well_wisher_inno_bot\venv\lib\site-packages\aiohttp\connector.py", line 901, in _create_connection
    _, proto = await self._create_direct_connection(req, traces, timeout)
  File "C:\Users\milan\OneDrive\Документы\Innopolis_studying\1_year\2_sem\well_wisher_inno_bot\venv\lib\site-packages\aiohttp\connector.py", line 1166, in _create_direct_connection
    raise ClientConnectorError(req.connection_key, exc) from exc
aiohttp.client_exceptions.ClientConnectorError: Cannot connect to host api.telegram.org:443 ssl:default [getaddrinfo failed]

During handling of the above exception, another exception occurred:

Traceback (most recent call last):
  File "C:\Users\milan\OneDrive\Документы\Innopolis_studying\1_year\2_sem\well_wisher_inno_bot\venv\lib\site-packages\aiogram\dispatcher\dispatcher.py", line 381, in start_polling
    updates = await self.bot.get_updates(
  File "C:\Users\milan\OneDrive\Документы\Innopolis_studying\1_year\2_sem\well_wisher_inno_bot\venv\lib\site-packages\aiogram\bot\bot.py", line 110, in get_updates
    result = await self.request(api.Methods.GET_UPDATES, payload)
  File "C:\Users\milan\OneDrive\Документы\Innopolis_studying\1_year\2_sem\well_wisher_inno_bot\venv\lib\site-packages\aiogram\bot\base.py", line 236, in request
    return await api.make_request(await self.get_session(), self.server, self.__token, method, data, files,
  File "C:\Users\milan\OneDrive\Документы\Innopolis_studying\1_year\2_sem\well_wisher_inno_bot\venv\lib\site-packages\aiogram\bot\api.py", line 142, in make_request
    raise exceptions.NetworkError(f"aiohttp client throws an error: {e.__class__.__name__}: {e}")
aiogram.utils.exceptions.NetworkError: Aiohttp client throws an error: ClientConnectorError: Cannot connect to host api.telegram.org:443 ssl:default [getaddrinfo failed]
17:58:29 aiogram.dispatcher.dispatcher ERROR Cause exception while getting updates.
Traceback (most recent call last):
  File "C:\Users\milan\OneDrive\Документы\Innopolis_studying\1_year\2_sem\well_wisher_inno_bot\venv\lib\site-packages\aiohttp\connector.py", line 1152, in _create_direct_connection
    hosts = await asyncio.shield(host_resolved)
  File "C:\Users\milan\OneDrive\Документы\Innopolis_studying\1_year\2_sem\well_wisher_inno_bot\venv\lib\site-packages\aiohttp\connector.py", line 874, in _resolve_host
    addrs = await self._resolver.resolve(host, port, family=self._family)
  File "C:\Users\milan\OneDrive\Документы\Innopolis_studying\1_year\2_sem\well_wisher_inno_bot\venv\lib\site-packages\aiohttp\resolver.py", line 33, in resolve
    infos = await self._loop.getaddrinfo(
  File "C:\Users\milan\AppData\Local\Programs\Python\Python310\lib\asyncio\base_events.py", line 860, in getaddrinfo
    return await self.run_in_executor(
  File "C:\Users\milan\AppData\Local\Programs\Python\Python310\lib\concurrent\futures\thread.py", line 58, in run
    result = self.fn(*self.args, **self.kwargs)
  File "C:\Users\milan\AppData\Local\Programs\Python\Python310\lib\socket.py", line 955, in getaddrinfo
    for res in _socket.getaddrinfo(host, port, family, type, proto, flags):
socket.gaierror: [Errno 11004] getaddrinfo failed

The above exception was the direct cause of the following exception:

Traceback (most recent call last):
  File "C:\Users\milan\OneDrive\Документы\Innopolis_studying\1_year\2_sem\well_wisher_inno_bot\venv\lib\site-packages\aiogram\bot\api.py", line 139, in make_request
    async with session.post(url, data=req, **kwargs) as response:
  File "C:\Users\milan\OneDrive\Документы\Innopolis_studying\1_year\2_sem\well_wisher_inno_bot\venv\lib\site-packages\aiohttp\client.py", line 1141, in __aenter__
    self._resp = await self._coro
  File "C:\Users\milan\OneDrive\Документы\Innopolis_studying\1_year\2_sem\well_wisher_inno_bot\venv\lib\site-packages\aiohttp\client.py", line 536, in _request
    conn = await self._connector.connect(
  File "C:\Users\milan\OneDrive\Документы\Innopolis_studying\1_year\2_sem\well_wisher_inno_bot\venv\lib\site-packages\aiohttp\connector.py", line 540, in connect
    proto = await self._create_connection(req, traces, timeout)
  File "C:\Users\milan\OneDrive\Документы\Innopolis_studying\1_year\2_sem\well_wisher_inno_bot\venv\lib\site-packages\aiohttp\connector.py", line 901, in _create_connection
    _, proto = await self._create_direct_connection(req, traces, timeout)
  File "C:\Users\milan\OneDrive\Документы\Innopolis_studying\1_year\2_sem\well_wisher_inno_bot\venv\lib\site-packages\aiohttp\connector.py", line 1166, in _create_direct_connection
    raise ClientConnectorError(req.connection_key, exc) from exc
aiohttp.client_exceptions.ClientConnectorError: Cannot connect to host api.telegram.org:443 ssl:default [getaddrinfo failed]

During handling of the above exception, another exception occurred:

Traceback (most recent call last):
  File "C:\Users\milan\OneDrive\Документы\Innopolis_studying\1_year\2_sem\well_wisher_inno_bot\venv\lib\site-packages\aiogram\dispatcher\dispatcher.py", line 381, in start_polling
    updates = await self.bot.get_updates(
  File "C:\Users\milan\OneDrive\Документы\Innopolis_studying\1_year\2_sem\well_wisher_inno_bot\venv\lib\site-packages\aiogram\bot\bot.py", line 110, in get_updates
    result = await self.request(api.Methods.GET_UPDATES, payload)
  File "C:\Users\milan\OneDrive\Документы\Innopolis_studying\1_year\2_sem\well_wisher_inno_bot\venv\lib\site-packages\aiogram\bot\base.py", line 236, in request
    return await api.make_request(await self.get_session(), self.server, self.__token, method, data, files,
  File "C:\Users\milan\OneDrive\Документы\Innopolis_studying\1_year\2_sem\well_wisher_inno_bot\venv\lib\site-packages\aiogram\bot\api.py", line 142, in make_request
    raise exceptions.NetworkError(f"aiohttp client throws an error: {e.__class__.__name__}: {e}")
aiogram.utils.exceptions.NetworkError: Aiohttp client throws an error: ClientConnectorError: Cannot connect to host api.telegram.org:443 ssl:default [getaddrinfo failed]
17:58:34 aiogram.dispatcher.dispatcher ERROR Cause exception while getting updates.
Traceback (most recent call last):
  File "C:\Users\milan\OneDrive\Документы\Innopolis_studying\1_year\2_sem\well_wisher_inno_bot\venv\lib\site-packages\aiohttp\connector.py", line 1152, in _create_direct_connection
    hosts = await asyncio.shield(host_resolved)
  File "C:\Users\milan\OneDrive\Документы\Innopolis_studying\1_year\2_sem\well_wisher_inno_bot\venv\lib\site-packages\aiohttp\connector.py", line 874, in _resolve_host
    addrs = await self._resolver.resolve(host, port, family=self._family)
  File "C:\Users\milan\OneDrive\Документы\Innopolis_studying\1_year\2_sem\well_wisher_inno_bot\venv\lib\site-packages\aiohttp\resolver.py", line 33, in resolve
    infos = await self._loop.getaddrinfo(
  File "C:\Users\milan\AppData\Local\Programs\Python\Python310\lib\asyncio\base_events.py", line 860, in getaddrinfo
    return await self.run_in_executor(
  File "C:\Users\milan\AppData\Local\Programs\Python\Python310\lib\concurrent\futures\thread.py", line 58, in run
    result = self.fn(*self.args, **self.kwargs)
  File "C:\Users\milan\AppData\Local\Programs\Python\Python310\lib\socket.py", line 955, in getaddrinfo
    for res in _socket.getaddrinfo(host, port, family, type, proto, flags):
socket.gaierror: [Errno 11004] getaddrinfo failed

The above exception was the direct cause of the following exception:

Traceback (most recent call last):
  File "C:\Users\milan\OneDrive\Документы\Innopolis_studying\1_year\2_sem\well_wisher_inno_bot\venv\lib\site-packages\aiogram\bot\api.py", line 139, in make_request
    async with session.post(url, data=req, **kwargs) as response:
  File "C:\Users\milan\OneDrive\Документы\Innopolis_studying\1_year\2_sem\well_wisher_inno_bot\venv\lib\site-packages\aiohttp\client.py", line 1141, in __aenter__
    self._resp = await self._coro
  File "C:\Users\milan\OneDrive\Документы\Innopolis_studying\1_year\2_sem\well_wisher_inno_bot\venv\lib\site-packages\aiohttp\client.py", line 536, in _request
    conn = await self._connector.connect(
  File "C:\Users\milan\OneDrive\Документы\Innopolis_studying\1_year\2_sem\well_wisher_inno_bot\venv\lib\site-packages\aiohttp\connector.py", line 540, in connect
    proto = await self._create_connection(req, traces, timeout)
  File "C:\Users\milan\OneDrive\Документы\Innopolis_studying\1_year\2_sem\well_wisher_inno_bot\venv\lib\site-packages\aiohttp\connector.py", line 901, in _create_connection
    _, proto = await self._create_direct_connection(req, traces, timeout)
  File "C:\Users\milan\OneDrive\Документы\Innopolis_studying\1_year\2_sem\well_wisher_inno_bot\venv\lib\site-packages\aiohttp\connector.py", line 1166, in _create_direct_connection
    raise ClientConnectorError(req.connection_key, exc) from exc
aiohttp.client_exceptions.ClientConnectorError: Cannot connect to host api.telegram.org:443 ssl:default [getaddrinfo failed]

During handling of the above exception, another exception occurred:

Traceback (most recent call last):
  File "C:\Users\milan\OneDrive\Документы\Innopolis_studying\1_year\2_sem\well_wisher_inno_bot\venv\lib\site-packages\aiogram\dispatcher\dispatcher.py", line 381, in start_polling
    updates = await self.bot.get_updates(
  File "C:\Users\milan\OneDrive\Документы\Innopolis_studying\1_year\2_sem\well_wisher_inno_bot\venv\lib\site-packages\aiogram\bot\bot.py", line 110, in get_updates
    result = await self.request(api.Methods.GET_UPDATES, payload)
  File "C:\Users\milan\OneDrive\Документы\Innopolis_studying\1_year\2_sem\well_wisher_inno_bot\venv\lib\site-packages\aiogram\bot\base.py", line 236, in request
    return await api.make_request(await self.get_session(), self.server, self.__token, method, data, files,
  File "C:\Users\milan\OneDrive\Документы\Innopolis_studying\1_year\2_sem\well_wisher_inno_bot\venv\lib\site-packages\aiogram\bot\api.py", line 142, in make_request
    raise exceptions.NetworkError(f"aiohttp client throws an error: {e.__class__.__name__}: {e}")
aiogram.utils.exceptions.NetworkError: Aiohttp client throws an error: ClientConnectorError: Cannot connect to host api.telegram.org:443 ssl:default [getaddrinfo failed]
17:58:39 aiogram.dispatcher.dispatcher ERROR Cause exception while getting updates.
Traceback (most recent call last):
  File "C:\Users\milan\OneDrive\Документы\Innopolis_studying\1_year\2_sem\well_wisher_inno_bot\venv\lib\site-packages\aiohttp\connector.py", line 1152, in _create_direct_connection
    hosts = await asyncio.shield(host_resolved)
  File "C:\Users\milan\OneDrive\Документы\Innopolis_studying\1_year\2_sem\well_wisher_inno_bot\venv\lib\site-packages\aiohttp\connector.py", line 874, in _resolve_host
    addrs = await self._resolver.resolve(host, port, family=self._family)
  File "C:\Users\milan\OneDrive\Документы\Innopolis_studying\1_year\2_sem\well_wisher_inno_bot\venv\lib\site-packages\aiohttp\resolver.py", line 33, in resolve
    infos = await self._loop.getaddrinfo(
  File "C:\Users\milan\AppData\Local\Programs\Python\Python310\lib\asyncio\base_events.py", line 860, in getaddrinfo
    return await self.run_in_executor(
  File "C:\Users\milan\AppData\Local\Programs\Python\Python310\lib\concurrent\futures\thread.py", line 58, in run
    result = self.fn(*self.args, **self.kwargs)
  File "C:\Users\milan\AppData\Local\Programs\Python\Python310\lib\socket.py", line 955, in getaddrinfo
    for res in _socket.getaddrinfo(host, port, family, type, proto, flags):
socket.gaierror: [Errno 11004] getaddrinfo failed

The above exception was the direct cause of the following exception:

Traceback (most recent call last):
  File "C:\Users\milan\OneDrive\Документы\Innopolis_studying\1_year\2_sem\well_wisher_inno_bot\venv\lib\site-packages\aiogram\bot\api.py", line 139, in make_request
    async with session.post(url, data=req, **kwargs) as response:
  File "C:\Users\milan\OneDrive\Документы\Innopolis_studying\1_year\2_sem\well_wisher_inno_bot\venv\lib\site-packages\aiohttp\client.py", line 1141, in __aenter__
    self._resp = await self._coro
  File "C:\Users\milan\OneDrive\Документы\Innopolis_studying\1_year\2_sem\well_wisher_inno_bot\venv\lib\site-packages\aiohttp\client.py", line 536, in _request
    conn = await self._connector.connect(
  File "C:\Users\milan\OneDrive\Документы\Innopolis_studying\1_year\2_sem\well_wisher_inno_bot\venv\lib\site-packages\aiohttp\connector.py", line 540, in connect
    proto = await self._create_connection(req, traces, timeout)
  File "C:\Users\milan\OneDrive\Документы\Innopolis_studying\1_year\2_sem\well_wisher_inno_bot\venv\lib\site-packages\aiohttp\connector.py", line 901, in _create_connection
    _, proto = await self._create_direct_connection(req, traces, timeout)
  File "C:\Users\milan\OneDrive\Документы\Innopolis_studying\1_year\2_sem\well_wisher_inno_bot\venv\lib\site-packages\aiohttp\connector.py", line 1166, in _create_direct_connection
    raise ClientConnectorError(req.connection_key, exc) from exc
aiohttp.client_exceptions.ClientConnectorError: Cannot connect to host api.telegram.org:443 ssl:default [getaddrinfo failed]

During handling of the above exception, another exception occurred:

Traceback (most recent call last):
  File "C:\Users\milan\OneDrive\Документы\Innopolis_studying\1_year\2_sem\well_wisher_inno_bot\venv\lib\site-packages\aiogram\dispatcher\dispatcher.py", line 381, in start_polling
    updates = await self.bot.get_updates(
  File "C:\Users\milan\OneDrive\Документы\Innopolis_studying\1_year\2_sem\well_wisher_inno_bot\venv\lib\site-packages\aiogram\bot\bot.py", line 110, in get_updates
    result = await self.request(api.Methods.GET_UPDATES, payload)
  File "C:\Users\milan\OneDrive\Документы\Innopolis_studying\1_year\2_sem\well_wisher_inno_bot\venv\lib\site-packages\aiogram\bot\base.py", line 236, in request
    return await api.make_request(await self.get_session(), self.server, self.__token, method, data, files,
  File "C:\Users\milan\OneDrive\Документы\Innopolis_studying\1_year\2_sem\well_wisher_inno_bot\venv\lib\site-packages\aiogram\bot\api.py", line 142, in make_request
    raise exceptions.NetworkError(f"aiohttp client throws an error: {e.__class__.__name__}: {e}")
aiogram.utils.exceptions.NetworkError: Aiohttp client throws an error: ClientConnectorError: Cannot connect to host api.telegram.org:443 ssl:default [getaddrinfo failed]
17:58:44 aiogram.dispatcher.dispatcher ERROR Cause exception while getting updates.
Traceback (most recent call last):
  File "C:\Users\milan\OneDrive\Документы\Innopolis_studying\1_year\2_sem\well_wisher_inno_bot\venv\lib\site-packages\aiohttp\connector.py", line 1152, in _create_direct_connection
    hosts = await asyncio.shield(host_resolved)
  File "C:\Users\milan\OneDrive\Документы\Innopolis_studying\1_year\2_sem\well_wisher_inno_bot\venv\lib\site-packages\aiohttp\connector.py", line 874, in _resolve_host
    addrs = await self._resolver.resolve(host, port, family=self._family)
  File "C:\Users\milan\OneDrive\Документы\Innopolis_studying\1_year\2_sem\well_wisher_inno_bot\venv\lib\site-packages\aiohttp\resolver.py", line 33, in resolve
    infos = await self._loop.getaddrinfo(
  File "C:\Users\milan\AppData\Local\Programs\Python\Python310\lib\asyncio\base_events.py", line 860, in getaddrinfo
    return await self.run_in_executor(
  File "C:\Users\milan\AppData\Local\Programs\Python\Python310\lib\concurrent\futures\thread.py", line 58, in run
    result = self.fn(*self.args, **self.kwargs)
  File "C:\Users\milan\AppData\Local\Programs\Python\Python310\lib\socket.py", line 955, in getaddrinfo
    for res in _socket.getaddrinfo(host, port, family, type, proto, flags):
socket.gaierror: [Errno 11004] getaddrinfo failed

The above exception was the direct cause of the following exception:

Traceback (most recent call last):
  File "C:\Users\milan\OneDrive\Документы\Innopolis_studying\1_year\2_sem\well_wisher_inno_bot\venv\lib\site-packages\aiogram\bot\api.py", line 139, in make_request
    async with session.post(url, data=req, **kwargs) as response:
  File "C:\Users\milan\OneDrive\Документы\Innopolis_studying\1_year\2_sem\well_wisher_inno_bot\venv\lib\site-packages\aiohttp\client.py", line 1141, in __aenter__
    self._resp = await self._coro
  File "C:\Users\milan\OneDrive\Документы\Innopolis_studying\1_year\2_sem\well_wisher_inno_bot\venv\lib\site-packages\aiohttp\client.py", line 536, in _request
    conn = await self._connector.connect(
  File "C:\Users\milan\OneDrive\Документы\Innopolis_studying\1_year\2_sem\well_wisher_inno_bot\venv\lib\site-packages\aiohttp\connector.py", line 540, in connect
    proto = await self._create_connection(req, traces, timeout)
  File "C:\Users\milan\OneDrive\Документы\Innopolis_studying\1_year\2_sem\well_wisher_inno_bot\venv\lib\site-packages\aiohttp\connector.py", line 901, in _create_connection
    _, proto = await self._create_direct_connection(req, traces, timeout)
  File "C:\Users\milan\OneDrive\Документы\Innopolis_studying\1_year\2_sem\well_wisher_inno_bot\venv\lib\site-packages\aiohttp\connector.py", line 1166, in _create_direct_connection
    raise ClientConnectorError(req.connection_key, exc) from exc
aiohttp.client_exceptions.ClientConnectorError: Cannot connect to host api.telegram.org:443 ssl:default [getaddrinfo failed]

During handling of the above exception, another exception occurred:

Traceback (most recent call last):
  File "C:\Users\milan\OneDrive\Документы\Innopolis_studying\1_year\2_sem\well_wisher_inno_bot\venv\lib\site-packages\aiogram\dispatcher\dispatcher.py", line 381, in start_polling
    updates = await self.bot.get_updates(
  File "C:\Users\milan\OneDrive\Документы\Innopolis_studying\1_year\2_sem\well_wisher_inno_bot\venv\lib\site-packages\aiogram\bot\bot.py", line 110, in get_updates
    result = await self.request(api.Methods.GET_UPDATES, payload)
  File "C:\Users\milan\OneDrive\Документы\Innopolis_studying\1_year\2_sem\well_wisher_inno_bot\venv\lib\site-packages\aiogram\bot\base.py", line 236, in request
    return await api.make_request(await self.get_session(), self.server, self.__token, method, data, files,
  File "C:\Users\milan\OneDrive\Документы\Innopolis_studying\1_year\2_sem\well_wisher_inno_bot\venv\lib\site-packages\aiogram\bot\api.py", line 142, in make_request
    raise exceptions.NetworkError(f"aiohttp client throws an error: {e.__class__.__name__}: {e}")
aiogram.utils.exceptions.NetworkError: Aiohttp client throws an error: ClientConnectorError: Cannot connect to host api.telegram.org:443 ssl:default [getaddrinfo failed]
17:58:49 aiogram.dispatcher.dispatcher ERROR Cause exception while getting updates.
Traceback (most recent call last):
  File "C:\Users\milan\OneDrive\Документы\Innopolis_studying\1_year\2_sem\well_wisher_inno_bot\venv\lib\site-packages\aiohttp\connector.py", line 1152, in _create_direct_connection
    hosts = await asyncio.shield(host_resolved)
  File "C:\Users\milan\OneDrive\Документы\Innopolis_studying\1_year\2_sem\well_wisher_inno_bot\venv\lib\site-packages\aiohttp\connector.py", line 874, in _resolve_host
    addrs = await self._resolver.resolve(host, port, family=self._family)
  File "C:\Users\milan\OneDrive\Документы\Innopolis_studying\1_year\2_sem\well_wisher_inno_bot\venv\lib\site-packages\aiohttp\resolver.py", line 33, in resolve
    infos = await self._loop.getaddrinfo(
  File "C:\Users\milan\AppData\Local\Programs\Python\Python310\lib\asyncio\base_events.py", line 860, in getaddrinfo
    return await self.run_in_executor(
  File "C:\Users\milan\AppData\Local\Programs\Python\Python310\lib\concurrent\futures\thread.py", line 58, in run
    result = self.fn(*self.args, **self.kwargs)
  File "C:\Users\milan\AppData\Local\Programs\Python\Python310\lib\socket.py", line 955, in getaddrinfo
    for res in _socket.getaddrinfo(host, port, family, type, proto, flags):
socket.gaierror: [Errno 11004] getaddrinfo failed

The above exception was the direct cause of the following exception:

Traceback (most recent call last):
  File "C:\Users\milan\OneDrive\Документы\Innopolis_studying\1_year\2_sem\well_wisher_inno_bot\venv\lib\site-packages\aiogram\bot\api.py", line 139, in make_request
    async with session.post(url, data=req, **kwargs) as response:
  File "C:\Users\milan\OneDrive\Документы\Innopolis_studying\1_year\2_sem\well_wisher_inno_bot\venv\lib\site-packages\aiohttp\client.py", line 1141, in __aenter__
    self._resp = await self._coro
  File "C:\Users\milan\OneDrive\Документы\Innopolis_studying\1_year\2_sem\well_wisher_inno_bot\venv\lib\site-packages\aiohttp\client.py", line 536, in _request
    conn = await self._connector.connect(
  File "C:\Users\milan\OneDrive\Документы\Innopolis_studying\1_year\2_sem\well_wisher_inno_bot\venv\lib\site-packages\aiohttp\connector.py", line 540, in connect
    proto = await self._create_connection(req, traces, timeout)
  File "C:\Users\milan\OneDrive\Документы\Innopolis_studying\1_year\2_sem\well_wisher_inno_bot\venv\lib\site-packages\aiohttp\connector.py", line 901, in _create_connection
    _, proto = await self._create_direct_connection(req, traces, timeout)
  File "C:\Users\milan\OneDrive\Документы\Innopolis_studying\1_year\2_sem\well_wisher_inno_bot\venv\lib\site-packages\aiohttp\connector.py", line 1166, in _create_direct_connection
    raise ClientConnectorError(req.connection_key, exc) from exc
aiohttp.client_exceptions.ClientConnectorError: Cannot connect to host api.telegram.org:443 ssl:default [getaddrinfo failed]

During handling of the above exception, another exception occurred:

Traceback (most recent call last):
  File "C:\Users\milan\OneDrive\Документы\Innopolis_studying\1_year\2_sem\well_wisher_inno_bot\venv\lib\site-packages\aiogram\dispatcher\dispatcher.py", line 381, in start_polling
    updates = await self.bot.get_updates(
  File "C:\Users\milan\OneDrive\Документы\Innopolis_studying\1_year\2_sem\well_wisher_inno_bot\venv\lib\site-packages\aiogram\bot\bot.py", line 110, in get_updates
    result = await self.request(api.Methods.GET_UPDATES, payload)
  File "C:\Users\milan\OneDrive\Документы\Innopolis_studying\1_year\2_sem\well_wisher_inno_bot\venv\lib\site-packages\aiogram\bot\base.py", line 236, in request
    return await api.make_request(await self.get_session(), self.server, self.__token, method, data, files,
  File "C:\Users\milan\OneDrive\Документы\Innopolis_studying\1_year\2_sem\well_wisher_inno_bot\venv\lib\site-packages\aiogram\bot\api.py", line 142, in make_request
    raise exceptions.NetworkError(f"aiohttp client throws an error: {e.__class__.__name__}: {e}")
aiogram.utils.exceptions.NetworkError: Aiohttp client throws an error: ClientConnectorError: Cannot connect to host api.telegram.org:443 ssl:default [getaddrinfo failed]
17:58:54 aiogram.dispatcher.dispatcher ERROR Cause exception while getting updates.
Traceback (most recent call last):
  File "C:\Users\milan\OneDrive\Документы\Innopolis_studying\1_year\2_sem\well_wisher_inno_bot\venv\lib\site-packages\aiohttp\connector.py", line 1152, in _create_direct_connection
    hosts = await asyncio.shield(host_resolved)
  File "C:\Users\milan\OneDrive\Документы\Innopolis_studying\1_year\2_sem\well_wisher_inno_bot\venv\lib\site-packages\aiohttp\connector.py", line 874, in _resolve_host
    addrs = await self._resolver.resolve(host, port, family=self._family)
  File "C:\Users\milan\OneDrive\Документы\Innopolis_studying\1_year\2_sem\well_wisher_inno_bot\venv\lib\site-packages\aiohttp\resolver.py", line 33, in resolve
    infos = await self._loop.getaddrinfo(
  File "C:\Users\milan\AppData\Local\Programs\Python\Python310\lib\asyncio\base_events.py", line 860, in getaddrinfo
    return await self.run_in_executor(
  File "C:\Users\milan\AppData\Local\Programs\Python\Python310\lib\concurrent\futures\thread.py", line 58, in run
    result = self.fn(*self.args, **self.kwargs)
  File "C:\Users\milan\AppData\Local\Programs\Python\Python310\lib\socket.py", line 955, in getaddrinfo
    for res in _socket.getaddrinfo(host, port, family, type, proto, flags):
socket.gaierror: [Errno 11004] getaddrinfo failed

The above exception was the direct cause of the following exception:

Traceback (most recent call last):
  File "C:\Users\milan\OneDrive\Документы\Innopolis_studying\1_year\2_sem\well_wisher_inno_bot\venv\lib\site-packages\aiogram\bot\api.py", line 139, in make_request
    async with session.post(url, data=req, **kwargs) as response:
  File "C:\Users\milan\OneDrive\Документы\Innopolis_studying\1_year\2_sem\well_wisher_inno_bot\venv\lib\site-packages\aiohttp\client.py", line 1141, in __aenter__
    self._resp = await self._coro
  File "C:\Users\milan\OneDrive\Документы\Innopolis_studying\1_year\2_sem\well_wisher_inno_bot\venv\lib\site-packages\aiohttp\client.py", line 536, in _request
    conn = await self._connector.connect(
  File "C:\Users\milan\OneDrive\Документы\Innopolis_studying\1_year\2_sem\well_wisher_inno_bot\venv\lib\site-packages\aiohttp\connector.py", line 540, in connect
    proto = await self._create_connection(req, traces, timeout)
  File "C:\Users\milan\OneDrive\Документы\Innopolis_studying\1_year\2_sem\well_wisher_inno_bot\venv\lib\site-packages\aiohttp\connector.py", line 901, in _create_connection
    _, proto = await self._create_direct_connection(req, traces, timeout)
  File "C:\Users\milan\OneDrive\Документы\Innopolis_studying\1_year\2_sem\well_wisher_inno_bot\venv\lib\site-packages\aiohttp\connector.py", line 1166, in _create_direct_connection
    raise ClientConnectorError(req.connection_key, exc) from exc
aiohttp.client_exceptions.ClientConnectorError: Cannot connect to host api.telegram.org:443 ssl:default [getaddrinfo failed]

During handling of the above exception, another exception occurred:

Traceback (most recent call last):
  File "C:\Users\milan\OneDrive\Документы\Innopolis_studying\1_year\2_sem\well_wisher_inno_bot\venv\lib\site-packages\aiogram\dispatcher\dispatcher.py", line 381, in start_polling
    updates = await self.bot.get_updates(
  File "C:\Users\milan\OneDrive\Документы\Innopolis_studying\1_year\2_sem\well_wisher_inno_bot\venv\lib\site-packages\aiogram\bot\bot.py", line 110, in get_updates
    result = await self.request(api.Methods.GET_UPDATES, payload)
  File "C:\Users\milan\OneDrive\Документы\Innopolis_studying\1_year\2_sem\well_wisher_inno_bot\venv\lib\site-packages\aiogram\bot\base.py", line 236, in request
    return await api.make_request(await self.get_session(), self.server, self.__token, method, data, files,
  File "C:\Users\milan\OneDrive\Документы\Innopolis_studying\1_year\2_sem\well_wisher_inno_bot\venv\lib\site-packages\aiogram\bot\api.py", line 142, in make_request
    raise exceptions.NetworkError(f"aiohttp client throws an error: {e.__class__.__name__}: {e}")
aiogram.utils.exceptions.NetworkError: Aiohttp client throws an error: ClientConnectorError: Cannot connect to host api.telegram.org:443 ssl:default [getaddrinfo failed]
17:58:59 aiogram.dispatcher.dispatcher ERROR Cause exception while getting updates.
Traceback (most recent call last):
  File "C:\Users\milan\OneDrive\Документы\Innopolis_studying\1_year\2_sem\well_wisher_inno_bot\venv\lib\site-packages\aiohttp\connector.py", line 1152, in _create_direct_connection
    hosts = await asyncio.shield(host_resolved)
  File "C:\Users\milan\OneDrive\Документы\Innopolis_studying\1_year\2_sem\well_wisher_inno_bot\venv\lib\site-packages\aiohttp\connector.py", line 874, in _resolve_host
    addrs = await self._resolver.resolve(host, port, family=self._family)
  File "C:\Users\milan\OneDrive\Документы\Innopolis_studying\1_year\2_sem\well_wisher_inno_bot\venv\lib\site-packages\aiohttp\resolver.py", line 33, in resolve
    infos = await self._loop.getaddrinfo(
  File "C:\Users\milan\AppData\Local\Programs\Python\Python310\lib\asyncio\base_events.py", line 860, in getaddrinfo
    return await self.run_in_executor(
  File "C:\Users\milan\AppData\Local\Programs\Python\Python310\lib\concurrent\futures\thread.py", line 58, in run
    result = self.fn(*self.args, **self.kwargs)
  File "C:\Users\milan\AppData\Local\Programs\Python\Python310\lib\socket.py", line 955, in getaddrinfo
    for res in _socket.getaddrinfo(host, port, family, type, proto, flags):
socket.gaierror: [Errno 11004] getaddrinfo failed

The above exception was the direct cause of the following exception:

Traceback (most recent call last):
  File "C:\Users\milan\OneDrive\Документы\Innopolis_studying\1_year\2_sem\well_wisher_inno_bot\venv\lib\site-packages\aiogram\bot\api.py", line 139, in make_request
    async with session.post(url, data=req, **kwargs) as response:
  File "C:\Users\milan\OneDrive\Документы\Innopolis_studying\1_year\2_sem\well_wisher_inno_bot\venv\lib\site-packages\aiohttp\client.py", line 1141, in __aenter__
    self._resp = await self._coro
  File "C:\Users\milan\OneDrive\Документы\Innopolis_studying\1_year\2_sem\well_wisher_inno_bot\venv\lib\site-packages\aiohttp\client.py", line 536, in _request
    conn = await self._connector.connect(
  File "C:\Users\milan\OneDrive\Документы\Innopolis_studying\1_year\2_sem\well_wisher_inno_bot\venv\lib\site-packages\aiohttp\connector.py", line 540, in connect
    proto = await self._create_connection(req, traces, timeout)
  File "C:\Users\milan\OneDrive\Документы\Innopolis_studying\1_year\2_sem\well_wisher_inno_bot\venv\lib\site-packages\aiohttp\connector.py", line 901, in _create_connection
    _, proto = await self._create_direct_connection(req, traces, timeout)
  File "C:\Users\milan\OneDrive\Документы\Innopolis_studying\1_year\2_sem\well_wisher_inno_bot\venv\lib\site-packages\aiohttp\connector.py", line 1166, in _create_direct_connection
    raise ClientConnectorError(req.connection_key, exc) from exc
aiohttp.client_exceptions.ClientConnectorError: Cannot connect to host api.telegram.org:443 ssl:default [getaddrinfo failed]

During handling of the above exception, another exception occurred:

Traceback (most recent call last):
  File "C:\Users\milan\OneDrive\Документы\Innopolis_studying\1_year\2_sem\well_wisher_inno_bot\venv\lib\site-packages\aiogram\dispatcher\dispatcher.py", line 381, in start_polling
    updates = await self.bot.get_updates(
  File "C:\Users\milan\OneDrive\Документы\Innopolis_studying\1_year\2_sem\well_wisher_inno_bot\venv\lib\site-packages\aiogram\bot\bot.py", line 110, in get_updates
    result = await self.request(api.Methods.GET_UPDATES, payload)
  File "C:\Users\milan\OneDrive\Документы\Innopolis_studying\1_year\2_sem\well_wisher_inno_bot\venv\lib\site-packages\aiogram\bot\base.py", line 236, in request
    return await api.make_request(await self.get_session(), self.server, self.__token, method, data, files,
  File "C:\Users\milan\OneDrive\Документы\Innopolis_studying\1_year\2_sem\well_wisher_inno_bot\venv\lib\site-packages\aiogram\bot\api.py", line 142, in make_request
    raise exceptions.NetworkError(f"aiohttp client throws an error: {e.__class__.__name__}: {e}")
aiogram.utils.exceptions.NetworkError: Aiohttp client throws an error: ClientConnectorError: Cannot connect to host api.telegram.org:443 ssl:default [getaddrinfo failed]
17:59:04 aiogram.dispatcher.dispatcher ERROR Cause exception while getting updates.
Traceback (most recent call last):
  File "C:\Users\milan\OneDrive\Документы\Innopolis_studying\1_year\2_sem\well_wisher_inno_bot\venv\lib\site-packages\aiohttp\connector.py", line 1152, in _create_direct_connection
    hosts = await asyncio.shield(host_resolved)
  File "C:\Users\milan\OneDrive\Документы\Innopolis_studying\1_year\2_sem\well_wisher_inno_bot\venv\lib\site-packages\aiohttp\connector.py", line 874, in _resolve_host
    addrs = await self._resolver.resolve(host, port, family=self._family)
  File "C:\Users\milan\OneDrive\Документы\Innopolis_studying\1_year\2_sem\well_wisher_inno_bot\venv\lib\site-packages\aiohttp\resolver.py", line 33, in resolve
    infos = await self._loop.getaddrinfo(
  File "C:\Users\milan\AppData\Local\Programs\Python\Python310\lib\asyncio\base_events.py", line 860, in getaddrinfo
    return await self.run_in_executor(
  File "C:\Users\milan\AppData\Local\Programs\Python\Python310\lib\concurrent\futures\thread.py", line 58, in run
    result = self.fn(*self.args, **self.kwargs)
  File "C:\Users\milan\AppData\Local\Programs\Python\Python310\lib\socket.py", line 955, in getaddrinfo
    for res in _socket.getaddrinfo(host, port, family, type, proto, flags):
socket.gaierror: [Errno 11004] getaddrinfo failed

The above exception was the direct cause of the following exception:

Traceback (most recent call last):
  File "C:\Users\milan\OneDrive\Документы\Innopolis_studying\1_year\2_sem\well_wisher_inno_bot\venv\lib\site-packages\aiogram\bot\api.py", line 139, in make_request
    async with session.post(url, data=req, **kwargs) as response:
  File "C:\Users\milan\OneDrive\Документы\Innopolis_studying\1_year\2_sem\well_wisher_inno_bot\venv\lib\site-packages\aiohttp\client.py", line 1141, in __aenter__
    self._resp = await self._coro
  File "C:\Users\milan\OneDrive\Документы\Innopolis_studying\1_year\2_sem\well_wisher_inno_bot\venv\lib\site-packages\aiohttp\client.py", line 536, in _request
    conn = await self._connector.connect(
  File "C:\Users\milan\OneDrive\Документы\Innopolis_studying\1_year\2_sem\well_wisher_inno_bot\venv\lib\site-packages\aiohttp\connector.py", line 540, in connect
    proto = await self._create_connection(req, traces, timeout)
  File "C:\Users\milan\OneDrive\Документы\Innopolis_studying\1_year\2_sem\well_wisher_inno_bot\venv\lib\site-packages\aiohttp\connector.py", line 901, in _create_connection
    _, proto = await self._create_direct_connection(req, traces, timeout)
  File "C:\Users\milan\OneDrive\Документы\Innopolis_studying\1_year\2_sem\well_wisher_inno_bot\venv\lib\site-packages\aiohttp\connector.py", line 1166, in _create_direct_connection
    raise ClientConnectorError(req.connection_key, exc) from exc
aiohttp.client_exceptions.ClientConnectorError: Cannot connect to host api.telegram.org:443 ssl:default [getaddrinfo failed]

During handling of the above exception, another exception occurred:

Traceback (most recent call last):
  File "C:\Users\milan\OneDrive\Документы\Innopolis_studying\1_year\2_sem\well_wisher_inno_bot\venv\lib\site-packages\aiogram\dispatcher\dispatcher.py", line 381, in start_polling
    updates = await self.bot.get_updates(
  File "C:\Users\milan\OneDrive\Документы\Innopolis_studying\1_year\2_sem\well_wisher_inno_bot\venv\lib\site-packages\aiogram\bot\bot.py", line 110, in get_updates
    result = await self.request(api.Methods.GET_UPDATES, payload)
  File "C:\Users\milan\OneDrive\Документы\Innopolis_studying\1_year\2_sem\well_wisher_inno_bot\venv\lib\site-packages\aiogram\bot\base.py", line 236, in request
    return await api.make_request(await self.get_session(), self.server, self.__token, method, data, files,
  File "C:\Users\milan\OneDrive\Документы\Innopolis_studying\1_year\2_sem\well_wisher_inno_bot\venv\lib\site-packages\aiogram\bot\api.py", line 142, in make_request
    raise exceptions.NetworkError(f"aiohttp client throws an error: {e.__class__.__name__}: {e}")
aiogram.utils.exceptions.NetworkError: Aiohttp client throws an error: ClientConnectorError: Cannot connect to host api.telegram.org:443 ssl:default [getaddrinfo failed]
17:59:09 aiogram.dispatcher.dispatcher ERROR Cause exception while getting updates.
Traceback (most recent call last):
  File "C:\Users\milan\OneDrive\Документы\Innopolis_studying\1_year\2_sem\well_wisher_inno_bot\venv\lib\site-packages\aiohttp\connector.py", line 1152, in _create_direct_connection
    hosts = await asyncio.shield(host_resolved)
  File "C:\Users\milan\OneDrive\Документы\Innopolis_studying\1_year\2_sem\well_wisher_inno_bot\venv\lib\site-packages\aiohttp\connector.py", line 874, in _resolve_host
    addrs = await self._resolver.resolve(host, port, family=self._family)
  File "C:\Users\milan\OneDrive\Документы\Innopolis_studying\1_year\2_sem\well_wisher_inno_bot\venv\lib\site-packages\aiohttp\resolver.py", line 33, in resolve
    infos = await self._loop.getaddrinfo(
  File "C:\Users\milan\AppData\Local\Programs\Python\Python310\lib\asyncio\base_events.py", line 860, in getaddrinfo
    return await self.run_in_executor(
  File "C:\Users\milan\AppData\Local\Programs\Python\Python310\lib\concurrent\futures\thread.py", line 58, in run
    result = self.fn(*self.args, **self.kwargs)
  File "C:\Users\milan\AppData\Local\Programs\Python\Python310\lib\socket.py", line 955, in getaddrinfo
    for res in _socket.getaddrinfo(host, port, family, type, proto, flags):
socket.gaierror: [Errno 11004] getaddrinfo failed

The above exception was the direct cause of the following exception:

Traceback (most recent call last):
  File "C:\Users\milan\OneDrive\Документы\Innopolis_studying\1_year\2_sem\well_wisher_inno_bot\venv\lib\site-packages\aiogram\bot\api.py", line 139, in make_request
    async with session.post(url, data=req, **kwargs) as response:
  File "C:\Users\milan\OneDrive\Документы\Innopolis_studying\1_year\2_sem\well_wisher_inno_bot\venv\lib\site-packages\aiohttp\client.py", line 1141, in __aenter__
    self._resp = await self._coro
  File "C:\Users\milan\OneDrive\Документы\Innopolis_studying\1_year\2_sem\well_wisher_inno_bot\venv\lib\site-packages\aiohttp\client.py", line 536, in _request
    conn = await self._connector.connect(
  File "C:\Users\milan\OneDrive\Документы\Innopolis_studying\1_year\2_sem\well_wisher_inno_bot\venv\lib\site-packages\aiohttp\connector.py", line 540, in connect
    proto = await self._create_connection(req, traces, timeout)
  File "C:\Users\milan\OneDrive\Документы\Innopolis_studying\1_year\2_sem\well_wisher_inno_bot\venv\lib\site-packages\aiohttp\connector.py", line 901, in _create_connection
    _, proto = await self._create_direct_connection(req, traces, timeout)
  File "C:\Users\milan\OneDrive\Документы\Innopolis_studying\1_year\2_sem\well_wisher_inno_bot\venv\lib\site-packages\aiohttp\connector.py", line 1166, in _create_direct_connection
    raise ClientConnectorError(req.connection_key, exc) from exc
aiohttp.client_exceptions.ClientConnectorError: Cannot connect to host api.telegram.org:443 ssl:default [getaddrinfo failed]

During handling of the above exception, another exception occurred:

Traceback (most recent call last):
  File "C:\Users\milan\OneDrive\Документы\Innopolis_studying\1_year\2_sem\well_wisher_inno_bot\venv\lib\site-packages\aiogram\dispatcher\dispatcher.py", line 381, in start_polling
    updates = await self.bot.get_updates(
  File "C:\Users\milan\OneDrive\Документы\Innopolis_studying\1_year\2_sem\well_wisher_inno_bot\venv\lib\site-packages\aiogram\bot\bot.py", line 110, in get_updates
    result = await self.request(api.Methods.GET_UPDATES, payload)
  File "C:\Users\milan\OneDrive\Документы\Innopolis_studying\1_year\2_sem\well_wisher_inno_bot\venv\lib\site-packages\aiogram\bot\base.py", line 236, in request
    return await api.make_request(await self.get_session(), self.server, self.__token, method, data, files,
  File "C:\Users\milan\OneDrive\Документы\Innopolis_studying\1_year\2_sem\well_wisher_inno_bot\venv\lib\site-packages\aiogram\bot\api.py", line 142, in make_request
    raise exceptions.NetworkError(f"aiohttp client throws an error: {e.__class__.__name__}: {e}")
aiogram.utils.exceptions.NetworkError: Aiohttp client throws an error: ClientConnectorError: Cannot connect to host api.telegram.org:443 ssl:default [getaddrinfo failed]
17:59:14 aiogram.dispatcher.dispatcher ERROR Cause exception while getting updates.
Traceback (most recent call last):
  File "C:\Users\milan\OneDrive\Документы\Innopolis_studying\1_year\2_sem\well_wisher_inno_bot\venv\lib\site-packages\aiohttp\connector.py", line 1152, in _create_direct_connection
    hosts = await asyncio.shield(host_resolved)
  File "C:\Users\milan\OneDrive\Документы\Innopolis_studying\1_year\2_sem\well_wisher_inno_bot\venv\lib\site-packages\aiohttp\connector.py", line 874, in _resolve_host
    addrs = await self._resolver.resolve(host, port, family=self._family)
  File "C:\Users\milan\OneDrive\Документы\Innopolis_studying\1_year\2_sem\well_wisher_inno_bot\venv\lib\site-packages\aiohttp\resolver.py", line 33, in resolve
    infos = await self._loop.getaddrinfo(
  File "C:\Users\milan\AppData\Local\Programs\Python\Python310\lib\asyncio\base_events.py", line 860, in getaddrinfo
    return await self.run_in_executor(
  File "C:\Users\milan\AppData\Local\Programs\Python\Python310\lib\concurrent\futures\thread.py", line 58, in run
    result = self.fn(*self.args, **self.kwargs)
  File "C:\Users\milan\AppData\Local\Programs\Python\Python310\lib\socket.py", line 955, in getaddrinfo
    for res in _socket.getaddrinfo(host, port, family, type, proto, flags):
socket.gaierror: [Errno 11004] getaddrinfo failed

The above exception was the direct cause of the following exception:

Traceback (most recent call last):
  File "C:\Users\milan\OneDrive\Документы\Innopolis_studying\1_year\2_sem\well_wisher_inno_bot\venv\lib\site-packages\aiogram\bot\api.py", line 139, in make_request
    async with session.post(url, data=req, **kwargs) as response:
  File "C:\Users\milan\OneDrive\Документы\Innopolis_studying\1_year\2_sem\well_wisher_inno_bot\venv\lib\site-packages\aiohttp\client.py", line 1141, in __aenter__
    self._resp = await self._coro
  File "C:\Users\milan\OneDrive\Документы\Innopolis_studying\1_year\2_sem\well_wisher_inno_bot\venv\lib\site-packages\aiohttp\client.py", line 536, in _request
    conn = await self._connector.connect(
  File "C:\Users\milan\OneDrive\Документы\Innopolis_studying\1_year\2_sem\well_wisher_inno_bot\venv\lib\site-packages\aiohttp\connector.py", line 540, in connect
    proto = await self._create_connection(req, traces, timeout)
  File "C:\Users\milan\OneDrive\Документы\Innopolis_studying\1_year\2_sem\well_wisher_inno_bot\venv\lib\site-packages\aiohttp\connector.py", line 901, in _create_connection
    _, proto = await self._create_direct_connection(req, traces, timeout)
  File "C:\Users\milan\OneDrive\Документы\Innopolis_studying\1_year\2_sem\well_wisher_inno_bot\venv\lib\site-packages\aiohttp\connector.py", line 1166, in _create_direct_connection
    raise ClientConnectorError(req.connection_key, exc) from exc
aiohttp.client_exceptions.ClientConnectorError: Cannot connect to host api.telegram.org:443 ssl:default [getaddrinfo failed]

During handling of the above exception, another exception occurred:

Traceback (most recent call last):
  File "C:\Users\milan\OneDrive\Документы\Innopolis_studying\1_year\2_sem\well_wisher_inno_bot\venv\lib\site-packages\aiogram\dispatcher\dispatcher.py", line 381, in start_polling
    updates = await self.bot.get_updates(
  File "C:\Users\milan\OneDrive\Документы\Innopolis_studying\1_year\2_sem\well_wisher_inno_bot\venv\lib\site-packages\aiogram\bot\bot.py", line 110, in get_updates
    result = await self.request(api.Methods.GET_UPDATES, payload)
  File "C:\Users\milan\OneDrive\Документы\Innopolis_studying\1_year\2_sem\well_wisher_inno_bot\venv\lib\site-packages\aiogram\bot\base.py", line 236, in request
    return await api.make_request(await self.get_session(), self.server, self.__token, method, data, files,
  File "C:\Users\milan\OneDrive\Документы\Innopolis_studying\1_year\2_sem\well_wisher_inno_bot\venv\lib\site-packages\aiogram\bot\api.py", line 142, in make_request
    raise exceptions.NetworkError(f"aiohttp client throws an error: {e.__class__.__name__}: {e}")
aiogram.utils.exceptions.NetworkError: Aiohttp client throws an error: ClientConnectorError: Cannot connect to host api.telegram.org:443 ssl:default [getaddrinfo failed]
17:59:19 aiogram.dispatcher.dispatcher ERROR Cause exception while getting updates.
Traceback (most recent call last):
  File "C:\Users\milan\OneDrive\Документы\Innopolis_studying\1_year\2_sem\well_wisher_inno_bot\venv\lib\site-packages\aiohttp\connector.py", line 1152, in _create_direct_connection
    hosts = await asyncio.shield(host_resolved)
  File "C:\Users\milan\OneDrive\Документы\Innopolis_studying\1_year\2_sem\well_wisher_inno_bot\venv\lib\site-packages\aiohttp\connector.py", line 874, in _resolve_host
    addrs = await self._resolver.resolve(host, port, family=self._family)
  File "C:\Users\milan\OneDrive\Документы\Innopolis_studying\1_year\2_sem\well_wisher_inno_bot\venv\lib\site-packages\aiohttp\resolver.py", line 33, in resolve
    infos = await self._loop.getaddrinfo(
  File "C:\Users\milan\AppData\Local\Programs\Python\Python310\lib\asyncio\base_events.py", line 860, in getaddrinfo
    return await self.run_in_executor(
  File "C:\Users\milan\AppData\Local\Programs\Python\Python310\lib\concurrent\futures\thread.py", line 58, in run
    result = self.fn(*self.args, **self.kwargs)
  File "C:\Users\milan\AppData\Local\Programs\Python\Python310\lib\socket.py", line 955, in getaddrinfo
    for res in _socket.getaddrinfo(host, port, family, type, proto, flags):
socket.gaierror: [Errno 11004] getaddrinfo failed

The above exception was the direct cause of the following exception:

Traceback (most recent call last):
  File "C:\Users\milan\OneDrive\Документы\Innopolis_studying\1_year\2_sem\well_wisher_inno_bot\venv\lib\site-packages\aiogram\bot\api.py", line 139, in make_request
    async with session.post(url, data=req, **kwargs) as response:
  File "C:\Users\milan\OneDrive\Документы\Innopolis_studying\1_year\2_sem\well_wisher_inno_bot\venv\lib\site-packages\aiohttp\client.py", line 1141, in __aenter__
    self._resp = await self._coro
  File "C:\Users\milan\OneDrive\Документы\Innopolis_studying\1_year\2_sem\well_wisher_inno_bot\venv\lib\site-packages\aiohttp\client.py", line 536, in _request
    conn = await self._connector.connect(
  File "C:\Users\milan\OneDrive\Документы\Innopolis_studying\1_year\2_sem\well_wisher_inno_bot\venv\lib\site-packages\aiohttp\connector.py", line 540, in connect
    proto = await self._create_connection(req, traces, timeout)
  File "C:\Users\milan\OneDrive\Документы\Innopolis_studying\1_year\2_sem\well_wisher_inno_bot\venv\lib\site-packages\aiohttp\connector.py", line 901, in _create_connection
    _, proto = await self._create_direct_connection(req, traces, timeout)
  File "C:\Users\milan\OneDrive\Документы\Innopolis_studying\1_year\2_sem\well_wisher_inno_bot\venv\lib\site-packages\aiohttp\connector.py", line 1166, in _create_direct_connection
    raise ClientConnectorError(req.connection_key, exc) from exc
aiohttp.client_exceptions.ClientConnectorError: Cannot connect to host api.telegram.org:443 ssl:default [getaddrinfo failed]

During handling of the above exception, another exception occurred:

Traceback (most recent call last):
  File "C:\Users\milan\OneDrive\Документы\Innopolis_studying\1_year\2_sem\well_wisher_inno_bot\venv\lib\site-packages\aiogram\dispatcher\dispatcher.py", line 381, in start_polling
    updates = await self.bot.get_updates(
  File "C:\Users\milan\OneDrive\Документы\Innopolis_studying\1_year\2_sem\well_wisher_inno_bot\venv\lib\site-packages\aiogram\bot\bot.py", line 110, in get_updates
    result = await self.request(api.Methods.GET_UPDATES, payload)
  File "C:\Users\milan\OneDrive\Документы\Innopolis_studying\1_year\2_sem\well_wisher_inno_bot\venv\lib\site-packages\aiogram\bot\base.py", line 236, in request
    return await api.make_request(await self.get_session(), self.server, self.__token, method, data, files,
  File "C:\Users\milan\OneDrive\Документы\Innopolis_studying\1_year\2_sem\well_wisher_inno_bot\venv\lib\site-packages\aiogram\bot\api.py", line 142, in make_request
    raise exceptions.NetworkError(f"aiohttp client throws an error: {e.__class__.__name__}: {e}")
aiogram.utils.exceptions.NetworkError: Aiohttp client throws an error: ClientConnectorError: Cannot connect to host api.telegram.org:443 ssl:default [getaddrinfo failed]
17:59:24 aiogram.dispatcher.dispatcher ERROR Cause exception while getting updates.
Traceback (most recent call last):
  File "C:\Users\milan\OneDrive\Документы\Innopolis_studying\1_year\2_sem\well_wisher_inno_bot\venv\lib\site-packages\aiohttp\connector.py", line 1152, in _create_direct_connection
    hosts = await asyncio.shield(host_resolved)
  File "C:\Users\milan\OneDrive\Документы\Innopolis_studying\1_year\2_sem\well_wisher_inno_bot\venv\lib\site-packages\aiohttp\connector.py", line 874, in _resolve_host
    addrs = await self._resolver.resolve(host, port, family=self._family)
  File "C:\Users\milan\OneDrive\Документы\Innopolis_studying\1_year\2_sem\well_wisher_inno_bot\venv\lib\site-packages\aiohttp\resolver.py", line 33, in resolve
    infos = await self._loop.getaddrinfo(
  File "C:\Users\milan\AppData\Local\Programs\Python\Python310\lib\asyncio\base_events.py", line 860, in getaddrinfo
    return await self.run_in_executor(
  File "C:\Users\milan\AppData\Local\Programs\Python\Python310\lib\concurrent\futures\thread.py", line 58, in run
    result = self.fn(*self.args, **self.kwargs)
  File "C:\Users\milan\AppData\Local\Programs\Python\Python310\lib\socket.py", line 955, in getaddrinfo
    for res in _socket.getaddrinfo(host, port, family, type, proto, flags):
socket.gaierror: [Errno 11004] getaddrinfo failed

The above exception was the direct cause of the following exception:

Traceback (most recent call last):
  File "C:\Users\milan\OneDrive\Документы\Innopolis_studying\1_year\2_sem\well_wisher_inno_bot\venv\lib\site-packages\aiogram\bot\api.py", line 139, in make_request
    async with session.post(url, data=req, **kwargs) as response:
  File "C:\Users\milan\OneDrive\Документы\Innopolis_studying\1_year\2_sem\well_wisher_inno_bot\venv\lib\site-packages\aiohttp\client.py", line 1141, in __aenter__
    self._resp = await self._coro
  File "C:\Users\milan\OneDrive\Документы\Innopolis_studying\1_year\2_sem\well_wisher_inno_bot\venv\lib\site-packages\aiohttp\client.py", line 536, in _request
    conn = await self._connector.connect(
  File "C:\Users\milan\OneDrive\Документы\Innopolis_studying\1_year\2_sem\well_wisher_inno_bot\venv\lib\site-packages\aiohttp\connector.py", line 540, in connect
    proto = await self._create_connection(req, traces, timeout)
  File "C:\Users\milan\OneDrive\Документы\Innopolis_studying\1_year\2_sem\well_wisher_inno_bot\venv\lib\site-packages\aiohttp\connector.py", line 901, in _create_connection
    _, proto = await self._create_direct_connection(req, traces, timeout)
  File "C:\Users\milan\OneDrive\Документы\Innopolis_studying\1_year\2_sem\well_wisher_inno_bot\venv\lib\site-packages\aiohttp\connector.py", line 1166, in _create_direct_connection
    raise ClientConnectorError(req.connection_key, exc) from exc
aiohttp.client_exceptions.ClientConnectorError: Cannot connect to host api.telegram.org:443 ssl:default [getaddrinfo failed]

During handling of the above exception, another exception occurred:

Traceback (most recent call last):
  File "C:\Users\milan\OneDrive\Документы\Innopolis_studying\1_year\2_sem\well_wisher_inno_bot\venv\lib\site-packages\aiogram\dispatcher\dispatcher.py", line 381, in start_polling
    updates = await self.bot.get_updates(
  File "C:\Users\milan\OneDrive\Документы\Innopolis_studying\1_year\2_sem\well_wisher_inno_bot\venv\lib\site-packages\aiogram\bot\bot.py", line 110, in get_updates
    result = await self.request(api.Methods.GET_UPDATES, payload)
  File "C:\Users\milan\OneDrive\Документы\Innopolis_studying\1_year\2_sem\well_wisher_inno_bot\venv\lib\site-packages\aiogram\bot\base.py", line 236, in request
    return await api.make_request(await self.get_session(), self.server, self.__token, method, data, files,
  File "C:\Users\milan\OneDrive\Документы\Innopolis_studying\1_year\2_sem\well_wisher_inno_bot\venv\lib\site-packages\aiogram\bot\api.py", line 142, in make_request
    raise exceptions.NetworkError(f"aiohttp client throws an error: {e.__class__.__name__}: {e}")
aiogram.utils.exceptions.NetworkError: Aiohttp client throws an error: ClientConnectorError: Cannot connect to host api.telegram.org:443 ssl:default [getaddrinfo failed]
17:59:29 aiogram.dispatcher.dispatcher ERROR Cause exception while getting updates.
Traceback (most recent call last):
  File "C:\Users\milan\OneDrive\Документы\Innopolis_studying\1_year\2_sem\well_wisher_inno_bot\venv\lib\site-packages\aiohttp\connector.py", line 1152, in _create_direct_connection
    hosts = await asyncio.shield(host_resolved)
  File "C:\Users\milan\OneDrive\Документы\Innopolis_studying\1_year\2_sem\well_wisher_inno_bot\venv\lib\site-packages\aiohttp\connector.py", line 874, in _resolve_host
    addrs = await self._resolver.resolve(host, port, family=self._family)
  File "C:\Users\milan\OneDrive\Документы\Innopolis_studying\1_year\2_sem\well_wisher_inno_bot\venv\lib\site-packages\aiohttp\resolver.py", line 33, in resolve
    infos = await self._loop.getaddrinfo(
  File "C:\Users\milan\AppData\Local\Programs\Python\Python310\lib\asyncio\base_events.py", line 860, in getaddrinfo
    return await self.run_in_executor(
  File "C:\Users\milan\AppData\Local\Programs\Python\Python310\lib\concurrent\futures\thread.py", line 58, in run
    result = self.fn(*self.args, **self.kwargs)
  File "C:\Users\milan\AppData\Local\Programs\Python\Python310\lib\socket.py", line 955, in getaddrinfo
    for res in _socket.getaddrinfo(host, port, family, type, proto, flags):
socket.gaierror: [Errno 11004] getaddrinfo failed

The above exception was the direct cause of the following exception:

Traceback (most recent call last):
  File "C:\Users\milan\OneDrive\Документы\Innopolis_studying\1_year\2_sem\well_wisher_inno_bot\venv\lib\site-packages\aiogram\bot\api.py", line 139, in make_request
    async with session.post(url, data=req, **kwargs) as response:
  File "C:\Users\milan\OneDrive\Документы\Innopolis_studying\1_year\2_sem\well_wisher_inno_bot\venv\lib\site-packages\aiohttp\client.py", line 1141, in __aenter__
    self._resp = await self._coro
  File "C:\Users\milan\OneDrive\Документы\Innopolis_studying\1_year\2_sem\well_wisher_inno_bot\venv\lib\site-packages\aiohttp\client.py", line 536, in _request
    conn = await self._connector.connect(
  File "C:\Users\milan\OneDrive\Документы\Innopolis_studying\1_year\2_sem\well_wisher_inno_bot\venv\lib\site-packages\aiohttp\connector.py", line 540, in connect
    proto = await self._create_connection(req, traces, timeout)
  File "C:\Users\milan\OneDrive\Документы\Innopolis_studying\1_year\2_sem\well_wisher_inno_bot\venv\lib\site-packages\aiohttp\connector.py", line 901, in _create_connection
    _, proto = await self._create_direct_connection(req, traces, timeout)
  File "C:\Users\milan\OneDrive\Документы\Innopolis_studying\1_year\2_sem\well_wisher_inno_bot\venv\lib\site-packages\aiohttp\connector.py", line 1166, in _create_direct_connection
    raise ClientConnectorError(req.connection_key, exc) from exc
aiohttp.client_exceptions.ClientConnectorError: Cannot connect to host api.telegram.org:443 ssl:default [getaddrinfo failed]

During handling of the above exception, another exception occurred:

Traceback (most recent call last):
  File "C:\Users\milan\OneDrive\Документы\Innopolis_studying\1_year\2_sem\well_wisher_inno_bot\venv\lib\site-packages\aiogram\dispatcher\dispatcher.py", line 381, in start_polling
    updates = await self.bot.get_updates(
  File "C:\Users\milan\OneDrive\Документы\Innopolis_studying\1_year\2_sem\well_wisher_inno_bot\venv\lib\site-packages\aiogram\bot\bot.py", line 110, in get_updates
    result = await self.request(api.Methods.GET_UPDATES, payload)
  File "C:\Users\milan\OneDrive\Документы\Innopolis_studying\1_year\2_sem\well_wisher_inno_bot\venv\lib\site-packages\aiogram\bot\base.py", line 236, in request
    return await api.make_request(await self.get_session(), self.server, self.__token, method, data, files,
  File "C:\Users\milan\OneDrive\Документы\Innopolis_studying\1_year\2_sem\well_wisher_inno_bot\venv\lib\site-packages\aiogram\bot\api.py", line 142, in make_request
    raise exceptions.NetworkError(f"aiohttp client throws an error: {e.__class__.__name__}: {e}")
aiogram.utils.exceptions.NetworkError: Aiohttp client throws an error: ClientConnectorError: Cannot connect to host api.telegram.org:443 ssl:default [getaddrinfo failed]
17:59:34 aiogram.dispatcher.dispatcher ERROR Cause exception while getting updates.
Traceback (most recent call last):
  File "C:\Users\milan\OneDrive\Документы\Innopolis_studying\1_year\2_sem\well_wisher_inno_bot\venv\lib\site-packages\aiohttp\connector.py", line 1152, in _create_direct_connection
    hosts = await asyncio.shield(host_resolved)
  File "C:\Users\milan\OneDrive\Документы\Innopolis_studying\1_year\2_sem\well_wisher_inno_bot\venv\lib\site-packages\aiohttp\connector.py", line 874, in _resolve_host
    addrs = await self._resolver.resolve(host, port, family=self._family)
  File "C:\Users\milan\OneDrive\Документы\Innopolis_studying\1_year\2_sem\well_wisher_inno_bot\venv\lib\site-packages\aiohttp\resolver.py", line 33, in resolve
    infos = await self._loop.getaddrinfo(
  File "C:\Users\milan\AppData\Local\Programs\Python\Python310\lib\asyncio\base_events.py", line 860, in getaddrinfo
    return await self.run_in_executor(
  File "C:\Users\milan\AppData\Local\Programs\Python\Python310\lib\concurrent\futures\thread.py", line 58, in run
    result = self.fn(*self.args, **self.kwargs)
  File "C:\Users\milan\AppData\Local\Programs\Python\Python310\lib\socket.py", line 955, in getaddrinfo
    for res in _socket.getaddrinfo(host, port, family, type, proto, flags):
socket.gaierror: [Errno 11004] getaddrinfo failed

The above exception was the direct cause of the following exception:

Traceback (most recent call last):
  File "C:\Users\milan\OneDrive\Документы\Innopolis_studying\1_year\2_sem\well_wisher_inno_bot\venv\lib\site-packages\aiogram\bot\api.py", line 139, in make_request
    async with session.post(url, data=req, **kwargs) as response:
  File "C:\Users\milan\OneDrive\Документы\Innopolis_studying\1_year\2_sem\well_wisher_inno_bot\venv\lib\site-packages\aiohttp\client.py", line 1141, in __aenter__
    self._resp = await self._coro
  File "C:\Users\milan\OneDrive\Документы\Innopolis_studying\1_year\2_sem\well_wisher_inno_bot\venv\lib\site-packages\aiohttp\client.py", line 536, in _request
    conn = await self._connector.connect(
  File "C:\Users\milan\OneDrive\Документы\Innopolis_studying\1_year\2_sem\well_wisher_inno_bot\venv\lib\site-packages\aiohttp\connector.py", line 540, in connect
    proto = await self._create_connection(req, traces, timeout)
  File "C:\Users\milan\OneDrive\Документы\Innopolis_studying\1_year\2_sem\well_wisher_inno_bot\venv\lib\site-packages\aiohttp\connector.py", line 901, in _create_connection
    _, proto = await self._create_direct_connection(req, traces, timeout)
  File "C:\Users\milan\OneDrive\Документы\Innopolis_studying\1_year\2_sem\well_wisher_inno_bot\venv\lib\site-packages\aiohttp\connector.py", line 1166, in _create_direct_connection
    raise ClientConnectorError(req.connection_key, exc) from exc
aiohttp.client_exceptions.ClientConnectorError: Cannot connect to host api.telegram.org:443 ssl:default [getaddrinfo failed]

During handling of the above exception, another exception occurred:

Traceback (most recent call last):
  File "C:\Users\milan\OneDrive\Документы\Innopolis_studying\1_year\2_sem\well_wisher_inno_bot\venv\lib\site-packages\aiogram\dispatcher\dispatcher.py", line 381, in start_polling
    updates = await self.bot.get_updates(
  File "C:\Users\milan\OneDrive\Документы\Innopolis_studying\1_year\2_sem\well_wisher_inno_bot\venv\lib\site-packages\aiogram\bot\bot.py", line 110, in get_updates
    result = await self.request(api.Methods.GET_UPDATES, payload)
  File "C:\Users\milan\OneDrive\Документы\Innopolis_studying\1_year\2_sem\well_wisher_inno_bot\venv\lib\site-packages\aiogram\bot\base.py", line 236, in request
    return await api.make_request(await self.get_session(), self.server, self.__token, method, data, files,
  File "C:\Users\milan\OneDrive\Документы\Innopolis_studying\1_year\2_sem\well_wisher_inno_bot\venv\lib\site-packages\aiogram\bot\api.py", line 142, in make_request
    raise exceptions.NetworkError(f"aiohttp client throws an error: {e.__class__.__name__}: {e}")
aiogram.utils.exceptions.NetworkError: Aiohttp client throws an error: ClientConnectorError: Cannot connect to host api.telegram.org:443 ssl:default [getaddrinfo failed]
17:59:39 aiogram.dispatcher.dispatcher ERROR Cause exception while getting updates.
Traceback (most recent call last):
  File "C:\Users\milan\OneDrive\Документы\Innopolis_studying\1_year\2_sem\well_wisher_inno_bot\venv\lib\site-packages\aiohttp\connector.py", line 1152, in _create_direct_connection
    hosts = await asyncio.shield(host_resolved)
  File "C:\Users\milan\OneDrive\Документы\Innopolis_studying\1_year\2_sem\well_wisher_inno_bot\venv\lib\site-packages\aiohttp\connector.py", line 874, in _resolve_host
    addrs = await self._resolver.resolve(host, port, family=self._family)
  File "C:\Users\milan\OneDrive\Документы\Innopolis_studying\1_year\2_sem\well_wisher_inno_bot\venv\lib\site-packages\aiohttp\resolver.py", line 33, in resolve
    infos = await self._loop.getaddrinfo(
  File "C:\Users\milan\AppData\Local\Programs\Python\Python310\lib\asyncio\base_events.py", line 860, in getaddrinfo
    return await self.run_in_executor(
  File "C:\Users\milan\AppData\Local\Programs\Python\Python310\lib\concurrent\futures\thread.py", line 58, in run
    result = self.fn(*self.args, **self.kwargs)
  File "C:\Users\milan\AppData\Local\Programs\Python\Python310\lib\socket.py", line 955, in getaddrinfo
    for res in _socket.getaddrinfo(host, port, family, type, proto, flags):
socket.gaierror: [Errno 11004] getaddrinfo failed

The above exception was the direct cause of the following exception:

Traceback (most recent call last):
  File "C:\Users\milan\OneDrive\Документы\Innopolis_studying\1_year\2_sem\well_wisher_inno_bot\venv\lib\site-packages\aiogram\bot\api.py", line 139, in make_request
    async with session.post(url, data=req, **kwargs) as response:
  File "C:\Users\milan\OneDrive\Документы\Innopolis_studying\1_year\2_sem\well_wisher_inno_bot\venv\lib\site-packages\aiohttp\client.py", line 1141, in __aenter__
    self._resp = await self._coro
  File "C:\Users\milan\OneDrive\Документы\Innopolis_studying\1_year\2_sem\well_wisher_inno_bot\venv\lib\site-packages\aiohttp\client.py", line 536, in _request
    conn = await self._connector.connect(
  File "C:\Users\milan\OneDrive\Документы\Innopolis_studying\1_year\2_sem\well_wisher_inno_bot\venv\lib\site-packages\aiohttp\connector.py", line 540, in connect
    proto = await self._create_connection(req, traces, timeout)
  File "C:\Users\milan\OneDrive\Документы\Innopolis_studying\1_year\2_sem\well_wisher_inno_bot\venv\lib\site-packages\aiohttp\connector.py", line 901, in _create_connection
    _, proto = await self._create_direct_connection(req, traces, timeout)
  File "C:\Users\milan\OneDrive\Документы\Innopolis_studying\1_year\2_sem\well_wisher_inno_bot\venv\lib\site-packages\aiohttp\connector.py", line 1166, in _create_direct_connection
    raise ClientConnectorError(req.connection_key, exc) from exc
aiohttp.client_exceptions.ClientConnectorError: Cannot connect to host api.telegram.org:443 ssl:default [getaddrinfo failed]

During handling of the above exception, another exception occurred:

Traceback (most recent call last):
  File "C:\Users\milan\OneDrive\Документы\Innopolis_studying\1_year\2_sem\well_wisher_inno_bot\venv\lib\site-packages\aiogram\dispatcher\dispatcher.py", line 381, in start_polling
    updates = await self.bot.get_updates(
  File "C:\Users\milan\OneDrive\Документы\Innopolis_studying\1_year\2_sem\well_wisher_inno_bot\venv\lib\site-packages\aiogram\bot\bot.py", line 110, in get_updates
    result = await self.request(api.Methods.GET_UPDATES, payload)
  File "C:\Users\milan\OneDrive\Документы\Innopolis_studying\1_year\2_sem\well_wisher_inno_bot\venv\lib\site-packages\aiogram\bot\base.py", line 236, in request
    return await api.make_request(await self.get_session(), self.server, self.__token, method, data, files,
  File "C:\Users\milan\OneDrive\Документы\Innopolis_studying\1_year\2_sem\well_wisher_inno_bot\venv\lib\site-packages\aiogram\bot\api.py", line 142, in make_request
    raise exceptions.NetworkError(f"aiohttp client throws an error: {e.__class__.__name__}: {e}")
aiogram.utils.exceptions.NetworkError: Aiohttp client throws an error: ClientConnectorError: Cannot connect to host api.telegram.org:443 ssl:default [getaddrinfo failed]
19:51:40 aiogram.dispatcher.dispatcher ERROR Cause exception while getting updates.
Traceback (most recent call last):
  File "C:\Users\milan\OneDrive\Документы\Innopolis_studying\1_year\2_sem\well_wisher_inno_bot\venv\lib\site-packages\aiogram\dispatcher\dispatcher.py", line 381, in start_polling
    updates = await self.bot.get_updates(
  File "C:\Users\milan\OneDrive\Документы\Innopolis_studying\1_year\2_sem\well_wisher_inno_bot\venv\lib\site-packages\aiogram\bot\bot.py", line 110, in get_updates
    result = await self.request(api.Methods.GET_UPDATES, payload)
  File "C:\Users\milan\OneDrive\Документы\Innopolis_studying\1_year\2_sem\well_wisher_inno_bot\venv\lib\site-packages\aiogram\bot\base.py", line 236, in request
    return await api.make_request(await self.get_session(), self.server, self.__token, method, data, files,
  File "C:\Users\milan\OneDrive\Документы\Innopolis_studying\1_year\2_sem\well_wisher_inno_bot\venv\lib\site-packages\aiogram\bot\api.py", line 139, in make_request
    async with session.post(url, data=req, **kwargs) as response:
  File "C:\Users\milan\OneDrive\Документы\Innopolis_studying\1_year\2_sem\well_wisher_inno_bot\venv\lib\site-packages\aiohttp\client.py", line 1141, in __aenter__
    self._resp = await self._coro
  File "C:\Users\milan\OneDrive\Документы\Innopolis_studying\1_year\2_sem\well_wisher_inno_bot\venv\lib\site-packages\aiohttp\client.py", line 560, in _request
    await resp.start(conn)
  File "C:\Users\milan\OneDrive\Документы\Innopolis_studying\1_year\2_sem\well_wisher_inno_bot\venv\lib\site-packages\aiohttp\client_reqrep.py", line 894, in start
    with self._timer:
  File "C:\Users\milan\OneDrive\Документы\Innopolis_studying\1_year\2_sem\well_wisher_inno_bot\venv\lib\site-packages\aiohttp\helpers.py", line 721, in __exit__
    raise asyncio.TimeoutError from None
asyncio.exceptions.TimeoutError
19:51:56 aiogram.dispatcher.dispatcher ERROR Cause exception while getting updates.
Traceback (most recent call last):
  File "C:\Users\milan\OneDrive\Документы\Innopolis_studying\1_year\2_sem\well_wisher_inno_bot\venv\lib\site-packages\aiohttp\connector.py", line 1152, in _create_direct_connection
    hosts = await asyncio.shield(host_resolved)
  File "C:\Users\milan\OneDrive\Документы\Innopolis_studying\1_year\2_sem\well_wisher_inno_bot\venv\lib\site-packages\aiohttp\connector.py", line 874, in _resolve_host
    addrs = await self._resolver.resolve(host, port, family=self._family)
  File "C:\Users\milan\OneDrive\Документы\Innopolis_studying\1_year\2_sem\well_wisher_inno_bot\venv\lib\site-packages\aiohttp\resolver.py", line 33, in resolve
    infos = await self._loop.getaddrinfo(
  File "C:\Users\milan\AppData\Local\Programs\Python\Python310\lib\asyncio\base_events.py", line 860, in getaddrinfo
    return await self.run_in_executor(
  File "C:\Users\milan\AppData\Local\Programs\Python\Python310\lib\concurrent\futures\thread.py", line 58, in run
    result = self.fn(*self.args, **self.kwargs)
  File "C:\Users\milan\AppData\Local\Programs\Python\Python310\lib\socket.py", line 955, in getaddrinfo
    for res in _socket.getaddrinfo(host, port, family, type, proto, flags):
socket.gaierror: [Errno 11001] getaddrinfo failed

The above exception was the direct cause of the following exception:

Traceback (most recent call last):
  File "C:\Users\milan\OneDrive\Документы\Innopolis_studying\1_year\2_sem\well_wisher_inno_bot\venv\lib\site-packages\aiogram\bot\api.py", line 139, in make_request
    async with session.post(url, data=req, **kwargs) as response:
  File "C:\Users\milan\OneDrive\Документы\Innopolis_studying\1_year\2_sem\well_wisher_inno_bot\venv\lib\site-packages\aiohttp\client.py", line 1141, in __aenter__
    self._resp = await self._coro
  File "C:\Users\milan\OneDrive\Документы\Innopolis_studying\1_year\2_sem\well_wisher_inno_bot\venv\lib\site-packages\aiohttp\client.py", line 536, in _request
    conn = await self._connector.connect(
  File "C:\Users\milan\OneDrive\Документы\Innopolis_studying\1_year\2_sem\well_wisher_inno_bot\venv\lib\site-packages\aiohttp\connector.py", line 540, in connect
    proto = await self._create_connection(req, traces, timeout)
  File "C:\Users\milan\OneDrive\Документы\Innopolis_studying\1_year\2_sem\well_wisher_inno_bot\venv\lib\site-packages\aiohttp\connector.py", line 901, in _create_connection
    _, proto = await self._create_direct_connection(req, traces, timeout)
  File "C:\Users\milan\OneDrive\Документы\Innopolis_studying\1_year\2_sem\well_wisher_inno_bot\venv\lib\site-packages\aiohttp\connector.py", line 1166, in _create_direct_connection
    raise ClientConnectorError(req.connection_key, exc) from exc
aiohttp.client_exceptions.ClientConnectorError: Cannot connect to host api.telegram.org:443 ssl:default [getaddrinfo failed]

During handling of the above exception, another exception occurred:

Traceback (most recent call last):
  File "C:\Users\milan\OneDrive\Документы\Innopolis_studying\1_year\2_sem\well_wisher_inno_bot\venv\lib\site-packages\aiogram\dispatcher\dispatcher.py", line 381, in start_polling
    updates = await self.bot.get_updates(
  File "C:\Users\milan\OneDrive\Документы\Innopolis_studying\1_year\2_sem\well_wisher_inno_bot\venv\lib\site-packages\aiogram\bot\bot.py", line 110, in get_updates
    result = await self.request(api.Methods.GET_UPDATES, payload)
  File "C:\Users\milan\OneDrive\Документы\Innopolis_studying\1_year\2_sem\well_wisher_inno_bot\venv\lib\site-packages\aiogram\bot\base.py", line 236, in request
    return await api.make_request(await self.get_session(), self.server, self.__token, method, data, files,
  File "C:\Users\milan\OneDrive\Документы\Innopolis_studying\1_year\2_sem\well_wisher_inno_bot\venv\lib\site-packages\aiogram\bot\api.py", line 142, in make_request
    raise exceptions.NetworkError(f"aiohttp client throws an error: {e.__class__.__name__}: {e}")
aiogram.utils.exceptions.NetworkError: Aiohttp client throws an error: ClientConnectorError: Cannot connect to host api.telegram.org:443 ssl:default [getaddrinfo failed]
21:27:13 aiogram.dispatcher.dispatcher ERROR Cause exception while getting updates.
Traceback (most recent call last):
  File "C:\Users\milan\OneDrive\Документы\Innopolis_studying\1_year\2_sem\well_wisher_inno_bot\venv\lib\site-packages\aiogram\dispatcher\dispatcher.py", line 381, in start_polling
    updates = await self.bot.get_updates(
  File "C:\Users\milan\OneDrive\Документы\Innopolis_studying\1_year\2_sem\well_wisher_inno_bot\venv\lib\site-packages\aiogram\bot\bot.py", line 110, in get_updates
    result = await self.request(api.Methods.GET_UPDATES, payload)
  File "C:\Users\milan\OneDrive\Документы\Innopolis_studying\1_year\2_sem\well_wisher_inno_bot\venv\lib\site-packages\aiogram\bot\base.py", line 236, in request
    return await api.make_request(await self.get_session(), self.server, self.__token, method, data, files,
  File "C:\Users\milan\OneDrive\Документы\Innopolis_studying\1_year\2_sem\well_wisher_inno_bot\venv\lib\site-packages\aiogram\bot\api.py", line 139, in make_request
    async with session.post(url, data=req, **kwargs) as response:
  File "C:\Users\milan\OneDrive\Документы\Innopolis_studying\1_year\2_sem\well_wisher_inno_bot\venv\lib\site-packages\aiohttp\client.py", line 1141, in __aenter__
    self._resp = await self._coro
  File "C:\Users\milan\OneDrive\Документы\Innopolis_studying\1_year\2_sem\well_wisher_inno_bot\venv\lib\site-packages\aiohttp\client.py", line 560, in _request
    await resp.start(conn)
  File "C:\Users\milan\OneDrive\Документы\Innopolis_studying\1_year\2_sem\well_wisher_inno_bot\venv\lib\site-packages\aiohttp\client_reqrep.py", line 894, in start
    with self._timer:
  File "C:\Users\milan\OneDrive\Документы\Innopolis_studying\1_year\2_sem\well_wisher_inno_bot\venv\lib\site-packages\aiohttp\helpers.py", line 721, in __exit__
    raise asyncio.TimeoutError from None
asyncio.exceptions.TimeoutError
17:27:43 aiogram INFO Bot: Well Wisher Bot [@well_wisher_inno_bot]
17:27:43 aiogram WARNING Updates were skipped successfully.
17:27:43 root INFO Bot is starting...
17:27:44 aiogram.dispatcher.dispatcher INFO Start polling.
17:27:47 aiogram.dispatcher.dispatcher ERROR Cause exception while getting updates.
Traceback (most recent call last):
  File "C:\Users\milan\OneDrive\Документы\Innopolis_studying\1_year\2_sem\well_wisher_inno_bot\venv\lib\site-packages\aiogram\dispatcher\dispatcher.py", line 381, in start_polling
    updates = await self.bot.get_updates(
  File "C:\Users\milan\OneDrive\Документы\Innopolis_studying\1_year\2_sem\well_wisher_inno_bot\venv\lib\site-packages\aiogram\bot\bot.py", line 110, in get_updates
    result = await self.request(api.Methods.GET_UPDATES, payload)
  File "C:\Users\milan\OneDrive\Документы\Innopolis_studying\1_year\2_sem\well_wisher_inno_bot\venv\lib\site-packages\aiogram\bot\base.py", line 236, in request
    return await api.make_request(await self.get_session(), self.server, self.__token, method, data, files,
  File "C:\Users\milan\OneDrive\Документы\Innopolis_studying\1_year\2_sem\well_wisher_inno_bot\venv\lib\site-packages\aiogram\bot\api.py", line 140, in make_request
    return check_result(method, response.content_type, response.status, await response.text())
  File "C:\Users\milan\OneDrive\Документы\Innopolis_studying\1_year\2_sem\well_wisher_inno_bot\venv\lib\site-packages\aiogram\bot\api.py", line 119, in check_result
    exceptions.ConflictError.detect(description)
  File "C:\Users\milan\OneDrive\Документы\Innopolis_studying\1_year\2_sem\well_wisher_inno_bot\venv\lib\site-packages\aiogram\utils\exceptions.py", line 140, in detect
    raise err(cls.text or description)
aiogram.utils.exceptions.TerminatedByOtherGetUpdates: Terminated by other getupdates request; make sure that only one bot instance is running
17:27:54 aiogram.dispatcher.dispatcher INFO Stop polling...
17:27:54 aiogram WARNING Goodbye!
