23:52:46 aiogram INFO Bot: Well Wisher Bot [@well_wisher_inno_bot]
23:52:46 aiogram WARNING Updates were skipped successfully.
23:52:46 root INFO Bot is starting...
23:52:47 aiogram.dispatcher.dispatcher INFO Start polling.
00:17:06 aiogram.dispatcher.dispatcher INFO Stop polling...
00:17:06 aiogram WARNING Goodbye!
00:17:50 aiogram INFO Bot: Well Wisher Bot [@well_wisher_inno_bot]
00:17:50 aiogram WARNING Updates were skipped successfully.
00:17:50 root INFO Bot is starting...
00:17:50 aiogram.dispatcher.dispatcher INFO Start polling.
00:18:17 asyncio ERROR Task exception was never retrieved
future: <Task finished name='Task-11' coro=<Dispatcher._process_polling_updates() done, defined at C:\Users\milan\OneDrive\Документы\Innopolis_studying\1_year\2_sem\well_wisher_inno_bot\venv\lib\site-packages\aiogram\dispatcher\dispatcher.py:407> exception=InterfaceError('(sqlite3.InterfaceError) Error binding parameter 0 - probably unsupported type.')>
Traceback (most recent call last):
  File "C:\Users\milan\OneDrive\Документы\Innopolis_studying\1_year\2_sem\well_wisher_inno_bot\venv\lib\site-packages\sqlalchemy\engine\base.py", line 1965, in _exec_single_context
    self.dialect.do_execute(
  File "C:\Users\milan\OneDrive\Документы\Innopolis_studying\1_year\2_sem\well_wisher_inno_bot\venv\lib\site-packages\sqlalchemy\engine\default.py", line 921, in do_execute
    cursor.execute(statement, parameters)
sqlite3.InterfaceError: Error binding parameter 0 - probably unsupported type.

The above exception was the direct cause of the following exception:

Traceback (most recent call last):
  File "C:\Users\milan\OneDrive\Документы\Innopolis_studying\1_year\2_sem\well_wisher_inno_bot\venv\lib\site-packages\aiogram\dispatcher\dispatcher.py", line 415, in _process_polling_updates
    for responses in itertools.chain.from_iterable(await self.process_updates(updates, fast)):
  File "C:\Users\milan\OneDrive\Документы\Innopolis_studying\1_year\2_sem\well_wisher_inno_bot\venv\lib\site-packages\aiogram\dispatcher\dispatcher.py", line 235, in process_updates
    return await asyncio.gather(*tasks)
  File "C:\Users\milan\OneDrive\Документы\Innopolis_studying\1_year\2_sem\well_wisher_inno_bot\venv\lib\site-packages\aiogram\dispatcher\handler.py", line 117, in notify
    response = await handler_obj.handler(*args, **partial_data)
  File "C:\Users\milan\OneDrive\Документы\Innopolis_studying\1_year\2_sem\well_wisher_inno_bot\venv\lib\site-packages\aiogram\dispatcher\dispatcher.py", line 256, in process_update
    return await self.message_handlers.notify(update.message)
  File "C:\Users\milan\OneDrive\Документы\Innopolis_studying\1_year\2_sem\well_wisher_inno_bot\venv\lib\site-packages\aiogram\dispatcher\handler.py", line 117, in notify
    response = await handler_obj.handler(*args, **partial_data)
  File "C:\Users\milan\OneDrive\Документы\Innopolis_studying\1_year\2_sem\well_wisher_inno_bot\app\main_logic.py", line 261, in get_today
    results = session.execute(select_query).fetchall()
  File "C:\Users\milan\OneDrive\Документы\Innopolis_studying\1_year\2_sem\well_wisher_inno_bot\venv\lib\site-packages\sqlalchemy\orm\session.py", line 2225, in execute
    return self._execute_internal(
  File "C:\Users\milan\OneDrive\Документы\Innopolis_studying\1_year\2_sem\well_wisher_inno_bot\venv\lib\site-packages\sqlalchemy\orm\session.py", line 2129, in _execute_internal
    result = conn.execute(
  File "C:\Users\milan\OneDrive\Документы\Innopolis_studying\1_year\2_sem\well_wisher_inno_bot\venv\lib\site-packages\sqlalchemy\engine\base.py", line 1412, in execute
    return meth(
  File "C:\Users\milan\OneDrive\Документы\Innopolis_studying\1_year\2_sem\well_wisher_inno_bot\venv\lib\site-packages\sqlalchemy\sql\elements.py", line 483, in _execute_on_connection
    return connection._execute_clauseelement(
  File "C:\Users\milan\OneDrive\Документы\Innopolis_studying\1_year\2_sem\well_wisher_inno_bot\venv\lib\site-packages\sqlalchemy\engine\base.py", line 1635, in _execute_clauseelement
    ret = self._execute_context(
  File "C:\Users\milan\OneDrive\Документы\Innopolis_studying\1_year\2_sem\well_wisher_inno_bot\venv\lib\site-packages\sqlalchemy\engine\base.py", line 1844, in _execute_context
    return self._exec_single_context(
  File "C:\Users\milan\OneDrive\Документы\Innopolis_studying\1_year\2_sem\well_wisher_inno_bot\venv\lib\site-packages\sqlalchemy\engine\base.py", line 1984, in _exec_single_context
    self._handle_dbapi_exception(
  File "C:\Users\milan\OneDrive\Документы\Innopolis_studying\1_year\2_sem\well_wisher_inno_bot\venv\lib\site-packages\sqlalchemy\engine\base.py", line 2339, in _handle_dbapi_exception
    raise sqlalchemy_exception.with_traceback(exc_info[2]) from e
  File "C:\Users\milan\OneDrive\Документы\Innopolis_studying\1_year\2_sem\well_wisher_inno_bot\venv\lib\site-packages\sqlalchemy\engine\base.py", line 1965, in _exec_single_context
    self.dialect.do_execute(
  File "C:\Users\milan\OneDrive\Документы\Innopolis_studying\1_year\2_sem\well_wisher_inno_bot\venv\lib\site-packages\sqlalchemy\engine\default.py", line 921, in do_execute
    cursor.execute(statement, parameters)
sqlalchemy.exc.InterfaceError: (sqlite3.InterfaceError) Error binding parameter 0 - probably unsupported type.
[SQL: SELECT "table_-857882889".data, "table_-857882889".is_birthday, "table_-857882889".date 
FROM "table_-857882889" 
WHERE "table_-857882889".date = ?]
[parameters: (<class 'datetime.datetime'>,)]
(Background on this error at: https://sqlalche.me/e/20/rvf5)
00:23:51 asyncio ERROR Task exception was never retrieved
future: <Task finished name='Task-48' coro=<Dispatcher._process_polling_updates() done, defined at C:\Users\milan\OneDrive\Документы\Innopolis_studying\1_year\2_sem\well_wisher_inno_bot\venv\lib\site-packages\aiogram\dispatcher\dispatcher.py:407> exception=InterfaceError('(sqlite3.InterfaceError) Error binding parameter 0 - probably unsupported type.')>
Traceback (most recent call last):
  File "C:\Users\milan\OneDrive\Документы\Innopolis_studying\1_year\2_sem\well_wisher_inno_bot\venv\lib\site-packages\sqlalchemy\engine\base.py", line 1965, in _exec_single_context
    self.dialect.do_execute(
  File "C:\Users\milan\OneDrive\Документы\Innopolis_studying\1_year\2_sem\well_wisher_inno_bot\venv\lib\site-packages\sqlalchemy\engine\default.py", line 921, in do_execute
    cursor.execute(statement, parameters)
sqlite3.InterfaceError: Error binding parameter 0 - probably unsupported type.

The above exception was the direct cause of the following exception:

Traceback (most recent call last):
  File "C:\Users\milan\OneDrive\Документы\Innopolis_studying\1_year\2_sem\well_wisher_inno_bot\venv\lib\site-packages\aiogram\dispatcher\dispatcher.py", line 415, in _process_polling_updates
    for responses in itertools.chain.from_iterable(await self.process_updates(updates, fast)):
  File "C:\Users\milan\OneDrive\Документы\Innopolis_studying\1_year\2_sem\well_wisher_inno_bot\venv\lib\site-packages\aiogram\dispatcher\dispatcher.py", line 235, in process_updates
    return await asyncio.gather(*tasks)
  File "C:\Users\milan\OneDrive\Документы\Innopolis_studying\1_year\2_sem\well_wisher_inno_bot\venv\lib\site-packages\aiogram\dispatcher\handler.py", line 117, in notify
    response = await handler_obj.handler(*args, **partial_data)
  File "C:\Users\milan\OneDrive\Документы\Innopolis_studying\1_year\2_sem\well_wisher_inno_bot\venv\lib\site-packages\aiogram\dispatcher\dispatcher.py", line 256, in process_update
    return await self.message_handlers.notify(update.message)
  File "C:\Users\milan\OneDrive\Документы\Innopolis_studying\1_year\2_sem\well_wisher_inno_bot\venv\lib\site-packages\aiogram\dispatcher\handler.py", line 117, in notify
    response = await handler_obj.handler(*args, **partial_data)
  File "C:\Users\milan\OneDrive\Документы\Innopolis_studying\1_year\2_sem\well_wisher_inno_bot\app\main_logic.py", line 261, in get_today
    results = session.execute(select_query).fetchall()
  File "C:\Users\milan\OneDrive\Документы\Innopolis_studying\1_year\2_sem\well_wisher_inno_bot\venv\lib\site-packages\sqlalchemy\orm\session.py", line 2225, in execute
    return self._execute_internal(
  File "C:\Users\milan\OneDrive\Документы\Innopolis_studying\1_year\2_sem\well_wisher_inno_bot\venv\lib\site-packages\sqlalchemy\orm\session.py", line 2129, in _execute_internal
    result = conn.execute(
  File "C:\Users\milan\OneDrive\Документы\Innopolis_studying\1_year\2_sem\well_wisher_inno_bot\venv\lib\site-packages\sqlalchemy\engine\base.py", line 1412, in execute
    return meth(
  File "C:\Users\milan\OneDrive\Документы\Innopolis_studying\1_year\2_sem\well_wisher_inno_bot\venv\lib\site-packages\sqlalchemy\sql\elements.py", line 483, in _execute_on_connection
    return connection._execute_clauseelement(
  File "C:\Users\milan\OneDrive\Документы\Innopolis_studying\1_year\2_sem\well_wisher_inno_bot\venv\lib\site-packages\sqlalchemy\engine\base.py", line 1635, in _execute_clauseelement
    ret = self._execute_context(
  File "C:\Users\milan\OneDrive\Документы\Innopolis_studying\1_year\2_sem\well_wisher_inno_bot\venv\lib\site-packages\sqlalchemy\engine\base.py", line 1844, in _execute_context
    return self._exec_single_context(
  File "C:\Users\milan\OneDrive\Документы\Innopolis_studying\1_year\2_sem\well_wisher_inno_bot\venv\lib\site-packages\sqlalchemy\engine\base.py", line 1984, in _exec_single_context
    self._handle_dbapi_exception(
  File "C:\Users\milan\OneDrive\Документы\Innopolis_studying\1_year\2_sem\well_wisher_inno_bot\venv\lib\site-packages\sqlalchemy\engine\base.py", line 2339, in _handle_dbapi_exception
    raise sqlalchemy_exception.with_traceback(exc_info[2]) from e
  File "C:\Users\milan\OneDrive\Документы\Innopolis_studying\1_year\2_sem\well_wisher_inno_bot\venv\lib\site-packages\sqlalchemy\engine\base.py", line 1965, in _exec_single_context
    self.dialect.do_execute(
  File "C:\Users\milan\OneDrive\Документы\Innopolis_studying\1_year\2_sem\well_wisher_inno_bot\venv\lib\site-packages\sqlalchemy\engine\default.py", line 921, in do_execute
    cursor.execute(statement, parameters)
sqlalchemy.exc.InterfaceError: (sqlite3.InterfaceError) Error binding parameter 0 - probably unsupported type.
[SQL: SELECT "table_-857882889".data, "table_-857882889".is_birthday, "table_-857882889".date 
FROM "table_-857882889" 
WHERE "table_-857882889".date = ?]
[parameters: (<class 'datetime.datetime'>,)]
(Background on this error at: https://sqlalche.me/e/20/rvf5)
00:24:45 aiogram.dispatcher.dispatcher INFO Stop polling...
00:24:45 aiogram WARNING Goodbye!
00:24:47 aiogram INFO Bot: Well Wisher Bot [@well_wisher_inno_bot]
00:24:47 aiogram WARNING Updates were skipped successfully.
00:24:47 root INFO Bot is starting...
00:24:48 aiogram.dispatcher.dispatcher INFO Start polling.
00:25:06 aiogram.dispatcher.dispatcher INFO Stop polling...
00:25:06 aiogram WARNING Goodbye!
00:25:09 aiogram INFO Bot: Well Wisher Bot [@well_wisher_inno_bot]
00:25:09 aiogram WARNING Updates were skipped successfully.
00:25:09 root INFO Bot is starting...
00:25:09 aiogram.dispatcher.dispatcher INFO Start polling.
00:25:11 asyncio ERROR Task exception was never retrieved
future: <Task finished name='Task-10' coro=<Dispatcher._process_polling_updates() done, defined at C:\Users\milan\OneDrive\Документы\Innopolis_studying\1_year\2_sem\well_wisher_inno_bot\venv\lib\site-packages\aiogram\dispatcher\dispatcher.py:407> exception=TypeError("descriptor 'strftime' for 'datetime.date' objects doesn't apply to a 'str' object")>
Traceback (most recent call last):
  File "C:\Users\milan\OneDrive\Документы\Innopolis_studying\1_year\2_sem\well_wisher_inno_bot\venv\lib\site-packages\aiogram\dispatcher\dispatcher.py", line 415, in _process_polling_updates
    for responses in itertools.chain.from_iterable(await self.process_updates(updates, fast)):
  File "C:\Users\milan\OneDrive\Документы\Innopolis_studying\1_year\2_sem\well_wisher_inno_bot\venv\lib\site-packages\aiogram\dispatcher\dispatcher.py", line 235, in process_updates
    return await asyncio.gather(*tasks)
  File "C:\Users\milan\OneDrive\Документы\Innopolis_studying\1_year\2_sem\well_wisher_inno_bot\venv\lib\site-packages\aiogram\dispatcher\handler.py", line 117, in notify
    response = await handler_obj.handler(*args, **partial_data)
  File "C:\Users\milan\OneDrive\Документы\Innopolis_studying\1_year\2_sem\well_wisher_inno_bot\venv\lib\site-packages\aiogram\dispatcher\dispatcher.py", line 256, in process_update
    return await self.message_handlers.notify(update.message)
  File "C:\Users\milan\OneDrive\Документы\Innopolis_studying\1_year\2_sem\well_wisher_inno_bot\venv\lib\site-packages\aiogram\dispatcher\handler.py", line 117, in notify
    response = await handler_obj.handler(*args, **partial_data)
  File "C:\Users\milan\OneDrive\Документы\Innopolis_studying\1_year\2_sem\well_wisher_inno_bot\app\main_logic.py", line 260, in get_today
    select_query = table.select().where(table.c.date == datetime.datetime.strftime('%Y-%m-%d %H:%M:%S'))
TypeError: descriptor 'strftime' for 'datetime.date' objects doesn't apply to a 'str' object
00:26:11 aiogram.dispatcher.dispatcher INFO Stop polling...
00:26:11 aiogram WARNING Goodbye!
00:26:13 aiogram INFO Bot: Well Wisher Bot [@well_wisher_inno_bot]
00:26:13 aiogram WARNING Updates were skipped successfully.
00:26:13 root INFO Bot is starting...
00:26:13 aiogram.dispatcher.dispatcher INFO Start polling.
00:28:00 aiogram.dispatcher.dispatcher INFO Stop polling...
00:28:00 aiogram WARNING Goodbye!
00:28:03 aiogram INFO Bot: Well Wisher Bot [@well_wisher_inno_bot]
00:28:03 aiogram WARNING Updates were skipped successfully.
00:28:03 root INFO Bot is starting...
00:28:03 aiogram.dispatcher.dispatcher INFO Start polling.
00:28:14 asyncio ERROR Task exception was never retrieved
future: <Task finished name='Task-15' coro=<Dispatcher._process_polling_updates() done, defined at C:\Users\milan\OneDrive\Документы\Innopolis_studying\1_year\2_sem\well_wisher_inno_bot\venv\lib\site-packages\aiogram\dispatcher\dispatcher.py:407> exception=TypeError("descriptor 'strftime' for 'datetime.date' objects doesn't apply to a 'str' object")>
Traceback (most recent call last):
  File "C:\Users\milan\OneDrive\Документы\Innopolis_studying\1_year\2_sem\well_wisher_inno_bot\venv\lib\site-packages\aiogram\dispatcher\dispatcher.py", line 415, in _process_polling_updates
    for responses in itertools.chain.from_iterable(await self.process_updates(updates, fast)):
  File "C:\Users\milan\OneDrive\Документы\Innopolis_studying\1_year\2_sem\well_wisher_inno_bot\venv\lib\site-packages\aiogram\dispatcher\dispatcher.py", line 235, in process_updates
    return await asyncio.gather(*tasks)
  File "C:\Users\milan\OneDrive\Документы\Innopolis_studying\1_year\2_sem\well_wisher_inno_bot\venv\lib\site-packages\aiogram\dispatcher\handler.py", line 117, in notify
    response = await handler_obj.handler(*args, **partial_data)
  File "C:\Users\milan\OneDrive\Документы\Innopolis_studying\1_year\2_sem\well_wisher_inno_bot\venv\lib\site-packages\aiogram\dispatcher\dispatcher.py", line 256, in process_update
    return await self.message_handlers.notify(update.message)
  File "C:\Users\milan\OneDrive\Документы\Innopolis_studying\1_year\2_sem\well_wisher_inno_bot\venv\lib\site-packages\aiogram\dispatcher\handler.py", line 117, in notify
    response = await handler_obj.handler(*args, **partial_data)
  File "C:\Users\milan\OneDrive\Документы\Innopolis_studying\1_year\2_sem\well_wisher_inno_bot\app\main_logic.py", line 261, in get_today
    print(datetime.datetime.strftime('%Y-%m-%d %H:%M:%S'))
TypeError: descriptor 'strftime' for 'datetime.date' objects doesn't apply to a 'str' object
00:29:00 aiogram.dispatcher.dispatcher INFO Stop polling...
00:29:00 aiogram WARNING Goodbye!
00:29:02 aiogram INFO Bot: Well Wisher Bot [@well_wisher_inno_bot]
00:29:03 aiogram WARNING Updates were skipped successfully.
00:29:03 root INFO Bot is starting...
00:29:03 aiogram.dispatcher.dispatcher INFO Start polling.
00:29:12 asyncio ERROR Task exception was never retrieved
future: <Task finished name='Task-10' coro=<Dispatcher._process_polling_updates() done, defined at C:\Users\milan\OneDrive\Документы\Innopolis_studying\1_year\2_sem\well_wisher_inno_bot\venv\lib\site-packages\aiogram\dispatcher\dispatcher.py:407> exception=TypeError("descriptor 'strftime' for 'datetime.date' objects doesn't apply to a 'str' object")>
Traceback (most recent call last):
  File "C:\Users\milan\OneDrive\Документы\Innopolis_studying\1_year\2_sem\well_wisher_inno_bot\venv\lib\site-packages\aiogram\dispatcher\dispatcher.py", line 415, in _process_polling_updates
    for responses in itertools.chain.from_iterable(await self.process_updates(updates, fast)):
  File "C:\Users\milan\OneDrive\Документы\Innopolis_studying\1_year\2_sem\well_wisher_inno_bot\venv\lib\site-packages\aiogram\dispatcher\dispatcher.py", line 235, in process_updates
    return await asyncio.gather(*tasks)
  File "C:\Users\milan\OneDrive\Документы\Innopolis_studying\1_year\2_sem\well_wisher_inno_bot\venv\lib\site-packages\aiogram\dispatcher\handler.py", line 117, in notify
    response = await handler_obj.handler(*args, **partial_data)
  File "C:\Users\milan\OneDrive\Документы\Innopolis_studying\1_year\2_sem\well_wisher_inno_bot\venv\lib\site-packages\aiogram\dispatcher\dispatcher.py", line 256, in process_update
    return await self.message_handlers.notify(update.message)
  File "C:\Users\milan\OneDrive\Документы\Innopolis_studying\1_year\2_sem\well_wisher_inno_bot\venv\lib\site-packages\aiogram\dispatcher\handler.py", line 117, in notify
    response = await handler_obj.handler(*args, **partial_data)
  File "C:\Users\milan\OneDrive\Документы\Innopolis_studying\1_year\2_sem\well_wisher_inno_bot\app\main_logic.py", line 263, in get_today
    select_query = table.select().where(table.c.date == datetime.datetime.strftime('%Y-%m-%d %H:%M:%S'))
TypeError: descriptor 'strftime' for 'datetime.date' objects doesn't apply to a 'str' object
00:29:59 aiogram.dispatcher.dispatcher INFO Stop polling...
00:29:59 aiogram WARNING Goodbye!
00:30:02 aiogram INFO Bot: Well Wisher Bot [@well_wisher_inno_bot]
00:30:02 aiogram WARNING Updates were skipped successfully.
00:30:02 root INFO Bot is starting...
00:30:02 aiogram.dispatcher.dispatcher INFO Start polling.
00:30:04 asyncio ERROR Task exception was never retrieved
future: <Task finished name='Task-10' coro=<Dispatcher._process_polling_updates() done, defined at C:\Users\milan\OneDrive\Документы\Innopolis_studying\1_year\2_sem\well_wisher_inno_bot\venv\lib\site-packages\aiogram\dispatcher\dispatcher.py:407> exception=TypeError('strftime() argument 1 must be str, not type')>
Traceback (most recent call last):
  File "C:\Users\milan\OneDrive\Документы\Innopolis_studying\1_year\2_sem\well_wisher_inno_bot\venv\lib\site-packages\aiogram\dispatcher\dispatcher.py", line 415, in _process_polling_updates
    for responses in itertools.chain.from_iterable(await self.process_updates(updates, fast)):
  File "C:\Users\milan\OneDrive\Документы\Innopolis_studying\1_year\2_sem\well_wisher_inno_bot\venv\lib\site-packages\aiogram\dispatcher\dispatcher.py", line 235, in process_updates
    return await asyncio.gather(*tasks)
  File "C:\Users\milan\OneDrive\Документы\Innopolis_studying\1_year\2_sem\well_wisher_inno_bot\venv\lib\site-packages\aiogram\dispatcher\handler.py", line 117, in notify
    response = await handler_obj.handler(*args, **partial_data)
  File "C:\Users\milan\OneDrive\Документы\Innopolis_studying\1_year\2_sem\well_wisher_inno_bot\venv\lib\site-packages\aiogram\dispatcher\dispatcher.py", line 256, in process_update
    return await self.message_handlers.notify(update.message)
  File "C:\Users\milan\OneDrive\Документы\Innopolis_studying\1_year\2_sem\well_wisher_inno_bot\venv\lib\site-packages\aiogram\dispatcher\handler.py", line 117, in notify
    response = await handler_obj.handler(*args, **partial_data)
  File "C:\Users\milan\OneDrive\Документы\Innopolis_studying\1_year\2_sem\well_wisher_inno_bot\app\main_logic.py", line 263, in get_today
    print(strftime(datetime.datetime))
TypeError: strftime() argument 1 must be str, not type
00:31:34 aiogram.dispatcher.dispatcher INFO Stop polling...
00:31:34 aiogram WARNING Goodbye!
00:31:37 aiogram INFO Bot: Well Wisher Bot [@well_wisher_inno_bot]
00:31:37 aiogram WARNING Updates were skipped successfully.
00:31:37 root INFO Bot is starting...
00:31:37 aiogram.dispatcher.dispatcher INFO Start polling.
00:31:38 asyncio ERROR Task exception was never retrieved
future: <Task finished name='Task-10' coro=<Dispatcher._process_polling_updates() done, defined at C:\Users\milan\OneDrive\Документы\Innopolis_studying\1_year\2_sem\well_wisher_inno_bot\venv\lib\site-packages\aiogram\dispatcher\dispatcher.py:407> exception=AttributeError("module 'datetime' has no attribute 'today'")>
Traceback (most recent call last):
  File "C:\Users\milan\OneDrive\Документы\Innopolis_studying\1_year\2_sem\well_wisher_inno_bot\venv\lib\site-packages\aiogram\dispatcher\dispatcher.py", line 415, in _process_polling_updates
    for responses in itertools.chain.from_iterable(await self.process_updates(updates, fast)):
  File "C:\Users\milan\OneDrive\Документы\Innopolis_studying\1_year\2_sem\well_wisher_inno_bot\venv\lib\site-packages\aiogram\dispatcher\dispatcher.py", line 235, in process_updates
    return await asyncio.gather(*tasks)
  File "C:\Users\milan\OneDrive\Документы\Innopolis_studying\1_year\2_sem\well_wisher_inno_bot\venv\lib\site-packages\aiogram\dispatcher\handler.py", line 117, in notify
    response = await handler_obj.handler(*args, **partial_data)
  File "C:\Users\milan\OneDrive\Документы\Innopolis_studying\1_year\2_sem\well_wisher_inno_bot\venv\lib\site-packages\aiogram\dispatcher\dispatcher.py", line 256, in process_update
    return await self.message_handlers.notify(update.message)
  File "C:\Users\milan\OneDrive\Документы\Innopolis_studying\1_year\2_sem\well_wisher_inno_bot\venv\lib\site-packages\aiogram\dispatcher\handler.py", line 117, in notify
    response = await handler_obj.handler(*args, **partial_data)
  File "C:\Users\milan\OneDrive\Документы\Innopolis_studying\1_year\2_sem\well_wisher_inno_bot\app\main_logic.py", line 263, in get_today
    print(datetime.today().strftime('%Y-%m-%d'))
AttributeError: module 'datetime' has no attribute 'today'
00:32:45 aiogram.dispatcher.dispatcher INFO Stop polling...
00:32:45 aiogram WARNING Goodbye!
00:32:47 aiogram INFO Bot: Well Wisher Bot [@well_wisher_inno_bot]
00:32:48 aiogram WARNING Updates were skipped successfully.
00:32:48 root INFO Bot is starting...
00:32:48 aiogram.dispatcher.dispatcher INFO Start polling.
00:32:50 asyncio ERROR Task exception was never retrieved
future: <Task finished name='Task-10' coro=<Dispatcher._process_polling_updates() done, defined at C:\Users\milan\OneDrive\Документы\Innopolis_studying\1_year\2_sem\well_wisher_inno_bot\venv\lib\site-packages\aiogram\dispatcher\dispatcher.py:407> exception=TypeError("descriptor 'strftime' for 'datetime.date' objects doesn't apply to a 'str' object")>
Traceback (most recent call last):
  File "C:\Users\milan\OneDrive\Документы\Innopolis_studying\1_year\2_sem\well_wisher_inno_bot\venv\lib\site-packages\aiogram\dispatcher\dispatcher.py", line 415, in _process_polling_updates
    for responses in itertools.chain.from_iterable(await self.process_updates(updates, fast)):
  File "C:\Users\milan\OneDrive\Документы\Innopolis_studying\1_year\2_sem\well_wisher_inno_bot\venv\lib\site-packages\aiogram\dispatcher\dispatcher.py", line 235, in process_updates
    return await asyncio.gather(*tasks)
  File "C:\Users\milan\OneDrive\Документы\Innopolis_studying\1_year\2_sem\well_wisher_inno_bot\venv\lib\site-packages\aiogram\dispatcher\handler.py", line 117, in notify
    response = await handler_obj.handler(*args, **partial_data)
  File "C:\Users\milan\OneDrive\Документы\Innopolis_studying\1_year\2_sem\well_wisher_inno_bot\venv\lib\site-packages\aiogram\dispatcher\dispatcher.py", line 256, in process_update
    return await self.message_handlers.notify(update.message)
  File "C:\Users\milan\OneDrive\Документы\Innopolis_studying\1_year\2_sem\well_wisher_inno_bot\venv\lib\site-packages\aiogram\dispatcher\handler.py", line 117, in notify
    response = await handler_obj.handler(*args, **partial_data)
  File "C:\Users\milan\OneDrive\Документы\Innopolis_studying\1_year\2_sem\well_wisher_inno_bot\app\main_logic.py", line 265, in get_today
    select_query = table.select().where(table.c.date == datetime.datetime.strftime('%Y-%m-%d %H:%M:%S'))
TypeError: descriptor 'strftime' for 'datetime.date' objects doesn't apply to a 'str' object
00:33:03 aiogram.dispatcher.dispatcher INFO Stop polling...
00:33:03 aiogram WARNING Goodbye!
00:33:06 aiogram INFO Bot: Well Wisher Bot [@well_wisher_inno_bot]
00:33:06 aiogram WARNING Updates were skipped successfully.
00:33:06 root INFO Bot is starting...
00:33:06 aiogram.dispatcher.dispatcher INFO Start polling.
00:33:56 aiogram.dispatcher.dispatcher INFO Stop polling...
00:33:56 aiogram WARNING Goodbye!
00:33:59 aiogram INFO Bot: Well Wisher Bot [@well_wisher_inno_bot]
00:33:59 aiogram WARNING Updates were skipped successfully.
00:33:59 root INFO Bot is starting...
00:34:00 aiogram.dispatcher.dispatcher INFO Start polling.
00:34:04 asyncio ERROR Task exception was never retrieved
future: <Task finished name='Task-10' coro=<Dispatcher._process_polling_updates() done, defined at C:\Users\milan\OneDrive\Документы\Innopolis_studying\1_year\2_sem\well_wisher_inno_bot\venv\lib\site-packages\aiogram\dispatcher\dispatcher.py:407> exception=AttributeError("Neither 'Column' object nor 'Comparator' object has an attribute 'split'")>
Traceback (most recent call last):
  File "C:\Users\milan\OneDrive\Документы\Innopolis_studying\1_year\2_sem\well_wisher_inno_bot\venv\lib\site-packages\sqlalchemy\sql\elements.py", line 1521, in __getattr__
    return getattr(self.comparator, key)
AttributeError: 'Comparator' object has no attribute 'split'

The above exception was the direct cause of the following exception:

Traceback (most recent call last):
  File "C:\Users\milan\OneDrive\Документы\Innopolis_studying\1_year\2_sem\well_wisher_inno_bot\venv\lib\site-packages\aiogram\dispatcher\dispatcher.py", line 415, in _process_polling_updates
    for responses in itertools.chain.from_iterable(await self.process_updates(updates, fast)):
  File "C:\Users\milan\OneDrive\Документы\Innopolis_studying\1_year\2_sem\well_wisher_inno_bot\venv\lib\site-packages\aiogram\dispatcher\dispatcher.py", line 235, in process_updates
    return await asyncio.gather(*tasks)
  File "C:\Users\milan\OneDrive\Документы\Innopolis_studying\1_year\2_sem\well_wisher_inno_bot\venv\lib\site-packages\aiogram\dispatcher\handler.py", line 117, in notify
    response = await handler_obj.handler(*args, **partial_data)
  File "C:\Users\milan\OneDrive\Документы\Innopolis_studying\1_year\2_sem\well_wisher_inno_bot\venv\lib\site-packages\aiogram\dispatcher\dispatcher.py", line 256, in process_update
    return await self.message_handlers.notify(update.message)
  File "C:\Users\milan\OneDrive\Документы\Innopolis_studying\1_year\2_sem\well_wisher_inno_bot\venv\lib\site-packages\aiogram\dispatcher\handler.py", line 117, in notify
    response = await handler_obj.handler(*args, **partial_data)
  File "C:\Users\milan\OneDrive\Документы\Innopolis_studying\1_year\2_sem\well_wisher_inno_bot\app\main_logic.py", line 265, in get_today
    select_query = table.select().where(table.c.date.split()[0] == datetime.date.today().strftime('%Y-%m-%d'))
  File "C:\Users\milan\OneDrive\Документы\Innopolis_studying\1_year\2_sem\well_wisher_inno_bot\venv\lib\site-packages\sqlalchemy\sql\elements.py", line 1523, in __getattr__
    raise AttributeError(
AttributeError: Neither 'Column' object nor 'Comparator' object has an attribute 'split'
00:40:46 aiogram.dispatcher.dispatcher ERROR Cause exception while getting updates.
Traceback (most recent call last):
  File "C:\Users\milan\OneDrive\Документы\Innopolis_studying\1_year\2_sem\well_wisher_inno_bot\venv\lib\site-packages\aiogram\dispatcher\dispatcher.py", line 381, in start_polling
    updates = await self.bot.get_updates(
  File "C:\Users\milan\OneDrive\Документы\Innopolis_studying\1_year\2_sem\well_wisher_inno_bot\venv\lib\site-packages\aiogram\bot\bot.py", line 110, in get_updates
    result = await self.request(api.Methods.GET_UPDATES, payload)
  File "C:\Users\milan\OneDrive\Документы\Innopolis_studying\1_year\2_sem\well_wisher_inno_bot\venv\lib\site-packages\aiogram\bot\base.py", line 236, in request
    return await api.make_request(await self.get_session(), self.server, self.__token, method, data, files,
  File "C:\Users\milan\OneDrive\Документы\Innopolis_studying\1_year\2_sem\well_wisher_inno_bot\venv\lib\site-packages\aiogram\bot\api.py", line 139, in make_request
    async with session.post(url, data=req, **kwargs) as response:
  File "C:\Users\milan\OneDrive\Документы\Innopolis_studying\1_year\2_sem\well_wisher_inno_bot\venv\lib\site-packages\aiohttp\client.py", line 1141, in __aenter__
    self._resp = await self._coro
  File "C:\Users\milan\OneDrive\Документы\Innopolis_studying\1_year\2_sem\well_wisher_inno_bot\venv\lib\site-packages\aiohttp\client.py", line 560, in _request
    await resp.start(conn)
  File "C:\Users\milan\OneDrive\Документы\Innopolis_studying\1_year\2_sem\well_wisher_inno_bot\venv\lib\site-packages\aiohttp\client_reqrep.py", line 894, in start
    with self._timer:
  File "C:\Users\milan\OneDrive\Документы\Innopolis_studying\1_year\2_sem\well_wisher_inno_bot\venv\lib\site-packages\aiohttp\helpers.py", line 721, in __exit__
    raise asyncio.TimeoutError from None
asyncio.exceptions.TimeoutError
00:46:13 asyncio ERROR Task exception was never retrieved
future: <Task finished name='Task-35' coro=<Dispatcher._process_polling_updates() done, defined at C:\Users\milan\OneDrive\Документы\Innopolis_studying\1_year\2_sem\well_wisher_inno_bot\venv\lib\site-packages\aiogram\dispatcher\dispatcher.py:407> exception=AttributeError("Neither 'Column' object nor 'Comparator' object has an attribute 'split'")>
Traceback (most recent call last):
  File "C:\Users\milan\OneDrive\Документы\Innopolis_studying\1_year\2_sem\well_wisher_inno_bot\venv\lib\site-packages\sqlalchemy\sql\elements.py", line 1521, in __getattr__
    return getattr(self.comparator, key)
AttributeError: 'Comparator' object has no attribute 'split'

The above exception was the direct cause of the following exception:

Traceback (most recent call last):
  File "C:\Users\milan\OneDrive\Документы\Innopolis_studying\1_year\2_sem\well_wisher_inno_bot\venv\lib\site-packages\aiogram\dispatcher\dispatcher.py", line 415, in _process_polling_updates
    for responses in itertools.chain.from_iterable(await self.process_updates(updates, fast)):
  File "C:\Users\milan\OneDrive\Документы\Innopolis_studying\1_year\2_sem\well_wisher_inno_bot\venv\lib\site-packages\aiogram\dispatcher\dispatcher.py", line 235, in process_updates
    return await asyncio.gather(*tasks)
  File "C:\Users\milan\OneDrive\Документы\Innopolis_studying\1_year\2_sem\well_wisher_inno_bot\venv\lib\site-packages\aiogram\dispatcher\handler.py", line 117, in notify
    response = await handler_obj.handler(*args, **partial_data)
  File "C:\Users\milan\OneDrive\Документы\Innopolis_studying\1_year\2_sem\well_wisher_inno_bot\venv\lib\site-packages\aiogram\dispatcher\dispatcher.py", line 256, in process_update
    return await self.message_handlers.notify(update.message)
  File "C:\Users\milan\OneDrive\Документы\Innopolis_studying\1_year\2_sem\well_wisher_inno_bot\venv\lib\site-packages\aiogram\dispatcher\handler.py", line 117, in notify
    response = await handler_obj.handler(*args, **partial_data)
  File "C:\Users\milan\OneDrive\Документы\Innopolis_studying\1_year\2_sem\well_wisher_inno_bot\app\main_logic.py", line 265, in get_today
    select_query = table.select().where(func.split(table.c.date, ' ')[0] == datetime.date.today().strftime('%Y-%m-%d'))
  File "C:\Users\milan\OneDrive\Документы\Innopolis_studying\1_year\2_sem\well_wisher_inno_bot\venv\lib\site-packages\sqlalchemy\sql\elements.py", line 1523, in __getattr__
    raise AttributeError(
AttributeError: Neither 'Column' object nor 'Comparator' object has an attribute 'split'
00:46:18 aiogram.dispatcher.dispatcher INFO Stop polling...
00:46:18 aiogram WARNING Goodbye!
00:46:21 aiogram INFO Bot: Well Wisher Bot [@well_wisher_inno_bot]
00:46:21 aiogram WARNING Updates were skipped successfully.
00:46:21 root INFO Bot is starting...
00:46:21 aiogram.dispatcher.dispatcher INFO Start polling.
00:46:24 asyncio ERROR Task exception was never retrieved
future: <Task finished name='Task-10' coro=<Dispatcher._process_polling_updates() done, defined at C:\Users\milan\OneDrive\Документы\Innopolis_studying\1_year\2_sem\well_wisher_inno_bot\venv\lib\site-packages\aiogram\dispatcher\dispatcher.py:407> exception=NameError("name 'func' is not defined")>
Traceback (most recent call last):
  File "C:\Users\milan\OneDrive\Документы\Innopolis_studying\1_year\2_sem\well_wisher_inno_bot\venv\lib\site-packages\aiogram\dispatcher\dispatcher.py", line 415, in _process_polling_updates
    for responses in itertools.chain.from_iterable(await self.process_updates(updates, fast)):
  File "C:\Users\milan\OneDrive\Документы\Innopolis_studying\1_year\2_sem\well_wisher_inno_bot\venv\lib\site-packages\aiogram\dispatcher\dispatcher.py", line 235, in process_updates
    return await asyncio.gather(*tasks)
  File "C:\Users\milan\OneDrive\Документы\Innopolis_studying\1_year\2_sem\well_wisher_inno_bot\venv\lib\site-packages\aiogram\dispatcher\handler.py", line 117, in notify
    response = await handler_obj.handler(*args, **partial_data)
  File "C:\Users\milan\OneDrive\Документы\Innopolis_studying\1_year\2_sem\well_wisher_inno_bot\venv\lib\site-packages\aiogram\dispatcher\dispatcher.py", line 256, in process_update
    return await self.message_handlers.notify(update.message)
  File "C:\Users\milan\OneDrive\Документы\Innopolis_studying\1_year\2_sem\well_wisher_inno_bot\venv\lib\site-packages\aiogram\dispatcher\handler.py", line 117, in notify
    response = await handler_obj.handler(*args, **partial_data)
  File "C:\Users\milan\OneDrive\Документы\Innopolis_studying\1_year\2_sem\well_wisher_inno_bot\app\main_logic.py", line 265, in get_today
    select_query = table.select().where(func.split(table.c.date, ' ')[0] == datetime.date.today().strftime('%Y-%m-%d'))
NameError: name 'func' is not defined
00:47:06 aiogram.dispatcher.dispatcher INFO Stop polling...
00:47:06 aiogram WARNING Goodbye!
00:47:09 aiogram INFO Bot: Well Wisher Bot [@well_wisher_inno_bot]
00:47:10 aiogram WARNING Updates were skipped successfully.
00:47:10 root INFO Bot is starting...
00:47:10 aiogram.dispatcher.dispatcher INFO Start polling.
00:47:11 asyncio ERROR Task exception was never retrieved
future: <Task finished name='Task-10' coro=<Dispatcher._process_polling_updates() done, defined at C:\Users\milan\OneDrive\Документы\Innopolis_studying\1_year\2_sem\well_wisher_inno_bot\venv\lib\site-packages\aiogram\dispatcher\dispatcher.py:407> exception=NotImplementedError("Operator 'getitem' is not supported on this expression")>
Traceback (most recent call last):
  File "C:\Users\milan\OneDrive\Документы\Innopolis_studying\1_year\2_sem\well_wisher_inno_bot\venv\lib\site-packages\aiogram\dispatcher\dispatcher.py", line 415, in _process_polling_updates
    for responses in itertools.chain.from_iterable(await self.process_updates(updates, fast)):
  File "C:\Users\milan\OneDrive\Документы\Innopolis_studying\1_year\2_sem\well_wisher_inno_bot\venv\lib\site-packages\aiogram\dispatcher\dispatcher.py", line 235, in process_updates
    return await asyncio.gather(*tasks)
  File "C:\Users\milan\OneDrive\Документы\Innopolis_studying\1_year\2_sem\well_wisher_inno_bot\venv\lib\site-packages\aiogram\dispatcher\handler.py", line 117, in notify
    response = await handler_obj.handler(*args, **partial_data)
  File "C:\Users\milan\OneDrive\Документы\Innopolis_studying\1_year\2_sem\well_wisher_inno_bot\venv\lib\site-packages\aiogram\dispatcher\dispatcher.py", line 256, in process_update
    return await self.message_handlers.notify(update.message)
  File "C:\Users\milan\OneDrive\Документы\Innopolis_studying\1_year\2_sem\well_wisher_inno_bot\venv\lib\site-packages\aiogram\dispatcher\handler.py", line 117, in notify
    response = await handler_obj.handler(*args, **partial_data)
  File "C:\Users\milan\OneDrive\Документы\Innopolis_studying\1_year\2_sem\well_wisher_inno_bot\app\main_logic.py", line 265, in get_today
    select_query = table.select().where(func.split(table.c.date, ' ')[0] == datetime.date.today().strftime('%Y-%m-%d'))
  File "C:\Users\milan\OneDrive\Документы\Innopolis_studying\1_year\2_sem\well_wisher_inno_bot\venv\lib\site-packages\sqlalchemy\sql\operators.py", line 615, in __getitem__
    return self.operate(getitem, index)
  File "C:\Users\milan\OneDrive\Документы\Innopolis_studying\1_year\2_sem\well_wisher_inno_bot\venv\lib\site-packages\sqlalchemy\sql\elements.py", line 1538, in operate
    return op(self.comparator, *other, **kwargs)  # type: ignore[return-value]  # noqa: E501
  File "C:\Users\milan\OneDrive\Документы\Innopolis_studying\1_year\2_sem\well_wisher_inno_bot\venv\lib\site-packages\sqlalchemy\sql\operators.py", line 615, in __getitem__
    return self.operate(getitem, index)
  File "C:\Users\milan\OneDrive\Документы\Innopolis_studying\1_year\2_sem\well_wisher_inno_bot\venv\lib\site-packages\sqlalchemy\sql\type_api.py", line 194, in operate
    return op_fn(self.expr, op, *other, **addtl_kw)  # type: ignore
  File "C:\Users\milan\OneDrive\Документы\Innopolis_studying\1_year\2_sem\well_wisher_inno_bot\venv\lib\site-packages\sqlalchemy\sql\default_comparator.py", line 244, in _getitem_impl
    _unsupported_impl(expr, op, other, **kw)
  File "C:\Users\milan\OneDrive\Документы\Innopolis_studying\1_year\2_sem\well_wisher_inno_bot\venv\lib\site-packages\sqlalchemy\sql\default_comparator.py", line 250, in _unsupported_impl
    raise NotImplementedError(
NotImplementedError: Operator 'getitem' is not supported on this expression
00:47:38 aiogram.dispatcher.dispatcher INFO Stop polling...
00:47:38 aiogram WARNING Goodbye!
10:03:23 aiogram INFO Bot: Well Wisher Bot [@well_wisher_inno_bot]
10:03:24 aiogram WARNING Updates were skipped successfully.
10:03:24 root INFO Bot is starting...
10:03:24 aiogram.dispatcher.dispatcher INFO Start polling.
10:03:30 asyncio ERROR Task exception was never retrieved
future: <Task finished name='Task-10' coro=<Dispatcher._process_polling_updates() done, defined at C:\Users\milan\OneDrive\Документы\Innopolis_studying\1_year\2_sem\well_wisher_inno_bot\venv\lib\site-packages\aiogram\dispatcher\dispatcher.py:407> exception=NotImplementedError("Operator 'getitem' is not supported on this expression")>
Traceback (most recent call last):
  File "C:\Users\milan\OneDrive\Документы\Innopolis_studying\1_year\2_sem\well_wisher_inno_bot\venv\lib\site-packages\aiogram\dispatcher\dispatcher.py", line 415, in _process_polling_updates
    for responses in itertools.chain.from_iterable(await self.process_updates(updates, fast)):
  File "C:\Users\milan\OneDrive\Документы\Innopolis_studying\1_year\2_sem\well_wisher_inno_bot\venv\lib\site-packages\aiogram\dispatcher\dispatcher.py", line 235, in process_updates
    return await asyncio.gather(*tasks)
  File "C:\Users\milan\OneDrive\Документы\Innopolis_studying\1_year\2_sem\well_wisher_inno_bot\venv\lib\site-packages\aiogram\dispatcher\handler.py", line 117, in notify
    response = await handler_obj.handler(*args, **partial_data)
  File "C:\Users\milan\OneDrive\Документы\Innopolis_studying\1_year\2_sem\well_wisher_inno_bot\venv\lib\site-packages\aiogram\dispatcher\dispatcher.py", line 256, in process_update
    return await self.message_handlers.notify(update.message)
  File "C:\Users\milan\OneDrive\Документы\Innopolis_studying\1_year\2_sem\well_wisher_inno_bot\venv\lib\site-packages\aiogram\dispatcher\handler.py", line 117, in notify
    response = await handler_obj.handler(*args, **partial_data)
  File "C:\Users\milan\OneDrive\Документы\Innopolis_studying\1_year\2_sem\well_wisher_inno_bot\app\main_logic.py", line 265, in get_today
    select_query = table.select().where(func.split(table.c.date, ' ')[0] == datetime.date.today().strftime('%Y-%m-%d'))
  File "C:\Users\milan\OneDrive\Документы\Innopolis_studying\1_year\2_sem\well_wisher_inno_bot\venv\lib\site-packages\sqlalchemy\sql\operators.py", line 615, in __getitem__
    return self.operate(getitem, index)
  File "C:\Users\milan\OneDrive\Документы\Innopolis_studying\1_year\2_sem\well_wisher_inno_bot\venv\lib\site-packages\sqlalchemy\sql\elements.py", line 1538, in operate
    return op(self.comparator, *other, **kwargs)  # type: ignore[return-value]  # noqa: E501
  File "C:\Users\milan\OneDrive\Документы\Innopolis_studying\1_year\2_sem\well_wisher_inno_bot\venv\lib\site-packages\sqlalchemy\sql\operators.py", line 615, in __getitem__
    return self.operate(getitem, index)
  File "C:\Users\milan\OneDrive\Документы\Innopolis_studying\1_year\2_sem\well_wisher_inno_bot\venv\lib\site-packages\sqlalchemy\sql\type_api.py", line 194, in operate
    return op_fn(self.expr, op, *other, **addtl_kw)  # type: ignore
  File "C:\Users\milan\OneDrive\Документы\Innopolis_studying\1_year\2_sem\well_wisher_inno_bot\venv\lib\site-packages\sqlalchemy\sql\default_comparator.py", line 244, in _getitem_impl
    _unsupported_impl(expr, op, other, **kw)
  File "C:\Users\milan\OneDrive\Документы\Innopolis_studying\1_year\2_sem\well_wisher_inno_bot\venv\lib\site-packages\sqlalchemy\sql\default_comparator.py", line 250, in _unsupported_impl
    raise NotImplementedError(
NotImplementedError: Operator 'getitem' is not supported on this expression
10:16:11 aiogram.dispatcher.dispatcher INFO Stop polling...
10:16:11 aiogram WARNING Goodbye!
10:16:13 aiogram INFO Bot: Well Wisher Bot [@well_wisher_inno_bot]
10:16:13 aiogram WARNING Updates were skipped successfully.
10:16:13 root INFO Bot is starting...
10:16:13 aiogram.dispatcher.dispatcher INFO Start polling.
10:16:17 asyncio ERROR Task exception was never retrieved
future: <Task finished name='Task-10' coro=<Dispatcher._process_polling_updates() done, defined at C:\Users\milan\OneDrive\Документы\Innopolis_studying\1_year\2_sem\well_wisher_inno_bot\venv\lib\site-packages\aiogram\dispatcher\dispatcher.py:407> exception=OperationalError('(sqlite3.OperationalError) no such function: split')>
Traceback (most recent call last):
  File "C:\Users\milan\OneDrive\Документы\Innopolis_studying\1_year\2_sem\well_wisher_inno_bot\venv\lib\site-packages\sqlalchemy\engine\base.py", line 1965, in _exec_single_context
    self.dialect.do_execute(
  File "C:\Users\milan\OneDrive\Документы\Innopolis_studying\1_year\2_sem\well_wisher_inno_bot\venv\lib\site-packages\sqlalchemy\engine\default.py", line 921, in do_execute
    cursor.execute(statement, parameters)
sqlite3.OperationalError: no such function: split

The above exception was the direct cause of the following exception:

Traceback (most recent call last):
  File "C:\Users\milan\OneDrive\Документы\Innopolis_studying\1_year\2_sem\well_wisher_inno_bot\venv\lib\site-packages\aiogram\dispatcher\dispatcher.py", line 415, in _process_polling_updates
    for responses in itertools.chain.from_iterable(await self.process_updates(updates, fast)):
  File "C:\Users\milan\OneDrive\Документы\Innopolis_studying\1_year\2_sem\well_wisher_inno_bot\venv\lib\site-packages\aiogram\dispatcher\dispatcher.py", line 235, in process_updates
    return await asyncio.gather(*tasks)
  File "C:\Users\milan\OneDrive\Документы\Innopolis_studying\1_year\2_sem\well_wisher_inno_bot\venv\lib\site-packages\aiogram\dispatcher\handler.py", line 117, in notify
    response = await handler_obj.handler(*args, **partial_data)
  File "C:\Users\milan\OneDrive\Документы\Innopolis_studying\1_year\2_sem\well_wisher_inno_bot\venv\lib\site-packages\aiogram\dispatcher\dispatcher.py", line 256, in process_update
    return await self.message_handlers.notify(update.message)
  File "C:\Users\milan\OneDrive\Документы\Innopolis_studying\1_year\2_sem\well_wisher_inno_bot\venv\lib\site-packages\aiogram\dispatcher\handler.py", line 117, in notify
    response = await handler_obj.handler(*args, **partial_data)
  File "C:\Users\milan\OneDrive\Документы\Innopolis_studying\1_year\2_sem\well_wisher_inno_bot\app\main_logic.py", line 270, in get_today
    results = session.execute(select_query).fetchall()
  File "C:\Users\milan\OneDrive\Документы\Innopolis_studying\1_year\2_sem\well_wisher_inno_bot\venv\lib\site-packages\sqlalchemy\orm\session.py", line 2225, in execute
    return self._execute_internal(
  File "C:\Users\milan\OneDrive\Документы\Innopolis_studying\1_year\2_sem\well_wisher_inno_bot\venv\lib\site-packages\sqlalchemy\orm\session.py", line 2129, in _execute_internal
    result = conn.execute(
  File "C:\Users\milan\OneDrive\Документы\Innopolis_studying\1_year\2_sem\well_wisher_inno_bot\venv\lib\site-packages\sqlalchemy\engine\base.py", line 1412, in execute
    return meth(
  File "C:\Users\milan\OneDrive\Документы\Innopolis_studying\1_year\2_sem\well_wisher_inno_bot\venv\lib\site-packages\sqlalchemy\sql\elements.py", line 483, in _execute_on_connection
    return connection._execute_clauseelement(
  File "C:\Users\milan\OneDrive\Документы\Innopolis_studying\1_year\2_sem\well_wisher_inno_bot\venv\lib\site-packages\sqlalchemy\engine\base.py", line 1635, in _execute_clauseelement
    ret = self._execute_context(
  File "C:\Users\milan\OneDrive\Документы\Innopolis_studying\1_year\2_sem\well_wisher_inno_bot\venv\lib\site-packages\sqlalchemy\engine\base.py", line 1844, in _execute_context
    return self._exec_single_context(
  File "C:\Users\milan\OneDrive\Документы\Innopolis_studying\1_year\2_sem\well_wisher_inno_bot\venv\lib\site-packages\sqlalchemy\engine\base.py", line 1984, in _exec_single_context
    self._handle_dbapi_exception(
  File "C:\Users\milan\OneDrive\Документы\Innopolis_studying\1_year\2_sem\well_wisher_inno_bot\venv\lib\site-packages\sqlalchemy\engine\base.py", line 2339, in _handle_dbapi_exception
    raise sqlalchemy_exception.with_traceback(exc_info[2]) from e
  File "C:\Users\milan\OneDrive\Документы\Innopolis_studying\1_year\2_sem\well_wisher_inno_bot\venv\lib\site-packages\sqlalchemy\engine\base.py", line 1965, in _exec_single_context
    self.dialect.do_execute(
  File "C:\Users\milan\OneDrive\Документы\Innopolis_studying\1_year\2_sem\well_wisher_inno_bot\venv\lib\site-packages\sqlalchemy\engine\default.py", line 921, in do_execute
    cursor.execute(statement, parameters)
sqlalchemy.exc.OperationalError: (sqlite3.OperationalError) no such function: split
[SQL: SELECT "table_-857882889".data, "table_-857882889".is_birthday, "table_-857882889".date 
FROM "table_-857882889" 
WHERE CAST(split("table_-857882889".date, ?) AS VARCHAR) LIKE ?]
[parameters: (' ', '2023-06-23%')]
(Background on this error at: https://sqlalche.me/e/20/e3q8)
10:17:21 aiogram.dispatcher.dispatcher INFO Stop polling...
10:17:21 aiogram WARNING Goodbye!
10:17:23 aiogram INFO Bot: Well Wisher Bot [@well_wisher_inno_bot]
10:17:24 aiogram WARNING Updates were skipped successfully.
10:17:24 root INFO Bot is starting...
10:17:24 aiogram.dispatcher.dispatcher INFO Start polling.
10:17:27 asyncio ERROR Task exception was never retrieved
future: <Task finished name='Task-10' coro=<Dispatcher._process_polling_updates() done, defined at C:\Users\milan\OneDrive\Документы\Innopolis_studying\1_year\2_sem\well_wisher_inno_bot\venv\lib\site-packages\aiogram\dispatcher\dispatcher.py:407> exception=TypeError("'coroutine' object is not subscriptable")>
Traceback (most recent call last):
  File "C:\Users\milan\OneDrive\Документы\Innopolis_studying\1_year\2_sem\well_wisher_inno_bot\venv\lib\site-packages\aiogram\dispatcher\dispatcher.py", line 415, in _process_polling_updates
    for responses in itertools.chain.from_iterable(await self.process_updates(updates, fast)):
  File "C:\Users\milan\OneDrive\Документы\Innopolis_studying\1_year\2_sem\well_wisher_inno_bot\venv\lib\site-packages\aiogram\dispatcher\dispatcher.py", line 235, in process_updates
    return await asyncio.gather(*tasks)
  File "C:\Users\milan\OneDrive\Документы\Innopolis_studying\1_year\2_sem\well_wisher_inno_bot\venv\lib\site-packages\aiogram\dispatcher\handler.py", line 117, in notify
    response = await handler_obj.handler(*args, **partial_data)
  File "C:\Users\milan\OneDrive\Документы\Innopolis_studying\1_year\2_sem\well_wisher_inno_bot\venv\lib\site-packages\aiogram\dispatcher\dispatcher.py", line 256, in process_update
    return await self.message_handlers.notify(update.message)
  File "C:\Users\milan\OneDrive\Документы\Innopolis_studying\1_year\2_sem\well_wisher_inno_bot\venv\lib\site-packages\aiogram\dispatcher\handler.py", line 117, in notify
    response = await handler_obj.handler(*args, **partial_data)
  File "C:\Users\milan\OneDrive\Документы\Innopolis_studying\1_year\2_sem\well_wisher_inno_bot\app\main_logic.py", line 282, in get_today
    answer_data += f'{user_data["username"]}\n'
TypeError: 'coroutine' object is not subscriptable
10:19:23 aiogram.dispatcher.dispatcher ERROR Cause exception while getting updates.
Traceback (most recent call last):
  File "C:\Users\milan\OneDrive\Документы\Innopolis_studying\1_year\2_sem\well_wisher_inno_bot\venv\lib\site-packages\aiogram\dispatcher\dispatcher.py", line 381, in start_polling
    updates = await self.bot.get_updates(
  File "C:\Users\milan\OneDrive\Документы\Innopolis_studying\1_year\2_sem\well_wisher_inno_bot\venv\lib\site-packages\aiogram\bot\bot.py", line 110, in get_updates
    result = await self.request(api.Methods.GET_UPDATES, payload)
  File "C:\Users\milan\OneDrive\Документы\Innopolis_studying\1_year\2_sem\well_wisher_inno_bot\venv\lib\site-packages\aiogram\bot\base.py", line 236, in request
    return await api.make_request(await self.get_session(), self.server, self.__token, method, data, files,
  File "C:\Users\milan\OneDrive\Документы\Innopolis_studying\1_year\2_sem\well_wisher_inno_bot\venv\lib\site-packages\aiogram\bot\api.py", line 140, in make_request
    return check_result(method, response.content_type, response.status, await response.text())
  File "C:\Users\milan\OneDrive\Документы\Innopolis_studying\1_year\2_sem\well_wisher_inno_bot\venv\lib\site-packages\aiogram\bot\api.py", line 119, in check_result
    exceptions.ConflictError.detect(description)
  File "C:\Users\milan\OneDrive\Документы\Innopolis_studying\1_year\2_sem\well_wisher_inno_bot\venv\lib\site-packages\aiogram\utils\exceptions.py", line 140, in detect
    raise err(cls.text or description)
aiogram.utils.exceptions.TerminatedByOtherGetUpdates: Terminated by other getupdates request; make sure that only one bot instance is running
10:19:33 aiogram.dispatcher.dispatcher ERROR Cause exception while getting updates.
Traceback (most recent call last):
  File "C:\Users\milan\OneDrive\Документы\Innopolis_studying\1_year\2_sem\well_wisher_inno_bot\venv\lib\site-packages\aiogram\dispatcher\dispatcher.py", line 381, in start_polling
    updates = await self.bot.get_updates(
  File "C:\Users\milan\OneDrive\Документы\Innopolis_studying\1_year\2_sem\well_wisher_inno_bot\venv\lib\site-packages\aiogram\bot\bot.py", line 110, in get_updates
    result = await self.request(api.Methods.GET_UPDATES, payload)
  File "C:\Users\milan\OneDrive\Документы\Innopolis_studying\1_year\2_sem\well_wisher_inno_bot\venv\lib\site-packages\aiogram\bot\base.py", line 236, in request
    return await api.make_request(await self.get_session(), self.server, self.__token, method, data, files,
  File "C:\Users\milan\OneDrive\Документы\Innopolis_studying\1_year\2_sem\well_wisher_inno_bot\venv\lib\site-packages\aiogram\bot\api.py", line 140, in make_request
    return check_result(method, response.content_type, response.status, await response.text())
  File "C:\Users\milan\OneDrive\Документы\Innopolis_studying\1_year\2_sem\well_wisher_inno_bot\venv\lib\site-packages\aiogram\bot\api.py", line 119, in check_result
    exceptions.ConflictError.detect(description)
  File "C:\Users\milan\OneDrive\Документы\Innopolis_studying\1_year\2_sem\well_wisher_inno_bot\venv\lib\site-packages\aiogram\utils\exceptions.py", line 140, in detect
    raise err(cls.text or description)
aiogram.utils.exceptions.TerminatedByOtherGetUpdates: Terminated by other getupdates request; make sure that only one bot instance is running
10:19:43 aiogram.dispatcher.dispatcher ERROR Cause exception while getting updates.
Traceback (most recent call last):
  File "C:\Users\milan\OneDrive\Документы\Innopolis_studying\1_year\2_sem\well_wisher_inno_bot\venv\lib\site-packages\aiogram\dispatcher\dispatcher.py", line 381, in start_polling
    updates = await self.bot.get_updates(
  File "C:\Users\milan\OneDrive\Документы\Innopolis_studying\1_year\2_sem\well_wisher_inno_bot\venv\lib\site-packages\aiogram\bot\bot.py", line 110, in get_updates
    result = await self.request(api.Methods.GET_UPDATES, payload)
  File "C:\Users\milan\OneDrive\Документы\Innopolis_studying\1_year\2_sem\well_wisher_inno_bot\venv\lib\site-packages\aiogram\bot\base.py", line 236, in request
    return await api.make_request(await self.get_session(), self.server, self.__token, method, data, files,
  File "C:\Users\milan\OneDrive\Документы\Innopolis_studying\1_year\2_sem\well_wisher_inno_bot\venv\lib\site-packages\aiogram\bot\api.py", line 140, in make_request
    return check_result(method, response.content_type, response.status, await response.text())
  File "C:\Users\milan\OneDrive\Документы\Innopolis_studying\1_year\2_sem\well_wisher_inno_bot\venv\lib\site-packages\aiogram\bot\api.py", line 119, in check_result
    exceptions.ConflictError.detect(description)
  File "C:\Users\milan\OneDrive\Документы\Innopolis_studying\1_year\2_sem\well_wisher_inno_bot\venv\lib\site-packages\aiogram\utils\exceptions.py", line 140, in detect
    raise err(cls.text or description)
aiogram.utils.exceptions.TerminatedByOtherGetUpdates: Terminated by other getupdates request; make sure that only one bot instance is running
10:19:54 aiogram.dispatcher.dispatcher ERROR Cause exception while getting updates.
Traceback (most recent call last):
  File "C:\Users\milan\OneDrive\Документы\Innopolis_studying\1_year\2_sem\well_wisher_inno_bot\venv\lib\site-packages\aiogram\dispatcher\dispatcher.py", line 381, in start_polling
    updates = await self.bot.get_updates(
  File "C:\Users\milan\OneDrive\Документы\Innopolis_studying\1_year\2_sem\well_wisher_inno_bot\venv\lib\site-packages\aiogram\bot\bot.py", line 110, in get_updates
    result = await self.request(api.Methods.GET_UPDATES, payload)
  File "C:\Users\milan\OneDrive\Документы\Innopolis_studying\1_year\2_sem\well_wisher_inno_bot\venv\lib\site-packages\aiogram\bot\base.py", line 236, in request
    return await api.make_request(await self.get_session(), self.server, self.__token, method, data, files,
  File "C:\Users\milan\OneDrive\Документы\Innopolis_studying\1_year\2_sem\well_wisher_inno_bot\venv\lib\site-packages\aiogram\bot\api.py", line 140, in make_request
    return check_result(method, response.content_type, response.status, await response.text())
  File "C:\Users\milan\OneDrive\Документы\Innopolis_studying\1_year\2_sem\well_wisher_inno_bot\venv\lib\site-packages\aiogram\bot\api.py", line 119, in check_result
    exceptions.ConflictError.detect(description)
  File "C:\Users\milan\OneDrive\Документы\Innopolis_studying\1_year\2_sem\well_wisher_inno_bot\venv\lib\site-packages\aiogram\utils\exceptions.py", line 140, in detect
    raise err(cls.text or description)
aiogram.utils.exceptions.TerminatedByOtherGetUpdates: Terminated by other getupdates request; make sure that only one bot instance is running
10:20:04 aiogram.dispatcher.dispatcher ERROR Cause exception while getting updates.
Traceback (most recent call last):
  File "C:\Users\milan\OneDrive\Документы\Innopolis_studying\1_year\2_sem\well_wisher_inno_bot\venv\lib\site-packages\aiogram\dispatcher\dispatcher.py", line 381, in start_polling
    updates = await self.bot.get_updates(
  File "C:\Users\milan\OneDrive\Документы\Innopolis_studying\1_year\2_sem\well_wisher_inno_bot\venv\lib\site-packages\aiogram\bot\bot.py", line 110, in get_updates
    result = await self.request(api.Methods.GET_UPDATES, payload)
  File "C:\Users\milan\OneDrive\Документы\Innopolis_studying\1_year\2_sem\well_wisher_inno_bot\venv\lib\site-packages\aiogram\bot\base.py", line 236, in request
    return await api.make_request(await self.get_session(), self.server, self.__token, method, data, files,
  File "C:\Users\milan\OneDrive\Документы\Innopolis_studying\1_year\2_sem\well_wisher_inno_bot\venv\lib\site-packages\aiogram\bot\api.py", line 140, in make_request
    return check_result(method, response.content_type, response.status, await response.text())
  File "C:\Users\milan\OneDrive\Документы\Innopolis_studying\1_year\2_sem\well_wisher_inno_bot\venv\lib\site-packages\aiogram\bot\api.py", line 119, in check_result
    exceptions.ConflictError.detect(description)
  File "C:\Users\milan\OneDrive\Документы\Innopolis_studying\1_year\2_sem\well_wisher_inno_bot\venv\lib\site-packages\aiogram\utils\exceptions.py", line 140, in detect
    raise err(cls.text or description)
aiogram.utils.exceptions.TerminatedByOtherGetUpdates: Terminated by other getupdates request; make sure that only one bot instance is running
10:20:14 aiogram.dispatcher.dispatcher ERROR Cause exception while getting updates.
Traceback (most recent call last):
  File "C:\Users\milan\OneDrive\Документы\Innopolis_studying\1_year\2_sem\well_wisher_inno_bot\venv\lib\site-packages\aiogram\dispatcher\dispatcher.py", line 381, in start_polling
    updates = await self.bot.get_updates(
  File "C:\Users\milan\OneDrive\Документы\Innopolis_studying\1_year\2_sem\well_wisher_inno_bot\venv\lib\site-packages\aiogram\bot\bot.py", line 110, in get_updates
    result = await self.request(api.Methods.GET_UPDATES, payload)
  File "C:\Users\milan\OneDrive\Документы\Innopolis_studying\1_year\2_sem\well_wisher_inno_bot\venv\lib\site-packages\aiogram\bot\base.py", line 236, in request
    return await api.make_request(await self.get_session(), self.server, self.__token, method, data, files,
  File "C:\Users\milan\OneDrive\Документы\Innopolis_studying\1_year\2_sem\well_wisher_inno_bot\venv\lib\site-packages\aiogram\bot\api.py", line 140, in make_request
    return check_result(method, response.content_type, response.status, await response.text())
  File "C:\Users\milan\OneDrive\Документы\Innopolis_studying\1_year\2_sem\well_wisher_inno_bot\venv\lib\site-packages\aiogram\bot\api.py", line 119, in check_result
    exceptions.ConflictError.detect(description)
  File "C:\Users\milan\OneDrive\Документы\Innopolis_studying\1_year\2_sem\well_wisher_inno_bot\venv\lib\site-packages\aiogram\utils\exceptions.py", line 140, in detect
    raise err(cls.text or description)
aiogram.utils.exceptions.TerminatedByOtherGetUpdates: Terminated by other getupdates request; make sure that only one bot instance is running
10:20:24 aiogram.dispatcher.dispatcher ERROR Cause exception while getting updates.
Traceback (most recent call last):
  File "C:\Users\milan\OneDrive\Документы\Innopolis_studying\1_year\2_sem\well_wisher_inno_bot\venv\lib\site-packages\aiogram\dispatcher\dispatcher.py", line 381, in start_polling
    updates = await self.bot.get_updates(
  File "C:\Users\milan\OneDrive\Документы\Innopolis_studying\1_year\2_sem\well_wisher_inno_bot\venv\lib\site-packages\aiogram\bot\bot.py", line 110, in get_updates
    result = await self.request(api.Methods.GET_UPDATES, payload)
  File "C:\Users\milan\OneDrive\Документы\Innopolis_studying\1_year\2_sem\well_wisher_inno_bot\venv\lib\site-packages\aiogram\bot\base.py", line 236, in request
    return await api.make_request(await self.get_session(), self.server, self.__token, method, data, files,
  File "C:\Users\milan\OneDrive\Документы\Innopolis_studying\1_year\2_sem\well_wisher_inno_bot\venv\lib\site-packages\aiogram\bot\api.py", line 140, in make_request
    return check_result(method, response.content_type, response.status, await response.text())
  File "C:\Users\milan\OneDrive\Документы\Innopolis_studying\1_year\2_sem\well_wisher_inno_bot\venv\lib\site-packages\aiogram\bot\api.py", line 119, in check_result
    exceptions.ConflictError.detect(description)
  File "C:\Users\milan\OneDrive\Документы\Innopolis_studying\1_year\2_sem\well_wisher_inno_bot\venv\lib\site-packages\aiogram\utils\exceptions.py", line 140, in detect
    raise err(cls.text or description)
aiogram.utils.exceptions.TerminatedByOtherGetUpdates: Terminated by other getupdates request; make sure that only one bot instance is running
10:20:34 aiogram.dispatcher.dispatcher ERROR Cause exception while getting updates.
Traceback (most recent call last):
  File "C:\Users\milan\OneDrive\Документы\Innopolis_studying\1_year\2_sem\well_wisher_inno_bot\venv\lib\site-packages\aiogram\dispatcher\dispatcher.py", line 381, in start_polling
    updates = await self.bot.get_updates(
  File "C:\Users\milan\OneDrive\Документы\Innopolis_studying\1_year\2_sem\well_wisher_inno_bot\venv\lib\site-packages\aiogram\bot\bot.py", line 110, in get_updates
    result = await self.request(api.Methods.GET_UPDATES, payload)
  File "C:\Users\milan\OneDrive\Документы\Innopolis_studying\1_year\2_sem\well_wisher_inno_bot\venv\lib\site-packages\aiogram\bot\base.py", line 236, in request
    return await api.make_request(await self.get_session(), self.server, self.__token, method, data, files,
  File "C:\Users\milan\OneDrive\Документы\Innopolis_studying\1_year\2_sem\well_wisher_inno_bot\venv\lib\site-packages\aiogram\bot\api.py", line 140, in make_request
    return check_result(method, response.content_type, response.status, await response.text())
  File "C:\Users\milan\OneDrive\Документы\Innopolis_studying\1_year\2_sem\well_wisher_inno_bot\venv\lib\site-packages\aiogram\bot\api.py", line 119, in check_result
    exceptions.ConflictError.detect(description)
  File "C:\Users\milan\OneDrive\Документы\Innopolis_studying\1_year\2_sem\well_wisher_inno_bot\venv\lib\site-packages\aiogram\utils\exceptions.py", line 140, in detect
    raise err(cls.text or description)
aiogram.utils.exceptions.TerminatedByOtherGetUpdates: Terminated by other getupdates request; make sure that only one bot instance is running
10:21:07 aiogram.dispatcher.dispatcher INFO Stop polling...
10:21:07 aiogram WARNING Goodbye!
10:21:27 aiogram INFO Bot: Well Wisher Bot [@well_wisher_inno_bot]
10:21:27 aiogram WARNING Updates were skipped successfully.
10:21:27 root INFO Bot is starting...
10:21:27 aiogram.dispatcher.dispatcher INFO Start polling.
10:21:38 asyncio ERROR Task exception was never retrieved
future: <Task finished name='Task-10' coro=<Dispatcher._process_polling_updates() done, defined at C:\Users\milan\OneDrive\Документы\Innopolis_studying\1_year\2_sem\well_wisher_inno_bot\venv\lib\site-packages\aiogram\dispatcher\dispatcher.py:407> exception=TypeError("'coroutine' object is not subscriptable")>
Traceback (most recent call last):
  File "C:\Users\milan\OneDrive\Документы\Innopolis_studying\1_year\2_sem\well_wisher_inno_bot\venv\lib\site-packages\aiogram\dispatcher\dispatcher.py", line 415, in _process_polling_updates
    for responses in itertools.chain.from_iterable(await self.process_updates(updates, fast)):
  File "C:\Users\milan\OneDrive\Документы\Innopolis_studying\1_year\2_sem\well_wisher_inno_bot\venv\lib\site-packages\aiogram\dispatcher\dispatcher.py", line 235, in process_updates
    return await asyncio.gather(*tasks)
  File "C:\Users\milan\OneDrive\Документы\Innopolis_studying\1_year\2_sem\well_wisher_inno_bot\venv\lib\site-packages\aiogram\dispatcher\handler.py", line 117, in notify
    response = await handler_obj.handler(*args, **partial_data)
  File "C:\Users\milan\OneDrive\Документы\Innopolis_studying\1_year\2_sem\well_wisher_inno_bot\venv\lib\site-packages\aiogram\dispatcher\dispatcher.py", line 256, in process_update
    return await self.message_handlers.notify(update.message)
  File "C:\Users\milan\OneDrive\Документы\Innopolis_studying\1_year\2_sem\well_wisher_inno_bot\venv\lib\site-packages\aiogram\dispatcher\handler.py", line 117, in notify
    response = await handler_obj.handler(*args, **partial_data)
  File "C:\Users\milan\OneDrive\Документы\Innopolis_studying\1_year\2_sem\well_wisher_inno_bot\app\main_logic.py", line 282, in get_today
    answer_data += f'{user_data["username"]}\n'
TypeError: 'coroutine' object is not subscriptable
10:23:39 aiogram.dispatcher.dispatcher INFO Stop polling...
10:23:39 aiogram.dispatcher.dispatcher WARNING Polling is stopped.
10:23:39 aiogram WARNING Goodbye!
10:23:42 aiogram INFO Bot: Well Wisher Bot [@well_wisher_inno_bot]
10:23:43 aiogram WARNING Updates were skipped successfully.
10:23:43 root INFO Bot is starting...
10:23:43 aiogram.dispatcher.dispatcher INFO Start polling.
10:23:46 asyncio ERROR Task exception was never retrieved
future: <Task finished name='Task-10' coro=<Dispatcher._process_polling_updates() done, defined at C:\Users\milan\OneDrive\Документы\Innopolis_studying\1_year\2_sem\well_wisher_inno_bot\venv\lib\site-packages\aiogram\dispatcher\dispatcher.py:407> exception=ChatNotFound('Chat not found')>
Traceback (most recent call last):
  File "C:\Users\milan\OneDrive\Документы\Innopolis_studying\1_year\2_sem\well_wisher_inno_bot\venv\lib\site-packages\aiogram\dispatcher\dispatcher.py", line 415, in _process_polling_updates
    for responses in itertools.chain.from_iterable(await self.process_updates(updates, fast)):
  File "C:\Users\milan\OneDrive\Документы\Innopolis_studying\1_year\2_sem\well_wisher_inno_bot\venv\lib\site-packages\aiogram\dispatcher\dispatcher.py", line 235, in process_updates
    return await asyncio.gather(*tasks)
  File "C:\Users\milan\OneDrive\Документы\Innopolis_studying\1_year\2_sem\well_wisher_inno_bot\venv\lib\site-packages\aiogram\dispatcher\handler.py", line 117, in notify
    response = await handler_obj.handler(*args, **partial_data)
  File "C:\Users\milan\OneDrive\Документы\Innopolis_studying\1_year\2_sem\well_wisher_inno_bot\venv\lib\site-packages\aiogram\dispatcher\dispatcher.py", line 256, in process_update
    return await self.message_handlers.notify(update.message)
  File "C:\Users\milan\OneDrive\Документы\Innopolis_studying\1_year\2_sem\well_wisher_inno_bot\venv\lib\site-packages\aiogram\dispatcher\handler.py", line 117, in notify
    response = await handler_obj.handler(*args, **partial_data)
  File "C:\Users\milan\OneDrive\Документы\Innopolis_studying\1_year\2_sem\well_wisher_inno_bot\app\main_logic.py", line 281, in get_today
    user_data = await get_user_data(row[0])
  File "C:\Users\milan\OneDrive\Документы\Innopolis_studying\1_year\2_sem\well_wisher_inno_bot\app\main_logic.py", line 36, in get_user_data
    user = await bot.get_chat(user_id)
  File "C:\Users\milan\OneDrive\Документы\Innopolis_studying\1_year\2_sem\well_wisher_inno_bot\venv\lib\site-packages\aiogram\bot\bot.py", line 2622, in get_chat
    result = await self.request(api.Methods.GET_CHAT, payload)
  File "C:\Users\milan\OneDrive\Документы\Innopolis_studying\1_year\2_sem\well_wisher_inno_bot\venv\lib\site-packages\aiogram\bot\base.py", line 236, in request
    return await api.make_request(await self.get_session(), self.server, self.__token, method, data, files,
  File "C:\Users\milan\OneDrive\Документы\Innopolis_studying\1_year\2_sem\well_wisher_inno_bot\venv\lib\site-packages\aiogram\bot\api.py", line 140, in make_request
    return check_result(method, response.content_type, response.status, await response.text())
  File "C:\Users\milan\OneDrive\Документы\Innopolis_studying\1_year\2_sem\well_wisher_inno_bot\venv\lib\site-packages\aiogram\bot\api.py", line 115, in check_result
    exceptions.BadRequest.detect(description)
  File "C:\Users\milan\OneDrive\Документы\Innopolis_studying\1_year\2_sem\well_wisher_inno_bot\venv\lib\site-packages\aiogram\utils\exceptions.py", line 140, in detect
    raise err(cls.text or description)
aiogram.utils.exceptions.ChatNotFound: Chat not found
10:24:25 asyncio ERROR Task exception was never retrieved
future: <Task finished name='Task-17' coro=<Dispatcher._process_polling_updates() done, defined at C:\Users\milan\OneDrive\Документы\Innopolis_studying\1_year\2_sem\well_wisher_inno_bot\venv\lib\site-packages\aiogram\dispatcher\dispatcher.py:407> exception=ChatNotFound('Chat not found')>
Traceback (most recent call last):
  File "C:\Users\milan\OneDrive\Документы\Innopolis_studying\1_year\2_sem\well_wisher_inno_bot\venv\lib\site-packages\aiogram\dispatcher\dispatcher.py", line 415, in _process_polling_updates
    for responses in itertools.chain.from_iterable(await self.process_updates(updates, fast)):
  File "C:\Users\milan\OneDrive\Документы\Innopolis_studying\1_year\2_sem\well_wisher_inno_bot\venv\lib\site-packages\aiogram\dispatcher\dispatcher.py", line 235, in process_updates
    return await asyncio.gather(*tasks)
  File "C:\Users\milan\OneDrive\Документы\Innopolis_studying\1_year\2_sem\well_wisher_inno_bot\venv\lib\site-packages\aiogram\dispatcher\handler.py", line 117, in notify
    response = await handler_obj.handler(*args, **partial_data)
  File "C:\Users\milan\OneDrive\Документы\Innopolis_studying\1_year\2_sem\well_wisher_inno_bot\venv\lib\site-packages\aiogram\dispatcher\dispatcher.py", line 256, in process_update
    return await self.message_handlers.notify(update.message)
  File "C:\Users\milan\OneDrive\Документы\Innopolis_studying\1_year\2_sem\well_wisher_inno_bot\venv\lib\site-packages\aiogram\dispatcher\handler.py", line 117, in notify
    response = await handler_obj.handler(*args, **partial_data)
  File "C:\Users\milan\OneDrive\Документы\Innopolis_studying\1_year\2_sem\well_wisher_inno_bot\app\main_logic.py", line 281, in get_today
    user_data = await get_user_data(row[0])
  File "C:\Users\milan\OneDrive\Документы\Innopolis_studying\1_year\2_sem\well_wisher_inno_bot\app\main_logic.py", line 36, in get_user_data
    user = await bot.get_chat(user_id)
  File "C:\Users\milan\OneDrive\Документы\Innopolis_studying\1_year\2_sem\well_wisher_inno_bot\venv\lib\site-packages\aiogram\bot\bot.py", line 2622, in get_chat
    result = await self.request(api.Methods.GET_CHAT, payload)
  File "C:\Users\milan\OneDrive\Документы\Innopolis_studying\1_year\2_sem\well_wisher_inno_bot\venv\lib\site-packages\aiogram\bot\base.py", line 236, in request
    return await api.make_request(await self.get_session(), self.server, self.__token, method, data, files,
  File "C:\Users\milan\OneDrive\Документы\Innopolis_studying\1_year\2_sem\well_wisher_inno_bot\venv\lib\site-packages\aiogram\bot\api.py", line 140, in make_request
    return check_result(method, response.content_type, response.status, await response.text())
  File "C:\Users\milan\OneDrive\Документы\Innopolis_studying\1_year\2_sem\well_wisher_inno_bot\venv\lib\site-packages\aiogram\bot\api.py", line 115, in check_result
    exceptions.BadRequest.detect(description)
  File "C:\Users\milan\OneDrive\Документы\Innopolis_studying\1_year\2_sem\well_wisher_inno_bot\venv\lib\site-packages\aiogram\utils\exceptions.py", line 140, in detect
    raise err(cls.text or description)
aiogram.utils.exceptions.ChatNotFound: Chat not found
10:25:47 aiogram.dispatcher.dispatcher INFO Stop polling...
10:25:47 aiogram WARNING Goodbye!
10:25:49 aiogram INFO Bot: Well Wisher Bot [@well_wisher_inno_bot]
10:25:49 aiogram WARNING Updates were skipped successfully.
10:25:49 root INFO Bot is starting...
10:25:49 aiogram.dispatcher.dispatcher INFO Start polling.
10:25:53 asyncio ERROR Task exception was never retrieved
future: <Task finished name='Task-10' coro=<Dispatcher._process_polling_updates() done, defined at C:\Users\milan\OneDrive\Документы\Innopolis_studying\1_year\2_sem\well_wisher_inno_bot\venv\lib\site-packages\aiogram\dispatcher\dispatcher.py:407> exception=ChatNotFound('Chat not found')>
Traceback (most recent call last):
  File "C:\Users\milan\OneDrive\Документы\Innopolis_studying\1_year\2_sem\well_wisher_inno_bot\venv\lib\site-packages\aiogram\dispatcher\dispatcher.py", line 415, in _process_polling_updates
    for responses in itertools.chain.from_iterable(await self.process_updates(updates, fast)):
  File "C:\Users\milan\OneDrive\Документы\Innopolis_studying\1_year\2_sem\well_wisher_inno_bot\venv\lib\site-packages\aiogram\dispatcher\dispatcher.py", line 235, in process_updates
    return await asyncio.gather(*tasks)
  File "C:\Users\milan\OneDrive\Документы\Innopolis_studying\1_year\2_sem\well_wisher_inno_bot\venv\lib\site-packages\aiogram\dispatcher\handler.py", line 117, in notify
    response = await handler_obj.handler(*args, **partial_data)
  File "C:\Users\milan\OneDrive\Документы\Innopolis_studying\1_year\2_sem\well_wisher_inno_bot\venv\lib\site-packages\aiogram\dispatcher\dispatcher.py", line 256, in process_update
    return await self.message_handlers.notify(update.message)
  File "C:\Users\milan\OneDrive\Документы\Innopolis_studying\1_year\2_sem\well_wisher_inno_bot\venv\lib\site-packages\aiogram\dispatcher\handler.py", line 117, in notify
    response = await handler_obj.handler(*args, **partial_data)
  File "C:\Users\milan\OneDrive\Документы\Innopolis_studying\1_year\2_sem\well_wisher_inno_bot\app\main_logic.py", line 282, in get_today
    user_data = await get_user_data(row[0])
  File "C:\Users\milan\OneDrive\Документы\Innopolis_studying\1_year\2_sem\well_wisher_inno_bot\app\main_logic.py", line 36, in get_user_data
    user = await bot.get_chat(user_id)
  File "C:\Users\milan\OneDrive\Документы\Innopolis_studying\1_year\2_sem\well_wisher_inno_bot\venv\lib\site-packages\aiogram\bot\bot.py", line 2622, in get_chat
    result = await self.request(api.Methods.GET_CHAT, payload)
  File "C:\Users\milan\OneDrive\Документы\Innopolis_studying\1_year\2_sem\well_wisher_inno_bot\venv\lib\site-packages\aiogram\bot\base.py", line 236, in request
    return await api.make_request(await self.get_session(), self.server, self.__token, method, data, files,
  File "C:\Users\milan\OneDrive\Документы\Innopolis_studying\1_year\2_sem\well_wisher_inno_bot\venv\lib\site-packages\aiogram\bot\api.py", line 140, in make_request
    return check_result(method, response.content_type, response.status, await response.text())
  File "C:\Users\milan\OneDrive\Документы\Innopolis_studying\1_year\2_sem\well_wisher_inno_bot\venv\lib\site-packages\aiogram\bot\api.py", line 115, in check_result
    exceptions.BadRequest.detect(description)
  File "C:\Users\milan\OneDrive\Документы\Innopolis_studying\1_year\2_sem\well_wisher_inno_bot\venv\lib\site-packages\aiogram\utils\exceptions.py", line 140, in detect
    raise err(cls.text or description)
aiogram.utils.exceptions.ChatNotFound: Chat not found
10:28:34 aiogram.dispatcher.dispatcher INFO Stop polling...
10:28:34 aiogram WARNING Goodbye!
10:28:39 aiogram INFO Bot: Well Wisher Bot [@well_wisher_inno_bot]
10:28:39 aiogram WARNING Updates were skipped successfully.
10:28:39 root INFO Bot is starting...
10:28:39 aiogram.dispatcher.dispatcher INFO Start polling.
10:28:41 asyncio ERROR Task exception was never retrieved
future: <Task finished name='Task-10' coro=<Dispatcher._process_polling_updates() done, defined at C:\Users\milan\OneDrive\Документы\Innopolis_studying\1_year\2_sem\well_wisher_inno_bot\venv\lib\site-packages\aiogram\dispatcher\dispatcher.py:407> exception=ChatNotFound('Chat not found')>
Traceback (most recent call last):
  File "C:\Users\milan\OneDrive\Документы\Innopolis_studying\1_year\2_sem\well_wisher_inno_bot\venv\lib\site-packages\aiogram\dispatcher\dispatcher.py", line 415, in _process_polling_updates
    for responses in itertools.chain.from_iterable(await self.process_updates(updates, fast)):
  File "C:\Users\milan\OneDrive\Документы\Innopolis_studying\1_year\2_sem\well_wisher_inno_bot\venv\lib\site-packages\aiogram\dispatcher\dispatcher.py", line 235, in process_updates
    return await asyncio.gather(*tasks)
  File "C:\Users\milan\OneDrive\Документы\Innopolis_studying\1_year\2_sem\well_wisher_inno_bot\venv\lib\site-packages\aiogram\dispatcher\handler.py", line 117, in notify
    response = await handler_obj.handler(*args, **partial_data)
  File "C:\Users\milan\OneDrive\Документы\Innopolis_studying\1_year\2_sem\well_wisher_inno_bot\venv\lib\site-packages\aiogram\dispatcher\dispatcher.py", line 256, in process_update
    return await self.message_handlers.notify(update.message)
  File "C:\Users\milan\OneDrive\Документы\Innopolis_studying\1_year\2_sem\well_wisher_inno_bot\venv\lib\site-packages\aiogram\dispatcher\handler.py", line 117, in notify
    response = await handler_obj.handler(*args, **partial_data)
  File "C:\Users\milan\OneDrive\Документы\Innopolis_studying\1_year\2_sem\well_wisher_inno_bot\app\main_logic.py", line 282, in get_today
    user_data = await get_user_data(row[0])
  File "C:\Users\milan\OneDrive\Документы\Innopolis_studying\1_year\2_sem\well_wisher_inno_bot\app\main_logic.py", line 36, in get_user_data
    user = await bot.get_chat(user_id)
  File "C:\Users\milan\OneDrive\Документы\Innopolis_studying\1_year\2_sem\well_wisher_inno_bot\venv\lib\site-packages\aiogram\bot\bot.py", line 2622, in get_chat
    result = await self.request(api.Methods.GET_CHAT, payload)
  File "C:\Users\milan\OneDrive\Документы\Innopolis_studying\1_year\2_sem\well_wisher_inno_bot\venv\lib\site-packages\aiogram\bot\base.py", line 236, in request
    return await api.make_request(await self.get_session(), self.server, self.__token, method, data, files,
  File "C:\Users\milan\OneDrive\Документы\Innopolis_studying\1_year\2_sem\well_wisher_inno_bot\venv\lib\site-packages\aiogram\bot\api.py", line 140, in make_request
    return check_result(method, response.content_type, response.status, await response.text())
  File "C:\Users\milan\OneDrive\Документы\Innopolis_studying\1_year\2_sem\well_wisher_inno_bot\venv\lib\site-packages\aiogram\bot\api.py", line 115, in check_result
    exceptions.BadRequest.detect(description)
  File "C:\Users\milan\OneDrive\Документы\Innopolis_studying\1_year\2_sem\well_wisher_inno_bot\venv\lib\site-packages\aiogram\utils\exceptions.py", line 140, in detect
    raise err(cls.text or description)
aiogram.utils.exceptions.ChatNotFound: Chat not found
10:30:07 asyncio ERROR Task exception was never retrieved
future: <Task finished name='Task-27' coro=<Dispatcher._process_polling_updates() done, defined at C:\Users\milan\OneDrive\Документы\Innopolis_studying\1_year\2_sem\well_wisher_inno_bot\venv\lib\site-packages\aiogram\dispatcher\dispatcher.py:407> exception=ChatNotFound('Chat not found')>
Traceback (most recent call last):
  File "C:\Users\milan\OneDrive\Документы\Innopolis_studying\1_year\2_sem\well_wisher_inno_bot\venv\lib\site-packages\aiogram\dispatcher\dispatcher.py", line 415, in _process_polling_updates
    for responses in itertools.chain.from_iterable(await self.process_updates(updates, fast)):
  File "C:\Users\milan\OneDrive\Документы\Innopolis_studying\1_year\2_sem\well_wisher_inno_bot\venv\lib\site-packages\aiogram\dispatcher\dispatcher.py", line 235, in process_updates
    return await asyncio.gather(*tasks)
  File "C:\Users\milan\OneDrive\Документы\Innopolis_studying\1_year\2_sem\well_wisher_inno_bot\venv\lib\site-packages\aiogram\dispatcher\handler.py", line 117, in notify
    response = await handler_obj.handler(*args, **partial_data)
  File "C:\Users\milan\OneDrive\Документы\Innopolis_studying\1_year\2_sem\well_wisher_inno_bot\venv\lib\site-packages\aiogram\dispatcher\dispatcher.py", line 256, in process_update
    return await self.message_handlers.notify(update.message)
  File "C:\Users\milan\OneDrive\Документы\Innopolis_studying\1_year\2_sem\well_wisher_inno_bot\venv\lib\site-packages\aiogram\dispatcher\handler.py", line 117, in notify
    response = await handler_obj.handler(*args, **partial_data)
  File "C:\Users\milan\OneDrive\Документы\Innopolis_studying\1_year\2_sem\well_wisher_inno_bot\app\main_logic.py", line 282, in get_today
    user_data = await get_user_data(row[0])
  File "C:\Users\milan\OneDrive\Документы\Innopolis_studying\1_year\2_sem\well_wisher_inno_bot\app\main_logic.py", line 36, in get_user_data
    user = await bot.get_chat(user_id)
  File "C:\Users\milan\OneDrive\Документы\Innopolis_studying\1_year\2_sem\well_wisher_inno_bot\venv\lib\site-packages\aiogram\bot\bot.py", line 2622, in get_chat
    result = await self.request(api.Methods.GET_CHAT, payload)
  File "C:\Users\milan\OneDrive\Документы\Innopolis_studying\1_year\2_sem\well_wisher_inno_bot\venv\lib\site-packages\aiogram\bot\base.py", line 236, in request
    return await api.make_request(await self.get_session(), self.server, self.__token, method, data, files,
  File "C:\Users\milan\OneDrive\Документы\Innopolis_studying\1_year\2_sem\well_wisher_inno_bot\venv\lib\site-packages\aiogram\bot\api.py", line 140, in make_request
    return check_result(method, response.content_type, response.status, await response.text())
  File "C:\Users\milan\OneDrive\Документы\Innopolis_studying\1_year\2_sem\well_wisher_inno_bot\venv\lib\site-packages\aiogram\bot\api.py", line 115, in check_result
    exceptions.BadRequest.detect(description)
  File "C:\Users\milan\OneDrive\Документы\Innopolis_studying\1_year\2_sem\well_wisher_inno_bot\venv\lib\site-packages\aiogram\utils\exceptions.py", line 140, in detect
    raise err(cls.text or description)
aiogram.utils.exceptions.ChatNotFound: Chat not found
10:32:26 aiogram.dispatcher.dispatcher INFO Stop polling...
10:32:26 aiogram WARNING Goodbye!
10:32:28 aiogram INFO Bot: Well Wisher Bot [@well_wisher_inno_bot]
10:32:29 aiogram WARNING Updates were skipped successfully.
10:32:29 root INFO Bot is starting...
10:32:29 aiogram.dispatcher.dispatcher INFO Start polling.
10:32:39 asyncio ERROR Task exception was never retrieved
future: <Task finished name='Task-17' coro=<Dispatcher._process_polling_updates() done, defined at C:\Users\milan\OneDrive\Документы\Innopolis_studying\1_year\2_sem\well_wisher_inno_bot\venv\lib\site-packages\aiogram\dispatcher\dispatcher.py:407> exception=ChatNotFound('Chat not found')>
Traceback (most recent call last):
  File "C:\Users\milan\OneDrive\Документы\Innopolis_studying\1_year\2_sem\well_wisher_inno_bot\venv\lib\site-packages\aiogram\dispatcher\dispatcher.py", line 415, in _process_polling_updates
    for responses in itertools.chain.from_iterable(await self.process_updates(updates, fast)):
  File "C:\Users\milan\OneDrive\Документы\Innopolis_studying\1_year\2_sem\well_wisher_inno_bot\venv\lib\site-packages\aiogram\dispatcher\dispatcher.py", line 235, in process_updates
    return await asyncio.gather(*tasks)
  File "C:\Users\milan\OneDrive\Документы\Innopolis_studying\1_year\2_sem\well_wisher_inno_bot\venv\lib\site-packages\aiogram\dispatcher\handler.py", line 117, in notify
    response = await handler_obj.handler(*args, **partial_data)
  File "C:\Users\milan\OneDrive\Документы\Innopolis_studying\1_year\2_sem\well_wisher_inno_bot\venv\lib\site-packages\aiogram\dispatcher\dispatcher.py", line 256, in process_update
    return await self.message_handlers.notify(update.message)
  File "C:\Users\milan\OneDrive\Документы\Innopolis_studying\1_year\2_sem\well_wisher_inno_bot\venv\lib\site-packages\aiogram\dispatcher\handler.py", line 117, in notify
    response = await handler_obj.handler(*args, **partial_data)
  File "C:\Users\milan\OneDrive\Документы\Innopolis_studying\1_year\2_sem\well_wisher_inno_bot\app\main_logic.py", line 283, in get_today
    user_data = await get_user_data(row[0])
  File "C:\Users\milan\OneDrive\Документы\Innopolis_studying\1_year\2_sem\well_wisher_inno_bot\app\main_logic.py", line 36, in get_user_data
    user = await bot.get_chat(user_id)
  File "C:\Users\milan\OneDrive\Документы\Innopolis_studying\1_year\2_sem\well_wisher_inno_bot\venv\lib\site-packages\aiogram\bot\bot.py", line 2622, in get_chat
    result = await self.request(api.Methods.GET_CHAT, payload)
  File "C:\Users\milan\OneDrive\Документы\Innopolis_studying\1_year\2_sem\well_wisher_inno_bot\venv\lib\site-packages\aiogram\bot\base.py", line 236, in request
    return await api.make_request(await self.get_session(), self.server, self.__token, method, data, files,
  File "C:\Users\milan\OneDrive\Документы\Innopolis_studying\1_year\2_sem\well_wisher_inno_bot\venv\lib\site-packages\aiogram\bot\api.py", line 140, in make_request
    return check_result(method, response.content_type, response.status, await response.text())
  File "C:\Users\milan\OneDrive\Документы\Innopolis_studying\1_year\2_sem\well_wisher_inno_bot\venv\lib\site-packages\aiogram\bot\api.py", line 115, in check_result
    exceptions.BadRequest.detect(description)
  File "C:\Users\milan\OneDrive\Документы\Innopolis_studying\1_year\2_sem\well_wisher_inno_bot\venv\lib\site-packages\aiogram\utils\exceptions.py", line 140, in detect
    raise err(cls.text or description)
aiogram.utils.exceptions.ChatNotFound: Chat not found
10:33:30 aiogram.dispatcher.dispatcher INFO Stop polling...
10:33:30 aiogram WARNING Goodbye!
10:33:32 aiogram INFO Bot: Well Wisher Bot [@well_wisher_inno_bot]
10:33:32 aiogram WARNING Updates were skipped successfully.
10:33:32 root INFO Bot is starting...
10:33:32 aiogram.dispatcher.dispatcher INFO Start polling.
10:34:42 aiogram.dispatcher.dispatcher INFO Stop polling...
10:34:42 aiogram WARNING Goodbye!
10:34:44 aiogram INFO Bot: Well Wisher Bot [@well_wisher_inno_bot]
10:34:44 aiogram WARNING Updates were skipped successfully.
10:34:44 root INFO Bot is starting...
10:34:45 aiogram.dispatcher.dispatcher INFO Start polling.
10:52:48 aiogram.dispatcher.dispatcher INFO Stop polling...
10:52:48 aiogram WARNING Goodbye!
10:52:50 aiogram INFO Bot: Well Wisher Bot [@well_wisher_inno_bot]
10:52:50 aiogram WARNING Updates were skipped successfully.
10:52:50 root INFO Bot is starting...
10:52:50 aiogram.dispatcher.dispatcher INFO Start polling.
10:53:37 aiogram.dispatcher.dispatcher INFO Stop polling...
10:53:37 aiogram WARNING Goodbye!
10:53:39 aiogram INFO Bot: Well Wisher Bot [@well_wisher_inno_bot]
10:53:39 aiogram WARNING Updates were skipped successfully.
10:53:39 root INFO Bot is starting...
10:53:39 aiogram.dispatcher.dispatcher INFO Start polling.
10:53:53 aiogram.dispatcher.dispatcher INFO Stop polling...
10:53:53 aiogram WARNING Goodbye!
10:53:55 aiogram INFO Bot: Well Wisher Bot [@well_wisher_inno_bot]
10:53:55 aiogram WARNING Updates were skipped successfully.
10:53:55 root INFO Bot is starting...
10:53:55 aiogram.dispatcher.dispatcher INFO Start polling.
10:54:40 aiogram.dispatcher.dispatcher INFO Stop polling...
10:54:40 aiogram WARNING Goodbye!
